[2024-04-13T18:46:42.520+0000] {taskinstance.py:1979} INFO - Dependencies all met for dep_context=non-requeueable deps ti=<TaskInstance: token_refresher_50mins.refresh_token scheduled__2024-04-13T17:30:00+00:00 [queued]>
[2024-04-13T18:46:42.524+0000] {taskinstance.py:1979} INFO - Dependencies all met for dep_context=requeueable deps ti=<TaskInstance: token_refresher_50mins.refresh_token scheduled__2024-04-13T17:30:00+00:00 [queued]>
[2024-04-13T18:46:42.525+0000] {taskinstance.py:2193} INFO - Starting attempt 1 of 2
[2024-04-13T18:46:42.533+0000] {taskinstance.py:2217} INFO - Executing <Task(PythonOperator): refresh_token> on 2024-04-13 17:30:00+00:00
[2024-04-13T18:46:42.535+0000] {standard_task_runner.py:60} INFO - Started process 706 to run task
[2024-04-13T18:46:42.537+0000] {standard_task_runner.py:87} INFO - Running: ['***', 'tasks', 'run', 'token_refresher_50mins', 'refresh_token', 'scheduled__2024-04-13T17:30:00+00:00', '--job-id', '74', '--raw', '--subdir', 'DAGS_FOLDER/refresh_token.py', '--cfg-path', '/tmp/tmp19926ye3']
[2024-04-13T18:46:42.539+0000] {standard_task_runner.py:88} INFO - Job 74: Subtask refresh_token
[2024-04-13T18:46:42.569+0000] {task_command.py:423} INFO - Running <TaskInstance: token_refresher_50mins.refresh_token scheduled__2024-04-13T17:30:00+00:00 [running]> on host 209a9ac884b0
[2024-04-13T18:46:42.600+0000] {taskinstance.py:2513} INFO - Exporting env vars: AIRFLOW_CTX_DAG_OWNER='***' AIRFLOW_CTX_DAG_ID='token_refresher_50mins' AIRFLOW_CTX_TASK_ID='refresh_token' AIRFLOW_CTX_EXECUTION_DATE='2024-04-13T17:30:00+00:00' AIRFLOW_CTX_TRY_NUMBER='1' AIRFLOW_CTX_DAG_RUN_ID='scheduled__2024-04-13T17:30:00+00:00'
[2024-04-13T18:46:42.602+0000] {oauth2.py:471} INFO - User authentication requires interaction with your web browser. Once you enter your credentials and give authorization, you will be redirected to a url.  Paste that url you were directed to to complete the authorization.
[2024-04-13T18:46:42.602+0000] {taskinstance.py:2731} ERROR - Task failed with exception
Traceback (most recent call last):
  File "/home/airflow/.local/lib/python3.8/site-packages/airflow/models/taskinstance.py", line 444, in _execute_task
    result = _execute_callable(context=context, **execute_callable_kwargs)
  File "/home/airflow/.local/lib/python3.8/site-packages/airflow/models/taskinstance.py", line 414, in _execute_callable
    return execute_callable(context=context, **execute_callable_kwargs)
  File "/home/airflow/.local/lib/python3.8/site-packages/airflow/operators/python.py", line 200, in execute
    return_value = self.execute_callable()
  File "/home/airflow/.local/lib/python3.8/site-packages/airflow/operators/python.py", line 217, in execute_callable
    return self.python_callable(*self.op_args, **self.op_kwargs)
  File "/opt/airflow/dags/refresh_token.py", line 34, in refresh_token
    current_user = sp.current_user()
  File "/home/airflow/.local/lib/python3.8/site-packages/spotipy/client.py", line 1227, in current_user
    return self.me()
  File "/home/airflow/.local/lib/python3.8/site-packages/spotipy/client.py", line 1221, in me
    return self._get("me/")
  File "/home/airflow/.local/lib/python3.8/site-packages/spotipy/client.py", line 323, in _get
    return self._internal_call("GET", url, payload, kwargs)
  File "/home/airflow/.local/lib/python3.8/site-packages/spotipy/client.py", line 247, in _internal_call
    headers = self._auth_headers()
  File "/home/airflow/.local/lib/python3.8/site-packages/spotipy/client.py", line 238, in _auth_headers
    token = self.auth_manager.get_access_token(as_dict=False)
  File "/home/airflow/.local/lib/python3.8/site-packages/spotipy/oauth2.py", line 535, in get_access_token
    "code": code or self.get_auth_response(),
  File "/home/airflow/.local/lib/python3.8/site-packages/spotipy/oauth2.py", line 490, in get_auth_response
    return self._get_auth_response_local_server(redirect_port)
  File "/home/airflow/.local/lib/python3.8/site-packages/spotipy/oauth2.py", line 457, in _get_auth_response_local_server
    server = start_local_http_server(redirect_port)
  File "/home/airflow/.local/lib/python3.8/site-packages/spotipy/oauth2.py", line 1303, in start_local_http_server
    server = HTTPServer(("127.0.0.1", port), handler)
  File "/usr/local/lib/python3.8/socketserver.py", line 452, in __init__
    self.server_bind()
  File "/usr/local/lib/python3.8/http/server.py", line 139, in server_bind
    socketserver.TCPServer.server_bind(self)
  File "/usr/local/lib/python3.8/socketserver.py", line 466, in server_bind
    self.socket.bind(self.server_address)
OSError: [Errno 98] Address already in use
[2024-04-13T18:46:42.607+0000] {taskinstance.py:1149} INFO - Marking task as UP_FOR_RETRY. dag_id=token_refresher_50mins, task_id=refresh_token, execution_date=20240413T173000, start_date=20240413T184642, end_date=20240413T184642
[2024-04-13T18:46:42.613+0000] {standard_task_runner.py:107} ERROR - Failed to execute job 74 for task refresh_token ([Errno 98] Address already in use; 706)
[2024-04-13T18:46:42.633+0000] {local_task_job_runner.py:234} INFO - Task exited with return code 1
[2024-04-13T18:46:42.644+0000] {taskinstance.py:3312} INFO - 0 downstream tasks scheduled from follow-on schedule check
[2024-04-14T02:34:53.221+0000] {taskinstance.py:1979} INFO - Dependencies all met for dep_context=non-requeueable deps ti=<TaskInstance: token_refresher_50mins.refresh_token scheduled__2024-04-13T17:30:00+00:00 [queued]>
[2024-04-14T02:34:53.241+0000] {taskinstance.py:1979} INFO - Dependencies all met for dep_context=requeueable deps ti=<TaskInstance: token_refresher_50mins.refresh_token scheduled__2024-04-13T17:30:00+00:00 [queued]>
[2024-04-14T02:34:53.242+0000] {taskinstance.py:2193} INFO - Starting attempt 1 of 2
[2024-04-14T02:34:53.252+0000] {taskinstance.py:2217} INFO - Executing <Task(PythonOperator): refresh_token> on 2024-04-13 17:30:00+00:00
[2024-04-14T02:34:53.256+0000] {standard_task_runner.py:60} INFO - Started process 936 to run task
[2024-04-14T02:34:53.259+0000] {standard_task_runner.py:87} INFO - Running: ['***', 'tasks', 'run', 'token_refresher_50mins', 'refresh_token', 'scheduled__2024-04-13T17:30:00+00:00', '--job-id', '141', '--raw', '--subdir', 'DAGS_FOLDER/refresh_token.py', '--cfg-path', '/tmp/tmpicsrzxd7']
[2024-04-14T02:34:53.260+0000] {standard_task_runner.py:88} INFO - Job 141: Subtask refresh_token
[2024-04-14T02:34:53.296+0000] {task_command.py:423} INFO - Running <TaskInstance: token_refresher_50mins.refresh_token scheduled__2024-04-13T17:30:00+00:00 [running]> on host 209a9ac884b0
[2024-04-14T02:34:53.351+0000] {taskinstance.py:2513} INFO - Exporting env vars: AIRFLOW_CTX_DAG_OWNER='***' AIRFLOW_CTX_DAG_ID='token_refresher_50mins' AIRFLOW_CTX_TASK_ID='refresh_token' AIRFLOW_CTX_EXECUTION_DATE='2024-04-13T17:30:00+00:00' AIRFLOW_CTX_TRY_NUMBER='1' AIRFLOW_CTX_DAG_RUN_ID='scheduled__2024-04-13T17:30:00+00:00'
[2024-04-14T02:34:53.423+0000] {logging_mixin.py:188} INFO - BQCQVAIok65hC8u71olAXw3Mpxb7_tfHptGmD3-Nje9vTcBn-F1s23SWG7PEUuK_Qy57rQ6q1uZQ4cQ5ONCue084Ac4M3LnOBhFOJ68WgTg96ikOIKk
[2024-04-14T02:34:53.425+0000] {python.py:202} INFO - Done. Returned value was: None
[2024-04-14T02:34:53.437+0000] {taskinstance.py:1149} INFO - Marking task as SUCCESS. dag_id=token_refresher_50mins, task_id=refresh_token, execution_date=20240413T173000, start_date=20240414T023453, end_date=20240414T023453
[2024-04-14T02:34:53.479+0000] {local_task_job_runner.py:234} INFO - Task exited with return code 0
[2024-04-14T02:34:53.495+0000] {taskinstance.py:3312} INFO - 0 downstream tasks scheduled from follow-on schedule check
[2024-04-14T02:37:55.311+0000] {taskinstance.py:1979} INFO - Dependencies all met for dep_context=non-requeueable deps ti=<TaskInstance: token_refresher_50mins.refresh_token scheduled__2024-04-13T17:30:00+00:00 [queued]>
[2024-04-14T02:37:55.319+0000] {taskinstance.py:1979} INFO - Dependencies all met for dep_context=requeueable deps ti=<TaskInstance: token_refresher_50mins.refresh_token scheduled__2024-04-13T17:30:00+00:00 [queued]>
[2024-04-14T02:37:55.320+0000] {taskinstance.py:2193} INFO - Starting attempt 1 of 2
[2024-04-14T02:37:55.328+0000] {taskinstance.py:2217} INFO - Executing <Task(PythonOperator): refresh_token> on 2024-04-13 17:30:00+00:00
[2024-04-14T02:37:55.331+0000] {standard_task_runner.py:60} INFO - Started process 1042 to run task
[2024-04-14T02:37:55.333+0000] {standard_task_runner.py:87} INFO - Running: ['***', 'tasks', 'run', 'token_refresher_50mins', 'refresh_token', 'scheduled__2024-04-13T17:30:00+00:00', '--job-id', '174', '--raw', '--subdir', 'DAGS_FOLDER/refresh_token.py', '--cfg-path', '/tmp/tmp1m1y0rdc']
[2024-04-14T02:37:55.334+0000] {standard_task_runner.py:88} INFO - Job 174: Subtask refresh_token
[2024-04-14T02:37:55.363+0000] {task_command.py:423} INFO - Running <TaskInstance: token_refresher_50mins.refresh_token scheduled__2024-04-13T17:30:00+00:00 [running]> on host 209a9ac884b0
[2024-04-14T02:37:55.403+0000] {taskinstance.py:2513} INFO - Exporting env vars: AIRFLOW_CTX_DAG_OWNER='***' AIRFLOW_CTX_DAG_ID='token_refresher_50mins' AIRFLOW_CTX_TASK_ID='refresh_token' AIRFLOW_CTX_EXECUTION_DATE='2024-04-13T17:30:00+00:00' AIRFLOW_CTX_TRY_NUMBER='1' AIRFLOW_CTX_DAG_RUN_ID='scheduled__2024-04-13T17:30:00+00:00'
[2024-04-14T02:37:55.470+0000] {logging_mixin.py:188} WARNING - --- Logging error ---
[2024-04-14T02:37:55.471+0000] {logging_mixin.py:188} WARNING - Traceback (most recent call last):
[2024-04-14T02:37:55.471+0000] {logging_mixin.py:188} WARNING -   File "/usr/local/lib/python3.8/logging/__init__.py", line 1085, in emit
    msg = self.format(record)
[2024-04-14T02:37:55.472+0000] {logging_mixin.py:188} WARNING -   File "/usr/local/lib/python3.8/logging/__init__.py", line 929, in format
    return fmt.format(record)
[2024-04-14T02:37:55.472+0000] {logging_mixin.py:188} WARNING -   File "/usr/local/lib/python3.8/logging/__init__.py", line 668, in format
    record.message = record.getMessage()
[2024-04-14T02:37:55.473+0000] {logging_mixin.py:188} WARNING -   File "/usr/local/lib/python3.8/logging/__init__.py", line 373, in getMessage
    msg = msg % self.args
[2024-04-14T02:37:55.473+0000] {logging_mixin.py:188} WARNING - TypeError: not all arguments converted during string formatting
[2024-04-14T02:37:55.474+0000] {logging_mixin.py:188} WARNING - Call stack:
[2024-04-14T02:37:55.479+0000] {logging_mixin.py:188} WARNING -   File "/home/***/.local/bin/***", line 8, in <module>
    sys.exit(main())
[2024-04-14T02:37:55.479+0000] {logging_mixin.py:188} WARNING -   File "/home/***/.local/lib/python3.8/site-packages/***/__main__.py", line 57, in main
    args.func(args)
[2024-04-14T02:37:55.479+0000] {logging_mixin.py:188} WARNING -   File "/home/***/.local/lib/python3.8/site-packages/***/cli/cli_config.py", line 49, in command
    return func(*args, **kwargs)
[2024-04-14T02:37:55.479+0000] {logging_mixin.py:188} WARNING -   File "/home/***/.local/lib/python3.8/site-packages/***/utils/cli.py", line 114, in wrapper
    return f(*args, **kwargs)
[2024-04-14T02:37:55.479+0000] {logging_mixin.py:188} WARNING -   File "/home/***/.local/lib/python3.8/site-packages/***/providers/celery/cli/celery_command.py", line 60, in wrapper
    providers_configuration_loaded(func)(*args, **kwargs)
[2024-04-14T02:37:55.480+0000] {logging_mixin.py:188} WARNING -   File "/home/***/.local/lib/python3.8/site-packages/***/utils/providers_configuration_loader.py", line 55, in wrapped_function
    return func(*args, **kwargs)
[2024-04-14T02:37:55.480+0000] {logging_mixin.py:188} WARNING -   File "/home/***/.local/lib/python3.8/site-packages/***/providers/celery/cli/celery_command.py", line 231, in worker
    _run_command_with_daemon_option(
[2024-04-14T02:37:55.480+0000] {logging_mixin.py:188} WARNING -   File "/home/***/.local/lib/python3.8/site-packages/***/providers/celery/cli/celery_command.py", line 46, in _run_command_with_daemon_option
    run_command_with_daemon_option(*args, **kwargs)
[2024-04-14T02:37:55.480+0000] {logging_mixin.py:188} WARNING -   File "/home/***/.local/lib/python3.8/site-packages/***/cli/commands/daemon_utils.py", line 86, in run_command_with_daemon_option
    callback()
[2024-04-14T02:37:55.480+0000] {logging_mixin.py:188} WARNING -   File "/home/***/.local/lib/python3.8/site-packages/***/providers/celery/cli/celery_command.py", line 224, in run_celery_worker
    celery_app.worker_main(options)
[2024-04-14T02:37:55.480+0000] {logging_mixin.py:188} WARNING -   File "/home/***/.local/lib/python3.8/site-packages/celery/app/base.py", line 389, in worker_main
    self.start(argv=argv)
[2024-04-14T02:37:55.480+0000] {logging_mixin.py:188} WARNING -   File "/home/***/.local/lib/python3.8/site-packages/celery/app/base.py", line 369, in start
    celery.main(args=argv, standalone_mode=False)
[2024-04-14T02:37:55.481+0000] {logging_mixin.py:188} WARNING -   File "/home/***/.local/lib/python3.8/site-packages/click/core.py", line 1078, in main
    rv = self.invoke(ctx)
[2024-04-14T02:37:55.481+0000] {logging_mixin.py:188} WARNING -   File "/home/***/.local/lib/python3.8/site-packages/click/core.py", line 1688, in invoke
    return _process_result(sub_ctx.command.invoke(sub_ctx))
[2024-04-14T02:37:55.481+0000] {logging_mixin.py:188} WARNING -   File "/home/***/.local/lib/python3.8/site-packages/click/core.py", line 1434, in invoke
    return ctx.invoke(self.callback, **ctx.params)
[2024-04-14T02:37:55.481+0000] {logging_mixin.py:188} WARNING -   File "/home/***/.local/lib/python3.8/site-packages/click/core.py", line 783, in invoke
    return __callback(*args, **kwargs)
[2024-04-14T02:37:55.481+0000] {logging_mixin.py:188} WARNING -   File "/home/***/.local/lib/python3.8/site-packages/click/decorators.py", line 33, in new_func
    return f(get_current_context(), *args, **kwargs)
[2024-04-14T02:37:55.481+0000] {logging_mixin.py:188} WARNING -   File "/home/***/.local/lib/python3.8/site-packages/celery/bin/base.py", line 134, in caller
    return f(ctx, *args, **kwargs)
[2024-04-14T02:37:55.481+0000] {logging_mixin.py:188} WARNING -   File "/home/***/.local/lib/python3.8/site-packages/celery/bin/worker.py", line 356, in worker
    worker.start()
[2024-04-14T02:37:55.482+0000] {logging_mixin.py:188} WARNING -   File "/home/***/.local/lib/python3.8/site-packages/celery/worker/worker.py", line 202, in start
    self.blueprint.start(self)
[2024-04-14T02:37:55.482+0000] {logging_mixin.py:188} WARNING -   File "/home/***/.local/lib/python3.8/site-packages/celery/bootsteps.py", line 116, in start
    step.start(parent)
[2024-04-14T02:37:55.482+0000] {logging_mixin.py:188} WARNING -   File "/home/***/.local/lib/python3.8/site-packages/celery/bootsteps.py", line 365, in start
    return self.obj.start()
[2024-04-14T02:37:55.482+0000] {logging_mixin.py:188} WARNING -   File "/home/***/.local/lib/python3.8/site-packages/celery/concurrency/base.py", line 130, in start
    self.on_start()
[2024-04-14T02:37:55.482+0000] {logging_mixin.py:188} WARNING -   File "/home/***/.local/lib/python3.8/site-packages/celery/concurrency/prefork.py", line 109, in on_start
    P = self._pool = Pool(processes=self.limit,
[2024-04-14T02:37:55.482+0000] {logging_mixin.py:188} WARNING -   File "/home/***/.local/lib/python3.8/site-packages/celery/concurrency/asynpool.py", line 464, in __init__
    super().__init__(processes, *args, **kwargs)
[2024-04-14T02:37:55.482+0000] {logging_mixin.py:188} WARNING -   File "/home/***/.local/lib/python3.8/site-packages/billiard/pool.py", line 1045, in __init__
    self._create_worker_process(i)
[2024-04-14T02:37:55.483+0000] {logging_mixin.py:188} WARNING -   File "/home/***/.local/lib/python3.8/site-packages/celery/concurrency/asynpool.py", line 482, in _create_worker_process
    return super()._create_worker_process(i)
[2024-04-14T02:37:55.483+0000] {logging_mixin.py:188} WARNING -   File "/home/***/.local/lib/python3.8/site-packages/billiard/pool.py", line 1157, in _create_worker_process
    w.start()
[2024-04-14T02:37:55.483+0000] {logging_mixin.py:188} WARNING -   File "/home/***/.local/lib/python3.8/site-packages/billiard/process.py", line 120, in start
    self._popen = self._Popen(self)
[2024-04-14T02:37:55.483+0000] {logging_mixin.py:188} WARNING -   File "/home/***/.local/lib/python3.8/site-packages/billiard/context.py", line 331, in _Popen
    return Popen(process_obj)
[2024-04-14T02:37:55.483+0000] {logging_mixin.py:188} WARNING -   File "/home/***/.local/lib/python3.8/site-packages/billiard/popen_fork.py", line 22, in __init__
    self._launch(process_obj)
[2024-04-14T02:37:55.483+0000] {logging_mixin.py:188} WARNING -   File "/home/***/.local/lib/python3.8/site-packages/billiard/popen_fork.py", line 77, in _launch
    code = process_obj._bootstrap()
[2024-04-14T02:37:55.483+0000] {logging_mixin.py:188} WARNING -   File "/home/***/.local/lib/python3.8/site-packages/billiard/process.py", line 323, in _bootstrap
    self.run()
[2024-04-14T02:37:55.484+0000] {logging_mixin.py:188} WARNING -   File "/home/***/.local/lib/python3.8/site-packages/billiard/process.py", line 110, in run
    self._target(*self._args, **self._kwargs)
[2024-04-14T02:37:55.484+0000] {logging_mixin.py:188} WARNING -   File "/home/***/.local/lib/python3.8/site-packages/billiard/pool.py", line 291, in __call__
    sys.exit(self.workloop(pid=pid))
[2024-04-14T02:37:55.484+0000] {logging_mixin.py:188} WARNING -   File "/home/***/.local/lib/python3.8/site-packages/billiard/pool.py", line 361, in workloop
    result = (True, prepare_result(fun(*args, **kwargs)))
[2024-04-14T02:37:55.484+0000] {logging_mixin.py:188} WARNING -   File "/home/***/.local/lib/python3.8/site-packages/celery/app/trace.py", line 675, in fast_trace_task
    R, I, T, Rstr = tasks[task].__trace__(
[2024-04-14T02:37:55.485+0000] {logging_mixin.py:188} WARNING -   File "/home/***/.local/lib/python3.8/site-packages/celery/app/trace.py", line 477, in trace_task
    R = retval = fun(*args, **kwargs)
[2024-04-14T02:37:55.485+0000] {logging_mixin.py:188} WARNING -   File "/home/***/.local/lib/python3.8/site-packages/celery/app/trace.py", line 760, in __protected_call__
    return self.run(*args, **kwargs)
[2024-04-14T02:37:55.485+0000] {logging_mixin.py:188} WARNING -   File "/home/***/.local/lib/python3.8/site-packages/***/providers/celery/executors/celery_executor_utils.py", line 135, in execute_command
    _execute_in_fork(command_to_exec, celery_task_id)
[2024-04-14T02:37:55.485+0000] {logging_mixin.py:188} WARNING -   File "/home/***/.local/lib/python3.8/site-packages/***/providers/celery/executors/celery_executor_utils.py", line 169, in _execute_in_fork
    args.func(args)
[2024-04-14T02:37:55.485+0000] {logging_mixin.py:188} WARNING -   File "/home/***/.local/lib/python3.8/site-packages/***/cli/cli_config.py", line 49, in command
    return func(*args, **kwargs)
[2024-04-14T02:37:55.486+0000] {logging_mixin.py:188} WARNING -   File "/home/***/.local/lib/python3.8/site-packages/***/utils/cli.py", line 114, in wrapper
    return f(*args, **kwargs)
[2024-04-14T02:37:55.486+0000] {logging_mixin.py:188} WARNING -   File "/home/***/.local/lib/python3.8/site-packages/***/cli/commands/task_command.py", line 438, in task_run
    task_return_code = _run_task_by_selected_method(args, _dag, ti)
[2024-04-14T02:37:55.486+0000] {logging_mixin.py:188} WARNING -   File "/home/***/.local/lib/python3.8/site-packages/***/cli/commands/task_command.py", line 216, in _run_task_by_selected_method
    return _run_task_by_local_task_job(args, ti)
[2024-04-14T02:37:55.486+0000] {logging_mixin.py:188} WARNING -   File "/home/***/.local/lib/python3.8/site-packages/***/cli/commands/task_command.py", line 278, in _run_task_by_local_task_job
    ret = run_job(job=job_runner.job, execute_callable=job_runner._execute)
[2024-04-14T02:37:55.486+0000] {logging_mixin.py:188} WARNING -   File "/home/***/.local/lib/python3.8/site-packages/***/utils/session.py", line 79, in wrapper
    return func(*args, session=session, **kwargs)
[2024-04-14T02:37:55.486+0000] {logging_mixin.py:188} WARNING -   File "/home/***/.local/lib/python3.8/site-packages/***/jobs/job.py", line 395, in run_job
    return execute_job(job, execute_callable=execute_callable)
[2024-04-14T02:37:55.486+0000] {logging_mixin.py:188} WARNING -   File "/home/***/.local/lib/python3.8/site-packages/***/jobs/job.py", line 424, in execute_job
    ret = execute_callable()
[2024-04-14T02:37:55.487+0000] {logging_mixin.py:188} WARNING -   File "/home/***/.local/lib/python3.8/site-packages/***/jobs/local_task_job_runner.py", line 165, in _execute
    self.task_runner.start()
[2024-04-14T02:37:55.487+0000] {logging_mixin.py:188} WARNING -   File "/home/***/.local/lib/python3.8/site-packages/***/task/task_runner/standard_task_runner.py", line 48, in start
    self.process = self._start_by_fork()
[2024-04-14T02:37:55.487+0000] {logging_mixin.py:188} WARNING -   File "/home/***/.local/lib/python3.8/site-packages/***/task/task_runner/standard_task_runner.py", line 100, in _start_by_fork
    ret = args.func(args, dag=self.dag)
[2024-04-14T02:37:55.487+0000] {logging_mixin.py:188} WARNING -   File "/home/***/.local/lib/python3.8/site-packages/***/cli/cli_config.py", line 49, in command
    return func(*args, **kwargs)
[2024-04-14T02:37:55.487+0000] {logging_mixin.py:188} WARNING -   File "/home/***/.local/lib/python3.8/site-packages/***/utils/cli.py", line 114, in wrapper
    return f(*args, **kwargs)
[2024-04-14T02:37:55.487+0000] {logging_mixin.py:188} WARNING -   File "/home/***/.local/lib/python3.8/site-packages/***/cli/commands/task_command.py", line 438, in task_run
    task_return_code = _run_task_by_selected_method(args, _dag, ti)
[2024-04-14T02:37:55.488+0000] {logging_mixin.py:188} WARNING -   File "/home/***/.local/lib/python3.8/site-packages/***/cli/commands/task_command.py", line 218, in _run_task_by_selected_method
    return _run_raw_task(args, ti)
[2024-04-14T02:37:55.488+0000] {logging_mixin.py:188} WARNING -   File "/home/***/.local/lib/python3.8/site-packages/***/cli/commands/task_command.py", line 297, in _run_raw_task
    return ti._run_raw_task(
[2024-04-14T02:37:55.488+0000] {logging_mixin.py:188} WARNING -   File "/home/***/.local/lib/python3.8/site-packages/***/utils/session.py", line 79, in wrapper
    return func(*args, session=session, **kwargs)
[2024-04-14T02:37:55.488+0000] {logging_mixin.py:188} WARNING -   File "/home/***/.local/lib/python3.8/site-packages/***/models/taskinstance.py", line 2360, in _run_raw_task
    self._execute_task_with_callbacks(context, test_mode, session=session)
[2024-04-14T02:37:55.488+0000] {logging_mixin.py:188} WARNING -   File "/home/***/.local/lib/python3.8/site-packages/***/models/taskinstance.py", line 2532, in _execute_task_with_callbacks
    result = self._execute_task(context, task_orig)
[2024-04-14T02:37:55.488+0000] {logging_mixin.py:188} WARNING -   File "/home/***/.local/lib/python3.8/site-packages/***/models/taskinstance.py", line 2549, in _execute_task
    return _execute_task(self, context, task_orig)
[2024-04-14T02:37:55.488+0000] {logging_mixin.py:188} WARNING -   File "/home/***/.local/lib/python3.8/site-packages/***/models/taskinstance.py", line 444, in _execute_task
    result = _execute_callable(context=context, **execute_callable_kwargs)
[2024-04-14T02:37:55.488+0000] {logging_mixin.py:188} WARNING -   File "/home/***/.local/lib/python3.8/site-packages/***/models/taskinstance.py", line 414, in _execute_callable
    return execute_callable(context=context, **execute_callable_kwargs)
[2024-04-14T02:37:55.489+0000] {logging_mixin.py:188} WARNING -   File "/home/***/.local/lib/python3.8/site-packages/***/operators/python.py", line 200, in execute
    return_value = self.execute_callable()
[2024-04-14T02:37:55.489+0000] {logging_mixin.py:188} WARNING -   File "/home/***/.local/lib/python3.8/site-packages/***/operators/python.py", line 217, in execute_callable
    return self.python_callable(*self.op_args, **self.op_kwargs)
[2024-04-14T02:37:55.489+0000] {logging_mixin.py:188} WARNING -   File "/opt/***/dags/refresh_token.py", line 46, in refresh_token
    logging.info("access_token:", access_token)
[2024-04-14T02:37:55.489+0000] {logging_mixin.py:188} WARNING -   File "/usr/local/lib/python3.8/logging/__init__.py", line 2082, in info
    root.info(msg, *args, **kwargs)
[2024-04-14T02:37:55.489+0000] {logging_mixin.py:188} WARNING -   File "/usr/local/lib/python3.8/logging/__init__.py", line 1446, in info
    self._log(INFO, msg, args, **kwargs)
[2024-04-14T02:37:55.489+0000] {logging_mixin.py:188} WARNING -   File "/usr/local/lib/python3.8/logging/__init__.py", line 1589, in _log
    self.handle(record)
[2024-04-14T02:37:55.489+0000] {logging_mixin.py:188} WARNING -   File "/usr/local/lib/python3.8/logging/__init__.py", line 1599, in handle
    self.callHandlers(record)
[2024-04-14T02:37:55.490+0000] {logging_mixin.py:188} WARNING -   File "/usr/local/lib/python3.8/logging/__init__.py", line 1661, in callHandlers
    hdlr.handle(record)
[2024-04-14T02:37:55.490+0000] {logging_mixin.py:188} WARNING -   File "/usr/local/lib/python3.8/logging/__init__.py", line 954, in handle
    self.emit(record)
[2024-04-14T02:37:55.490+0000] {logging_mixin.py:188} WARNING -   File "/home/***/.local/lib/python3.8/site-packages/***/utils/log/file_task_handler.py", line 247, in emit
    self.handler.emit(record)
[2024-04-14T02:37:55.490+0000] {logging_mixin.py:188} WARNING - Message: 'access_token:'
Arguments: ('BQDxVi-6UmvapLhyem_WRO7Y7_riVAZTq8xEeQD-7CYTewSZJlGHV8j_v4pPkZtb6L43FbYWyzE16ppBb_0lneK0Tgjk5NgG3T4S_nmK9jbmCWol5tI',)
[2024-04-14T02:37:55.491+0000] {python.py:202} INFO - Done. Returned value was: None
[2024-04-14T02:37:55.494+0000] {taskinstance.py:1149} INFO - Marking task as SUCCESS. dag_id=token_refresher_50mins, task_id=refresh_token, execution_date=20240413T173000, start_date=20240414T023755, end_date=20240414T023755
[2024-04-14T02:37:55.515+0000] {local_task_job_runner.py:234} INFO - Task exited with return code 0
[2024-04-14T02:37:55.522+0000] {taskinstance.py:3312} INFO - 0 downstream tasks scheduled from follow-on schedule check
[2024-04-14T02:46:26.944+0000] {taskinstance.py:1979} INFO - Dependencies all met for dep_context=non-requeueable deps ti=<TaskInstance: token_refresher_50mins.refresh_token scheduled__2024-04-13T17:30:00+00:00 [queued]>
[2024-04-14T02:46:26.951+0000] {taskinstance.py:1979} INFO - Dependencies all met for dep_context=requeueable deps ti=<TaskInstance: token_refresher_50mins.refresh_token scheduled__2024-04-13T17:30:00+00:00 [queued]>
[2024-04-14T02:46:26.952+0000] {taskinstance.py:2193} INFO - Starting attempt 1 of 2
[2024-04-14T02:46:26.962+0000] {taskinstance.py:2217} INFO - Executing <Task(PythonOperator): refresh_token> on 2024-04-13 17:30:00+00:00
[2024-04-14T02:46:26.968+0000] {standard_task_runner.py:60} INFO - Started process 1345 to run task
[2024-04-14T02:46:26.971+0000] {standard_task_runner.py:87} INFO - Running: ['***', 'tasks', 'run', 'token_refresher_50mins', 'refresh_token', 'scheduled__2024-04-13T17:30:00+00:00', '--job-id', '258', '--raw', '--subdir', 'DAGS_FOLDER/refresh_token.py', '--cfg-path', '/tmp/tmpvu8sb9h0']
[2024-04-14T02:46:26.973+0000] {standard_task_runner.py:88} INFO - Job 258: Subtask refresh_token
[2024-04-14T02:46:27.026+0000] {task_command.py:423} INFO - Running <TaskInstance: token_refresher_50mins.refresh_token scheduled__2024-04-13T17:30:00+00:00 [running]> on host 209a9ac884b0
[2024-04-14T02:46:27.108+0000] {taskinstance.py:2513} INFO - Exporting env vars: AIRFLOW_CTX_DAG_OWNER='***' AIRFLOW_CTX_DAG_ID='token_refresher_50mins' AIRFLOW_CTX_TASK_ID='refresh_token' AIRFLOW_CTX_EXECUTION_DATE='2024-04-13T17:30:00+00:00' AIRFLOW_CTX_TRY_NUMBER='1' AIRFLOW_CTX_DAG_RUN_ID='scheduled__2024-04-13T17:30:00+00:00'
[2024-04-14T02:46:27.191+0000] {logging_mixin.py:188} WARNING - --- Logging error ---
[2024-04-14T02:46:27.193+0000] {logging_mixin.py:188} WARNING - Traceback (most recent call last):
[2024-04-14T02:46:27.194+0000] {logging_mixin.py:188} WARNING -   File "/usr/local/lib/python3.8/logging/__init__.py", line 1085, in emit
    msg = self.format(record)
[2024-04-14T02:46:27.196+0000] {logging_mixin.py:188} WARNING -   File "/usr/local/lib/python3.8/logging/__init__.py", line 929, in format
    return fmt.format(record)
[2024-04-14T02:46:27.197+0000] {logging_mixin.py:188} WARNING -   File "/usr/local/lib/python3.8/logging/__init__.py", line 668, in format
    record.message = record.getMessage()
[2024-04-14T02:46:27.197+0000] {logging_mixin.py:188} WARNING -   File "/usr/local/lib/python3.8/logging/__init__.py", line 373, in getMessage
    msg = msg % self.args
[2024-04-14T02:46:27.199+0000] {logging_mixin.py:188} WARNING - TypeError: not all arguments converted during string formatting
[2024-04-14T02:46:27.200+0000] {logging_mixin.py:188} WARNING - Call stack:
[2024-04-14T02:46:27.206+0000] {logging_mixin.py:188} WARNING -   File "/home/***/.local/bin/***", line 8, in <module>
    sys.exit(main())
[2024-04-14T02:46:27.209+0000] {logging_mixin.py:188} WARNING -   File "/home/***/.local/lib/python3.8/site-packages/***/__main__.py", line 57, in main
    args.func(args)
[2024-04-14T02:46:27.211+0000] {logging_mixin.py:188} WARNING -   File "/home/***/.local/lib/python3.8/site-packages/***/cli/cli_config.py", line 49, in command
    return func(*args, **kwargs)
[2024-04-14T02:46:27.212+0000] {logging_mixin.py:188} WARNING -   File "/home/***/.local/lib/python3.8/site-packages/***/utils/cli.py", line 114, in wrapper
    return f(*args, **kwargs)
[2024-04-14T02:46:27.215+0000] {logging_mixin.py:188} WARNING -   File "/home/***/.local/lib/python3.8/site-packages/***/providers/celery/cli/celery_command.py", line 60, in wrapper
    providers_configuration_loaded(func)(*args, **kwargs)
[2024-04-14T02:46:27.217+0000] {logging_mixin.py:188} WARNING -   File "/home/***/.local/lib/python3.8/site-packages/***/utils/providers_configuration_loader.py", line 55, in wrapped_function
    return func(*args, **kwargs)
[2024-04-14T02:46:27.218+0000] {logging_mixin.py:188} WARNING -   File "/home/***/.local/lib/python3.8/site-packages/***/providers/celery/cli/celery_command.py", line 231, in worker
    _run_command_with_daemon_option(
[2024-04-14T02:46:27.219+0000] {logging_mixin.py:188} WARNING -   File "/home/***/.local/lib/python3.8/site-packages/***/providers/celery/cli/celery_command.py", line 46, in _run_command_with_daemon_option
    run_command_with_daemon_option(*args, **kwargs)
[2024-04-14T02:46:27.223+0000] {logging_mixin.py:188} WARNING -   File "/home/***/.local/lib/python3.8/site-packages/***/cli/commands/daemon_utils.py", line 86, in run_command_with_daemon_option
    callback()
[2024-04-14T02:46:27.224+0000] {logging_mixin.py:188} WARNING -   File "/home/***/.local/lib/python3.8/site-packages/***/providers/celery/cli/celery_command.py", line 224, in run_celery_worker
    celery_app.worker_main(options)
[2024-04-14T02:46:27.227+0000] {logging_mixin.py:188} WARNING -   File "/home/***/.local/lib/python3.8/site-packages/celery/app/base.py", line 389, in worker_main
    self.start(argv=argv)
[2024-04-14T02:46:27.229+0000] {logging_mixin.py:188} WARNING -   File "/home/***/.local/lib/python3.8/site-packages/celery/app/base.py", line 369, in start
    celery.main(args=argv, standalone_mode=False)
[2024-04-14T02:46:27.230+0000] {logging_mixin.py:188} WARNING -   File "/home/***/.local/lib/python3.8/site-packages/click/core.py", line 1078, in main
    rv = self.invoke(ctx)
[2024-04-14T02:46:27.238+0000] {logging_mixin.py:188} WARNING -   File "/home/***/.local/lib/python3.8/site-packages/click/core.py", line 1688, in invoke
    return _process_result(sub_ctx.command.invoke(sub_ctx))
[2024-04-14T02:46:27.242+0000] {logging_mixin.py:188} WARNING -   File "/home/***/.local/lib/python3.8/site-packages/click/core.py", line 1434, in invoke
    return ctx.invoke(self.callback, **ctx.params)
[2024-04-14T02:46:27.246+0000] {logging_mixin.py:188} WARNING -   File "/home/***/.local/lib/python3.8/site-packages/click/core.py", line 783, in invoke
    return __callback(*args, **kwargs)
[2024-04-14T02:46:27.247+0000] {logging_mixin.py:188} WARNING -   File "/home/***/.local/lib/python3.8/site-packages/click/decorators.py", line 33, in new_func
    return f(get_current_context(), *args, **kwargs)
[2024-04-14T02:46:27.251+0000] {logging_mixin.py:188} WARNING -   File "/home/***/.local/lib/python3.8/site-packages/celery/bin/base.py", line 134, in caller
    return f(ctx, *args, **kwargs)
[2024-04-14T02:46:27.256+0000] {logging_mixin.py:188} WARNING -   File "/home/***/.local/lib/python3.8/site-packages/celery/bin/worker.py", line 356, in worker
    worker.start()
[2024-04-14T02:46:27.263+0000] {logging_mixin.py:188} WARNING -   File "/home/***/.local/lib/python3.8/site-packages/celery/worker/worker.py", line 202, in start
    self.blueprint.start(self)
[2024-04-14T02:46:27.268+0000] {logging_mixin.py:188} WARNING -   File "/home/***/.local/lib/python3.8/site-packages/celery/bootsteps.py", line 116, in start
    step.start(parent)
[2024-04-14T02:46:27.269+0000] {logging_mixin.py:188} WARNING -   File "/home/***/.local/lib/python3.8/site-packages/celery/bootsteps.py", line 365, in start
    return self.obj.start()
[2024-04-14T02:46:27.271+0000] {logging_mixin.py:188} WARNING -   File "/home/***/.local/lib/python3.8/site-packages/celery/concurrency/base.py", line 130, in start
    self.on_start()
[2024-04-14T02:46:27.273+0000] {logging_mixin.py:188} WARNING -   File "/home/***/.local/lib/python3.8/site-packages/celery/concurrency/prefork.py", line 109, in on_start
    P = self._pool = Pool(processes=self.limit,
[2024-04-14T02:46:27.274+0000] {logging_mixin.py:188} WARNING -   File "/home/***/.local/lib/python3.8/site-packages/celery/concurrency/asynpool.py", line 464, in __init__
    super().__init__(processes, *args, **kwargs)
[2024-04-14T02:46:27.275+0000] {logging_mixin.py:188} WARNING -   File "/home/***/.local/lib/python3.8/site-packages/billiard/pool.py", line 1045, in __init__
    self._create_worker_process(i)
[2024-04-14T02:46:27.276+0000] {logging_mixin.py:188} WARNING -   File "/home/***/.local/lib/python3.8/site-packages/celery/concurrency/asynpool.py", line 482, in _create_worker_process
    return super()._create_worker_process(i)
[2024-04-14T02:46:27.277+0000] {logging_mixin.py:188} WARNING -   File "/home/***/.local/lib/python3.8/site-packages/billiard/pool.py", line 1157, in _create_worker_process
    w.start()
[2024-04-14T02:46:27.277+0000] {logging_mixin.py:188} WARNING -   File "/home/***/.local/lib/python3.8/site-packages/billiard/process.py", line 120, in start
    self._popen = self._Popen(self)
[2024-04-14T02:46:27.278+0000] {logging_mixin.py:188} WARNING -   File "/home/***/.local/lib/python3.8/site-packages/billiard/context.py", line 331, in _Popen
    return Popen(process_obj)
[2024-04-14T02:46:27.279+0000] {logging_mixin.py:188} WARNING -   File "/home/***/.local/lib/python3.8/site-packages/billiard/popen_fork.py", line 22, in __init__
    self._launch(process_obj)
[2024-04-14T02:46:27.283+0000] {logging_mixin.py:188} WARNING -   File "/home/***/.local/lib/python3.8/site-packages/billiard/popen_fork.py", line 77, in _launch
    code = process_obj._bootstrap()
[2024-04-14T02:46:27.284+0000] {logging_mixin.py:188} WARNING -   File "/home/***/.local/lib/python3.8/site-packages/billiard/process.py", line 323, in _bootstrap
    self.run()
[2024-04-14T02:46:27.289+0000] {logging_mixin.py:188} WARNING -   File "/home/***/.local/lib/python3.8/site-packages/billiard/process.py", line 110, in run
    self._target(*self._args, **self._kwargs)
[2024-04-14T02:46:27.290+0000] {logging_mixin.py:188} WARNING -   File "/home/***/.local/lib/python3.8/site-packages/billiard/pool.py", line 291, in __call__
    sys.exit(self.workloop(pid=pid))
[2024-04-14T02:46:27.291+0000] {logging_mixin.py:188} WARNING -   File "/home/***/.local/lib/python3.8/site-packages/billiard/pool.py", line 361, in workloop
    result = (True, prepare_result(fun(*args, **kwargs)))
[2024-04-14T02:46:27.292+0000] {logging_mixin.py:188} WARNING -   File "/home/***/.local/lib/python3.8/site-packages/celery/app/trace.py", line 675, in fast_trace_task
    R, I, T, Rstr = tasks[task].__trace__(
[2024-04-14T02:46:27.293+0000] {logging_mixin.py:188} WARNING -   File "/home/***/.local/lib/python3.8/site-packages/celery/app/trace.py", line 477, in trace_task
    R = retval = fun(*args, **kwargs)
[2024-04-14T02:46:27.295+0000] {logging_mixin.py:188} WARNING -   File "/home/***/.local/lib/python3.8/site-packages/celery/app/trace.py", line 760, in __protected_call__
    return self.run(*args, **kwargs)
[2024-04-14T02:46:27.297+0000] {logging_mixin.py:188} WARNING -   File "/home/***/.local/lib/python3.8/site-packages/***/providers/celery/executors/celery_executor_utils.py", line 135, in execute_command
    _execute_in_fork(command_to_exec, celery_task_id)
[2024-04-14T02:46:27.298+0000] {logging_mixin.py:188} WARNING -   File "/home/***/.local/lib/python3.8/site-packages/***/providers/celery/executors/celery_executor_utils.py", line 169, in _execute_in_fork
    args.func(args)
[2024-04-14T02:46:27.299+0000] {logging_mixin.py:188} WARNING -   File "/home/***/.local/lib/python3.8/site-packages/***/cli/cli_config.py", line 49, in command
    return func(*args, **kwargs)
[2024-04-14T02:46:27.302+0000] {logging_mixin.py:188} WARNING -   File "/home/***/.local/lib/python3.8/site-packages/***/utils/cli.py", line 114, in wrapper
    return f(*args, **kwargs)
[2024-04-14T02:46:27.305+0000] {logging_mixin.py:188} WARNING -   File "/home/***/.local/lib/python3.8/site-packages/***/cli/commands/task_command.py", line 438, in task_run
    task_return_code = _run_task_by_selected_method(args, _dag, ti)
[2024-04-14T02:46:27.306+0000] {logging_mixin.py:188} WARNING -   File "/home/***/.local/lib/python3.8/site-packages/***/cli/commands/task_command.py", line 216, in _run_task_by_selected_method
    return _run_task_by_local_task_job(args, ti)
[2024-04-14T02:46:27.307+0000] {logging_mixin.py:188} WARNING -   File "/home/***/.local/lib/python3.8/site-packages/***/cli/commands/task_command.py", line 278, in _run_task_by_local_task_job
    ret = run_job(job=job_runner.job, execute_callable=job_runner._execute)
[2024-04-14T02:46:27.307+0000] {logging_mixin.py:188} WARNING -   File "/home/***/.local/lib/python3.8/site-packages/***/utils/session.py", line 79, in wrapper
    return func(*args, session=session, **kwargs)
[2024-04-14T02:46:27.309+0000] {logging_mixin.py:188} WARNING -   File "/home/***/.local/lib/python3.8/site-packages/***/jobs/job.py", line 395, in run_job
    return execute_job(job, execute_callable=execute_callable)
[2024-04-14T02:46:27.310+0000] {logging_mixin.py:188} WARNING -   File "/home/***/.local/lib/python3.8/site-packages/***/jobs/job.py", line 424, in execute_job
    ret = execute_callable()
[2024-04-14T02:46:27.311+0000] {logging_mixin.py:188} WARNING -   File "/home/***/.local/lib/python3.8/site-packages/***/jobs/local_task_job_runner.py", line 165, in _execute
    self.task_runner.start()
[2024-04-14T02:46:27.312+0000] {logging_mixin.py:188} WARNING -   File "/home/***/.local/lib/python3.8/site-packages/***/task/task_runner/standard_task_runner.py", line 48, in start
    self.process = self._start_by_fork()
[2024-04-14T02:46:27.312+0000] {logging_mixin.py:188} WARNING -   File "/home/***/.local/lib/python3.8/site-packages/***/task/task_runner/standard_task_runner.py", line 100, in _start_by_fork
    ret = args.func(args, dag=self.dag)
[2024-04-14T02:46:27.313+0000] {logging_mixin.py:188} WARNING -   File "/home/***/.local/lib/python3.8/site-packages/***/cli/cli_config.py", line 49, in command
    return func(*args, **kwargs)
[2024-04-14T02:46:27.313+0000] {logging_mixin.py:188} WARNING -   File "/home/***/.local/lib/python3.8/site-packages/***/utils/cli.py", line 114, in wrapper
    return f(*args, **kwargs)
[2024-04-14T02:46:27.316+0000] {logging_mixin.py:188} WARNING -   File "/home/***/.local/lib/python3.8/site-packages/***/cli/commands/task_command.py", line 438, in task_run
    task_return_code = _run_task_by_selected_method(args, _dag, ti)
[2024-04-14T02:46:27.318+0000] {logging_mixin.py:188} WARNING -   File "/home/***/.local/lib/python3.8/site-packages/***/cli/commands/task_command.py", line 218, in _run_task_by_selected_method
    return _run_raw_task(args, ti)
[2024-04-14T02:46:27.321+0000] {logging_mixin.py:188} WARNING -   File "/home/***/.local/lib/python3.8/site-packages/***/cli/commands/task_command.py", line 297, in _run_raw_task
    return ti._run_raw_task(
[2024-04-14T02:46:27.323+0000] {logging_mixin.py:188} WARNING -   File "/home/***/.local/lib/python3.8/site-packages/***/utils/session.py", line 79, in wrapper
    return func(*args, session=session, **kwargs)
[2024-04-14T02:46:27.324+0000] {logging_mixin.py:188} WARNING -   File "/home/***/.local/lib/python3.8/site-packages/***/models/taskinstance.py", line 2360, in _run_raw_task
    self._execute_task_with_callbacks(context, test_mode, session=session)
[2024-04-14T02:46:27.324+0000] {logging_mixin.py:188} WARNING -   File "/home/***/.local/lib/python3.8/site-packages/***/models/taskinstance.py", line 2532, in _execute_task_with_callbacks
    result = self._execute_task(context, task_orig)
[2024-04-14T02:46:27.324+0000] {logging_mixin.py:188} WARNING -   File "/home/***/.local/lib/python3.8/site-packages/***/models/taskinstance.py", line 2549, in _execute_task
    return _execute_task(self, context, task_orig)
[2024-04-14T02:46:27.325+0000] {logging_mixin.py:188} WARNING -   File "/home/***/.local/lib/python3.8/site-packages/***/models/taskinstance.py", line 444, in _execute_task
    result = _execute_callable(context=context, **execute_callable_kwargs)
[2024-04-14T02:46:27.325+0000] {logging_mixin.py:188} WARNING -   File "/home/***/.local/lib/python3.8/site-packages/***/models/taskinstance.py", line 414, in _execute_callable
    return execute_callable(context=context, **execute_callable_kwargs)
[2024-04-14T02:46:27.326+0000] {logging_mixin.py:188} WARNING -   File "/home/***/.local/lib/python3.8/site-packages/***/operators/python.py", line 200, in execute
    return_value = self.execute_callable()
[2024-04-14T02:46:27.327+0000] {logging_mixin.py:188} WARNING -   File "/home/***/.local/lib/python3.8/site-packages/***/operators/python.py", line 217, in execute_callable
    return self.python_callable(*self.op_args, **self.op_kwargs)
[2024-04-14T02:46:27.328+0000] {logging_mixin.py:188} WARNING -   File "/opt/***/dags/refresh_token.py", line 42, in refresh_token
    logging.info("access_token:", access_token)
[2024-04-14T02:46:27.328+0000] {logging_mixin.py:188} WARNING -   File "/usr/local/lib/python3.8/logging/__init__.py", line 2082, in info
    root.info(msg, *args, **kwargs)
[2024-04-14T02:46:27.328+0000] {logging_mixin.py:188} WARNING -   File "/usr/local/lib/python3.8/logging/__init__.py", line 1446, in info
    self._log(INFO, msg, args, **kwargs)
[2024-04-14T02:46:27.329+0000] {logging_mixin.py:188} WARNING -   File "/usr/local/lib/python3.8/logging/__init__.py", line 1589, in _log
    self.handle(record)
[2024-04-14T02:46:27.329+0000] {logging_mixin.py:188} WARNING -   File "/usr/local/lib/python3.8/logging/__init__.py", line 1599, in handle
    self.callHandlers(record)
[2024-04-14T02:46:27.329+0000] {logging_mixin.py:188} WARNING -   File "/usr/local/lib/python3.8/logging/__init__.py", line 1661, in callHandlers
    hdlr.handle(record)
[2024-04-14T02:46:27.329+0000] {logging_mixin.py:188} WARNING -   File "/usr/local/lib/python3.8/logging/__init__.py", line 954, in handle
    self.emit(record)
[2024-04-14T02:46:27.329+0000] {logging_mixin.py:188} WARNING -   File "/home/***/.local/lib/python3.8/site-packages/***/utils/log/file_task_handler.py", line 247, in emit
    self.handler.emit(record)
[2024-04-14T02:46:27.330+0000] {logging_mixin.py:188} WARNING - Message: 'access_token:'
Arguments: ('BQCFSzUiAkfd-hAQWuaxQB3LO8I9yBtQtTtKuPFxr-HHrulfqmPqg1rKyKLYdOpd_HPdU3v6atSgqw6fHGamy6wG8aF6UQQS6WBzyUVuGE4JjKMRxKw',)
[2024-04-14T02:46:27.330+0000] {python.py:202} INFO - Done. Returned value was: None
[2024-04-14T02:46:27.346+0000] {taskinstance.py:1149} INFO - Marking task as SUCCESS. dag_id=token_refresher_50mins, task_id=refresh_token, execution_date=20240413T173000, start_date=20240414T024626, end_date=20240414T024627
[2024-04-14T02:46:27.398+0000] {local_task_job_runner.py:234} INFO - Task exited with return code 0
[2024-04-14T02:46:27.414+0000] {taskinstance.py:3312} INFO - 1 downstream tasks scheduled from follow-on schedule check
