[2024-04-13T18:37:59.112+0000] {taskinstance.py:1979} INFO - Dependencies all met for dep_context=non-requeueable deps ti=<TaskInstance: token_refresher_50mins.refresh_token scheduled__2024-04-13T05:00:00+00:00 [queued]>
[2024-04-13T18:37:59.117+0000] {taskinstance.py:1979} INFO - Dependencies all met for dep_context=requeueable deps ti=<TaskInstance: token_refresher_50mins.refresh_token scheduled__2024-04-13T05:00:00+00:00 [queued]>
[2024-04-13T18:37:59.119+0000] {taskinstance.py:2193} INFO - Starting attempt 1 of 2
[2024-04-13T18:37:59.128+0000] {taskinstance.py:2217} INFO - Executing <Task(PythonOperator): refresh_token> on 2024-04-13 05:00:00+00:00
[2024-04-13T18:37:59.131+0000] {standard_task_runner.py:60} INFO - Started process 449 to run task
[2024-04-13T18:37:59.134+0000] {standard_task_runner.py:87} INFO - Running: ['***', 'tasks', 'run', 'token_refresher_50mins', 'refresh_token', 'scheduled__2024-04-13T05:00:00+00:00', '--job-id', '13', '--raw', '--subdir', 'DAGS_FOLDER/refresh_token.py', '--cfg-path', '/tmp/tmp5q6nqfjw']
[2024-04-13T18:37:59.137+0000] {standard_task_runner.py:88} INFO - Job 13: Subtask refresh_token
[2024-04-13T18:37:59.190+0000] {task_command.py:423} INFO - Running <TaskInstance: token_refresher_50mins.refresh_token scheduled__2024-04-13T05:00:00+00:00 [running]> on host 209a9ac884b0
[2024-04-13T18:37:59.239+0000] {taskinstance.py:2513} INFO - Exporting env vars: AIRFLOW_CTX_DAG_OWNER='***' AIRFLOW_CTX_DAG_ID='token_refresher_50mins' AIRFLOW_CTX_TASK_ID='refresh_token' AIRFLOW_CTX_EXECUTION_DATE='2024-04-13T05:00:00+00:00' AIRFLOW_CTX_TRY_NUMBER='1' AIRFLOW_CTX_DAG_RUN_ID='scheduled__2024-04-13T05:00:00+00:00'
[2024-04-13T18:37:59.240+0000] {oauth2.py:471} INFO - User authentication requires interaction with your web browser. Once you enter your credentials and give authorization, you will be redirected to a url.  Paste that url you were directed to to complete the authorization.
[2024-04-13T18:37:59.241+0000] {taskinstance.py:2731} ERROR - Task failed with exception
Traceback (most recent call last):
  File "/home/airflow/.local/lib/python3.8/site-packages/airflow/models/taskinstance.py", line 444, in _execute_task
    result = _execute_callable(context=context, **execute_callable_kwargs)
  File "/home/airflow/.local/lib/python3.8/site-packages/airflow/models/taskinstance.py", line 414, in _execute_callable
    return execute_callable(context=context, **execute_callable_kwargs)
  File "/home/airflow/.local/lib/python3.8/site-packages/airflow/operators/python.py", line 200, in execute
    return_value = self.execute_callable()
  File "/home/airflow/.local/lib/python3.8/site-packages/airflow/operators/python.py", line 217, in execute_callable
    return self.python_callable(*self.op_args, **self.op_kwargs)
  File "/opt/airflow/dags/refresh_token.py", line 34, in refresh_token
    current_user = sp.current_user()
  File "/home/airflow/.local/lib/python3.8/site-packages/spotipy/client.py", line 1227, in current_user
    return self.me()
  File "/home/airflow/.local/lib/python3.8/site-packages/spotipy/client.py", line 1221, in me
    return self._get("me/")
  File "/home/airflow/.local/lib/python3.8/site-packages/spotipy/client.py", line 323, in _get
    return self._internal_call("GET", url, payload, kwargs)
  File "/home/airflow/.local/lib/python3.8/site-packages/spotipy/client.py", line 247, in _internal_call
    headers = self._auth_headers()
  File "/home/airflow/.local/lib/python3.8/site-packages/spotipy/client.py", line 238, in _auth_headers
    token = self.auth_manager.get_access_token(as_dict=False)
  File "/home/airflow/.local/lib/python3.8/site-packages/spotipy/oauth2.py", line 535, in get_access_token
    "code": code or self.get_auth_response(),
  File "/home/airflow/.local/lib/python3.8/site-packages/spotipy/oauth2.py", line 490, in get_auth_response
    return self._get_auth_response_local_server(redirect_port)
  File "/home/airflow/.local/lib/python3.8/site-packages/spotipy/oauth2.py", line 457, in _get_auth_response_local_server
    server = start_local_http_server(redirect_port)
  File "/home/airflow/.local/lib/python3.8/site-packages/spotipy/oauth2.py", line 1303, in start_local_http_server
    server = HTTPServer(("127.0.0.1", port), handler)
  File "/usr/local/lib/python3.8/socketserver.py", line 452, in __init__
    self.server_bind()
  File "/usr/local/lib/python3.8/http/server.py", line 139, in server_bind
    socketserver.TCPServer.server_bind(self)
  File "/usr/local/lib/python3.8/socketserver.py", line 466, in server_bind
    self.socket.bind(self.server_address)
OSError: [Errno 98] Address already in use
[2024-04-13T18:37:59.247+0000] {taskinstance.py:1149} INFO - Marking task as UP_FOR_RETRY. dag_id=token_refresher_50mins, task_id=refresh_token, execution_date=20240413T050000, start_date=20240413T183759, end_date=20240413T183759
[2024-04-13T18:37:59.252+0000] {standard_task_runner.py:107} ERROR - Failed to execute job 13 for task refresh_token ([Errno 98] Address already in use; 449)
[2024-04-13T18:37:59.277+0000] {local_task_job_runner.py:234} INFO - Task exited with return code 1
[2024-04-13T18:37:59.301+0000] {taskinstance.py:3312} INFO - 0 downstream tasks scheduled from follow-on schedule check
[2024-04-13T18:39:59.966+0000] {taskinstance.py:1979} INFO - Dependencies all met for dep_context=non-requeueable deps ti=<TaskInstance: token_refresher_50mins.refresh_token scheduled__2024-04-13T05:00:00+00:00 [queued]>
[2024-04-13T18:39:59.970+0000] {taskinstance.py:1979} INFO - Dependencies all met for dep_context=requeueable deps ti=<TaskInstance: token_refresher_50mins.refresh_token scheduled__2024-04-13T05:00:00+00:00 [queued]>
[2024-04-13T18:39:59.971+0000] {taskinstance.py:2193} INFO - Starting attempt 1 of 2
[2024-04-13T18:39:59.976+0000] {taskinstance.py:2217} INFO - Executing <Task(PythonOperator): refresh_token> on 2024-04-13 05:00:00+00:00
[2024-04-13T18:39:59.979+0000] {standard_task_runner.py:60} INFO - Started process 514 to run task
[2024-04-13T18:39:59.980+0000] {standard_task_runner.py:87} INFO - Running: ['***', 'tasks', 'run', 'token_refresher_50mins', 'refresh_token', 'scheduled__2024-04-13T05:00:00+00:00', '--job-id', '30', '--raw', '--subdir', 'DAGS_FOLDER/refresh_token.py', '--cfg-path', '/tmp/tmpxp9coybi']
[2024-04-13T18:39:59.981+0000] {standard_task_runner.py:88} INFO - Job 30: Subtask refresh_token
[2024-04-13T18:40:00.009+0000] {task_command.py:423} INFO - Running <TaskInstance: token_refresher_50mins.refresh_token scheduled__2024-04-13T05:00:00+00:00 [running]> on host 209a9ac884b0
[2024-04-13T18:40:00.048+0000] {taskinstance.py:2513} INFO - Exporting env vars: AIRFLOW_CTX_DAG_OWNER='***' AIRFLOW_CTX_DAG_ID='token_refresher_50mins' AIRFLOW_CTX_TASK_ID='refresh_token' AIRFLOW_CTX_EXECUTION_DATE='2024-04-13T05:00:00+00:00' AIRFLOW_CTX_TRY_NUMBER='1' AIRFLOW_CTX_DAG_RUN_ID='scheduled__2024-04-13T05:00:00+00:00'
[2024-04-13T18:40:00.052+0000] {oauth2.py:471} INFO - User authentication requires interaction with your web browser. Once you enter your credentials and give authorization, you will be redirected to a url.  Paste that url you were directed to to complete the authorization.
[2024-04-13T18:40:00.053+0000] {taskinstance.py:2731} ERROR - Task failed with exception
Traceback (most recent call last):
  File "/home/airflow/.local/lib/python3.8/site-packages/airflow/models/taskinstance.py", line 444, in _execute_task
    result = _execute_callable(context=context, **execute_callable_kwargs)
  File "/home/airflow/.local/lib/python3.8/site-packages/airflow/models/taskinstance.py", line 414, in _execute_callable
    return execute_callable(context=context, **execute_callable_kwargs)
  File "/home/airflow/.local/lib/python3.8/site-packages/airflow/operators/python.py", line 200, in execute
    return_value = self.execute_callable()
  File "/home/airflow/.local/lib/python3.8/site-packages/airflow/operators/python.py", line 217, in execute_callable
    return self.python_callable(*self.op_args, **self.op_kwargs)
  File "/opt/airflow/dags/refresh_token.py", line 34, in refresh_token
    current_user = sp.current_user()
  File "/home/airflow/.local/lib/python3.8/site-packages/spotipy/client.py", line 1227, in current_user
    return self.me()
  File "/home/airflow/.local/lib/python3.8/site-packages/spotipy/client.py", line 1221, in me
    return self._get("me/")
  File "/home/airflow/.local/lib/python3.8/site-packages/spotipy/client.py", line 323, in _get
    return self._internal_call("GET", url, payload, kwargs)
  File "/home/airflow/.local/lib/python3.8/site-packages/spotipy/client.py", line 247, in _internal_call
    headers = self._auth_headers()
  File "/home/airflow/.local/lib/python3.8/site-packages/spotipy/client.py", line 238, in _auth_headers
    token = self.auth_manager.get_access_token(as_dict=False)
  File "/home/airflow/.local/lib/python3.8/site-packages/spotipy/oauth2.py", line 535, in get_access_token
    "code": code or self.get_auth_response(),
  File "/home/airflow/.local/lib/python3.8/site-packages/spotipy/oauth2.py", line 490, in get_auth_response
    return self._get_auth_response_local_server(redirect_port)
  File "/home/airflow/.local/lib/python3.8/site-packages/spotipy/oauth2.py", line 457, in _get_auth_response_local_server
    server = start_local_http_server(redirect_port)
  File "/home/airflow/.local/lib/python3.8/site-packages/spotipy/oauth2.py", line 1303, in start_local_http_server
    server = HTTPServer(("127.0.0.1", port), handler)
  File "/usr/local/lib/python3.8/socketserver.py", line 452, in __init__
    self.server_bind()
  File "/usr/local/lib/python3.8/http/server.py", line 139, in server_bind
    socketserver.TCPServer.server_bind(self)
  File "/usr/local/lib/python3.8/socketserver.py", line 466, in server_bind
    self.socket.bind(self.server_address)
OSError: [Errno 98] Address already in use
[2024-04-13T18:40:00.058+0000] {taskinstance.py:1149} INFO - Marking task as UP_FOR_RETRY. dag_id=token_refresher_50mins, task_id=refresh_token, execution_date=20240413T050000, start_date=20240413T183959, end_date=20240413T184000
[2024-04-13T18:40:00.066+0000] {standard_task_runner.py:107} ERROR - Failed to execute job 30 for task refresh_token ([Errno 98] Address already in use; 514)
[2024-04-13T18:40:00.077+0000] {local_task_job_runner.py:234} INFO - Task exited with return code 1
[2024-04-13T18:40:00.096+0000] {taskinstance.py:3312} INFO - 0 downstream tasks scheduled from follow-on schedule check
[2024-04-13T18:41:30.424+0000] {taskinstance.py:1979} INFO - Dependencies all met for dep_context=non-requeueable deps ti=<TaskInstance: token_refresher_50mins.refresh_token scheduled__2024-04-13T05:00:00+00:00 [queued]>
[2024-04-13T18:41:30.430+0000] {taskinstance.py:1979} INFO - Dependencies all met for dep_context=requeueable deps ti=<TaskInstance: token_refresher_50mins.refresh_token scheduled__2024-04-13T05:00:00+00:00 [queued]>
[2024-04-13T18:41:30.430+0000] {taskinstance.py:2193} INFO - Starting attempt 1 of 2
[2024-04-13T18:41:30.465+0000] {taskinstance.py:2217} INFO - Executing <Task(PythonOperator): refresh_token> on 2024-04-13 05:00:00+00:00
[2024-04-13T18:41:30.468+0000] {standard_task_runner.py:60} INFO - Started process 568 to run task
[2024-04-13T18:41:30.472+0000] {standard_task_runner.py:87} INFO - Running: ['***', 'tasks', 'run', 'token_refresher_50mins', 'refresh_token', 'scheduled__2024-04-13T05:00:00+00:00', '--job-id', '45', '--raw', '--subdir', 'DAGS_FOLDER/refresh_token.py', '--cfg-path', '/tmp/tmpgn7l8vli']
[2024-04-13T18:41:30.474+0000] {standard_task_runner.py:88} INFO - Job 45: Subtask refresh_token
[2024-04-13T18:41:30.560+0000] {task_command.py:423} INFO - Running <TaskInstance: token_refresher_50mins.refresh_token scheduled__2024-04-13T05:00:00+00:00 [running]> on host 209a9ac884b0
[2024-04-13T18:41:30.614+0000] {taskinstance.py:2513} INFO - Exporting env vars: AIRFLOW_CTX_DAG_OWNER='***' AIRFLOW_CTX_DAG_ID='token_refresher_50mins' AIRFLOW_CTX_TASK_ID='refresh_token' AIRFLOW_CTX_EXECUTION_DATE='2024-04-13T05:00:00+00:00' AIRFLOW_CTX_TRY_NUMBER='1' AIRFLOW_CTX_DAG_RUN_ID='scheduled__2024-04-13T05:00:00+00:00'
[2024-04-13T18:41:30.616+0000] {oauth2.py:471} INFO - User authentication requires interaction with your web browser. Once you enter your credentials and give authorization, you will be redirected to a url.  Paste that url you were directed to to complete the authorization.
[2024-04-13T18:41:30.617+0000] {taskinstance.py:2731} ERROR - Task failed with exception
Traceback (most recent call last):
  File "/home/airflow/.local/lib/python3.8/site-packages/airflow/models/taskinstance.py", line 444, in _execute_task
    result = _execute_callable(context=context, **execute_callable_kwargs)
  File "/home/airflow/.local/lib/python3.8/site-packages/airflow/models/taskinstance.py", line 414, in _execute_callable
    return execute_callable(context=context, **execute_callable_kwargs)
  File "/home/airflow/.local/lib/python3.8/site-packages/airflow/operators/python.py", line 200, in execute
    return_value = self.execute_callable()
  File "/home/airflow/.local/lib/python3.8/site-packages/airflow/operators/python.py", line 217, in execute_callable
    return self.python_callable(*self.op_args, **self.op_kwargs)
  File "/opt/airflow/dags/refresh_token.py", line 34, in refresh_token
    current_user = sp.current_user()
  File "/home/airflow/.local/lib/python3.8/site-packages/spotipy/client.py", line 1227, in current_user
    return self.me()
  File "/home/airflow/.local/lib/python3.8/site-packages/spotipy/client.py", line 1221, in me
    return self._get("me/")
  File "/home/airflow/.local/lib/python3.8/site-packages/spotipy/client.py", line 323, in _get
    return self._internal_call("GET", url, payload, kwargs)
  File "/home/airflow/.local/lib/python3.8/site-packages/spotipy/client.py", line 247, in _internal_call
    headers = self._auth_headers()
  File "/home/airflow/.local/lib/python3.8/site-packages/spotipy/client.py", line 238, in _auth_headers
    token = self.auth_manager.get_access_token(as_dict=False)
  File "/home/airflow/.local/lib/python3.8/site-packages/spotipy/oauth2.py", line 535, in get_access_token
    "code": code or self.get_auth_response(),
  File "/home/airflow/.local/lib/python3.8/site-packages/spotipy/oauth2.py", line 490, in get_auth_response
    return self._get_auth_response_local_server(redirect_port)
  File "/home/airflow/.local/lib/python3.8/site-packages/spotipy/oauth2.py", line 457, in _get_auth_response_local_server
    server = start_local_http_server(redirect_port)
  File "/home/airflow/.local/lib/python3.8/site-packages/spotipy/oauth2.py", line 1303, in start_local_http_server
    server = HTTPServer(("127.0.0.1", port), handler)
  File "/usr/local/lib/python3.8/socketserver.py", line 452, in __init__
    self.server_bind()
  File "/usr/local/lib/python3.8/http/server.py", line 139, in server_bind
    socketserver.TCPServer.server_bind(self)
  File "/usr/local/lib/python3.8/socketserver.py", line 466, in server_bind
    self.socket.bind(self.server_address)
OSError: [Errno 98] Address already in use
[2024-04-13T18:41:30.623+0000] {taskinstance.py:1149} INFO - Marking task as UP_FOR_RETRY. dag_id=token_refresher_50mins, task_id=refresh_token, execution_date=20240413T050000, start_date=20240413T184130, end_date=20240413T184130
[2024-04-13T18:41:30.631+0000] {standard_task_runner.py:107} ERROR - Failed to execute job 45 for task refresh_token ([Errno 98] Address already in use; 568)
[2024-04-13T18:41:30.670+0000] {local_task_job_runner.py:234} INFO - Task exited with return code 1
[2024-04-13T18:41:30.695+0000] {taskinstance.py:3312} INFO - 0 downstream tasks scheduled from follow-on schedule check
[2024-04-14T02:34:45.757+0000] {taskinstance.py:1979} INFO - Dependencies all met for dep_context=non-requeueable deps ti=<TaskInstance: token_refresher_50mins.refresh_token scheduled__2024-04-13T05:00:00+00:00 [queued]>
[2024-04-14T02:34:45.763+0000] {taskinstance.py:1979} INFO - Dependencies all met for dep_context=requeueable deps ti=<TaskInstance: token_refresher_50mins.refresh_token scheduled__2024-04-13T05:00:00+00:00 [queued]>
[2024-04-14T02:34:45.763+0000] {taskinstance.py:2193} INFO - Starting attempt 1 of 2
[2024-04-14T02:34:45.768+0000] {taskinstance.py:2217} INFO - Executing <Task(PythonOperator): refresh_token> on 2024-04-13 05:00:00+00:00
[2024-04-14T02:34:45.770+0000] {standard_task_runner.py:60} INFO - Started process 896 to run task
[2024-04-14T02:34:45.772+0000] {standard_task_runner.py:87} INFO - Running: ['***', 'tasks', 'run', 'token_refresher_50mins', 'refresh_token', 'scheduled__2024-04-13T05:00:00+00:00', '--job-id', '126', '--raw', '--subdir', 'DAGS_FOLDER/refresh_token.py', '--cfg-path', '/tmp/tmpzjuog_zr']
[2024-04-14T02:34:45.772+0000] {standard_task_runner.py:88} INFO - Job 126: Subtask refresh_token
[2024-04-14T02:34:45.791+0000] {task_command.py:423} INFO - Running <TaskInstance: token_refresher_50mins.refresh_token scheduled__2024-04-13T05:00:00+00:00 [running]> on host 209a9ac884b0
[2024-04-14T02:34:45.818+0000] {taskinstance.py:2513} INFO - Exporting env vars: AIRFLOW_CTX_DAG_OWNER='***' AIRFLOW_CTX_DAG_ID='token_refresher_50mins' AIRFLOW_CTX_TASK_ID='refresh_token' AIRFLOW_CTX_EXECUTION_DATE='2024-04-13T05:00:00+00:00' AIRFLOW_CTX_TRY_NUMBER='1' AIRFLOW_CTX_DAG_RUN_ID='scheduled__2024-04-13T05:00:00+00:00'
[2024-04-14T02:34:45.875+0000] {logging_mixin.py:188} INFO - BQCd0chWkv-13Xa4JeL6Ak4uTlm0AROuQ_YDjjxnOPWf-la6rD4K7MHKRNC9mYeqandgcQMVOgCAFjjvLmep7A0gBlDGmqjryXva35IqEyFBBKF4VK8
[2024-04-14T02:34:45.875+0000] {python.py:202} INFO - Done. Returned value was: None
[2024-04-14T02:34:45.880+0000] {taskinstance.py:1149} INFO - Marking task as SUCCESS. dag_id=token_refresher_50mins, task_id=refresh_token, execution_date=20240413T050000, start_date=20240414T023445, end_date=20240414T023445
[2024-04-14T02:34:45.909+0000] {local_task_job_runner.py:234} INFO - Task exited with return code 0
[2024-04-14T02:34:45.916+0000] {taskinstance.py:3312} INFO - 0 downstream tasks scheduled from follow-on schedule check
[2024-04-14T02:37:50.542+0000] {taskinstance.py:1979} INFO - Dependencies all met for dep_context=non-requeueable deps ti=<TaskInstance: token_refresher_50mins.refresh_token scheduled__2024-04-13T05:00:00+00:00 [queued]>
[2024-04-14T02:37:50.550+0000] {taskinstance.py:1979} INFO - Dependencies all met for dep_context=requeueable deps ti=<TaskInstance: token_refresher_50mins.refresh_token scheduled__2024-04-13T05:00:00+00:00 [queued]>
[2024-04-14T02:37:50.553+0000] {taskinstance.py:2193} INFO - Starting attempt 1 of 2
[2024-04-14T02:37:50.560+0000] {taskinstance.py:2217} INFO - Executing <Task(PythonOperator): refresh_token> on 2024-04-13 05:00:00+00:00
[2024-04-14T02:37:50.562+0000] {standard_task_runner.py:60} INFO - Started process 1011 to run task
[2024-04-14T02:37:50.564+0000] {standard_task_runner.py:87} INFO - Running: ['***', 'tasks', 'run', 'token_refresher_50mins', 'refresh_token', 'scheduled__2024-04-13T05:00:00+00:00', '--job-id', '159', '--raw', '--subdir', 'DAGS_FOLDER/refresh_token.py', '--cfg-path', '/tmp/tmp7n_zs6p5']
[2024-04-14T02:37:50.565+0000] {standard_task_runner.py:88} INFO - Job 159: Subtask refresh_token
[2024-04-14T02:37:50.586+0000] {task_command.py:423} INFO - Running <TaskInstance: token_refresher_50mins.refresh_token scheduled__2024-04-13T05:00:00+00:00 [running]> on host 209a9ac884b0
[2024-04-14T02:37:50.619+0000] {taskinstance.py:2513} INFO - Exporting env vars: AIRFLOW_CTX_DAG_OWNER='***' AIRFLOW_CTX_DAG_ID='token_refresher_50mins' AIRFLOW_CTX_TASK_ID='refresh_token' AIRFLOW_CTX_EXECUTION_DATE='2024-04-13T05:00:00+00:00' AIRFLOW_CTX_TRY_NUMBER='1' AIRFLOW_CTX_DAG_RUN_ID='scheduled__2024-04-13T05:00:00+00:00'
[2024-04-14T02:37:50.699+0000] {logging_mixin.py:188} WARNING - --- Logging error ---
[2024-04-14T02:37:50.700+0000] {logging_mixin.py:188} WARNING - Traceback (most recent call last):
[2024-04-14T02:37:50.700+0000] {logging_mixin.py:188} WARNING -   File "/usr/local/lib/python3.8/logging/__init__.py", line 1085, in emit
    msg = self.format(record)
[2024-04-14T02:37:50.700+0000] {logging_mixin.py:188} WARNING -   File "/usr/local/lib/python3.8/logging/__init__.py", line 929, in format
    return fmt.format(record)
[2024-04-14T02:37:50.700+0000] {logging_mixin.py:188} WARNING -   File "/usr/local/lib/python3.8/logging/__init__.py", line 668, in format
    record.message = record.getMessage()
[2024-04-14T02:37:50.700+0000] {logging_mixin.py:188} WARNING -   File "/usr/local/lib/python3.8/logging/__init__.py", line 373, in getMessage
    msg = msg % self.args
[2024-04-14T02:37:50.701+0000] {logging_mixin.py:188} WARNING - TypeError: not all arguments converted during string formatting
[2024-04-14T02:37:50.701+0000] {logging_mixin.py:188} WARNING - Call stack:
[2024-04-14T02:37:50.703+0000] {logging_mixin.py:188} WARNING -   File "/home/***/.local/bin/***", line 8, in <module>
    sys.exit(main())
[2024-04-14T02:37:50.703+0000] {logging_mixin.py:188} WARNING -   File "/home/***/.local/lib/python3.8/site-packages/***/__main__.py", line 57, in main
    args.func(args)
[2024-04-14T02:37:50.703+0000] {logging_mixin.py:188} WARNING -   File "/home/***/.local/lib/python3.8/site-packages/***/cli/cli_config.py", line 49, in command
    return func(*args, **kwargs)
[2024-04-14T02:37:50.704+0000] {logging_mixin.py:188} WARNING -   File "/home/***/.local/lib/python3.8/site-packages/***/utils/cli.py", line 114, in wrapper
    return f(*args, **kwargs)
[2024-04-14T02:37:50.704+0000] {logging_mixin.py:188} WARNING -   File "/home/***/.local/lib/python3.8/site-packages/***/providers/celery/cli/celery_command.py", line 60, in wrapper
    providers_configuration_loaded(func)(*args, **kwargs)
[2024-04-14T02:37:50.704+0000] {logging_mixin.py:188} WARNING -   File "/home/***/.local/lib/python3.8/site-packages/***/utils/providers_configuration_loader.py", line 55, in wrapped_function
    return func(*args, **kwargs)
[2024-04-14T02:37:50.704+0000] {logging_mixin.py:188} WARNING -   File "/home/***/.local/lib/python3.8/site-packages/***/providers/celery/cli/celery_command.py", line 231, in worker
    _run_command_with_daemon_option(
[2024-04-14T02:37:50.704+0000] {logging_mixin.py:188} WARNING -   File "/home/***/.local/lib/python3.8/site-packages/***/providers/celery/cli/celery_command.py", line 46, in _run_command_with_daemon_option
    run_command_with_daemon_option(*args, **kwargs)
[2024-04-14T02:37:50.704+0000] {logging_mixin.py:188} WARNING -   File "/home/***/.local/lib/python3.8/site-packages/***/cli/commands/daemon_utils.py", line 86, in run_command_with_daemon_option
    callback()
[2024-04-14T02:37:50.704+0000] {logging_mixin.py:188} WARNING -   File "/home/***/.local/lib/python3.8/site-packages/***/providers/celery/cli/celery_command.py", line 224, in run_celery_worker
    celery_app.worker_main(options)
[2024-04-14T02:37:50.704+0000] {logging_mixin.py:188} WARNING -   File "/home/***/.local/lib/python3.8/site-packages/celery/app/base.py", line 389, in worker_main
    self.start(argv=argv)
[2024-04-14T02:37:50.705+0000] {logging_mixin.py:188} WARNING -   File "/home/***/.local/lib/python3.8/site-packages/celery/app/base.py", line 369, in start
    celery.main(args=argv, standalone_mode=False)
[2024-04-14T02:37:50.705+0000] {logging_mixin.py:188} WARNING -   File "/home/***/.local/lib/python3.8/site-packages/click/core.py", line 1078, in main
    rv = self.invoke(ctx)
[2024-04-14T02:37:50.705+0000] {logging_mixin.py:188} WARNING -   File "/home/***/.local/lib/python3.8/site-packages/click/core.py", line 1688, in invoke
    return _process_result(sub_ctx.command.invoke(sub_ctx))
[2024-04-14T02:37:50.705+0000] {logging_mixin.py:188} WARNING -   File "/home/***/.local/lib/python3.8/site-packages/click/core.py", line 1434, in invoke
    return ctx.invoke(self.callback, **ctx.params)
[2024-04-14T02:37:50.705+0000] {logging_mixin.py:188} WARNING -   File "/home/***/.local/lib/python3.8/site-packages/click/core.py", line 783, in invoke
    return __callback(*args, **kwargs)
[2024-04-14T02:37:50.705+0000] {logging_mixin.py:188} WARNING -   File "/home/***/.local/lib/python3.8/site-packages/click/decorators.py", line 33, in new_func
    return f(get_current_context(), *args, **kwargs)
[2024-04-14T02:37:50.705+0000] {logging_mixin.py:188} WARNING -   File "/home/***/.local/lib/python3.8/site-packages/celery/bin/base.py", line 134, in caller
    return f(ctx, *args, **kwargs)
[2024-04-14T02:37:50.705+0000] {logging_mixin.py:188} WARNING -   File "/home/***/.local/lib/python3.8/site-packages/celery/bin/worker.py", line 356, in worker
    worker.start()
[2024-04-14T02:37:50.706+0000] {logging_mixin.py:188} WARNING -   File "/home/***/.local/lib/python3.8/site-packages/celery/worker/worker.py", line 202, in start
    self.blueprint.start(self)
[2024-04-14T02:37:50.706+0000] {logging_mixin.py:188} WARNING -   File "/home/***/.local/lib/python3.8/site-packages/celery/bootsteps.py", line 116, in start
    step.start(parent)
[2024-04-14T02:37:50.706+0000] {logging_mixin.py:188} WARNING -   File "/home/***/.local/lib/python3.8/site-packages/celery/bootsteps.py", line 365, in start
    return self.obj.start()
[2024-04-14T02:37:50.706+0000] {logging_mixin.py:188} WARNING -   File "/home/***/.local/lib/python3.8/site-packages/celery/concurrency/base.py", line 130, in start
    self.on_start()
[2024-04-14T02:37:50.706+0000] {logging_mixin.py:188} WARNING -   File "/home/***/.local/lib/python3.8/site-packages/celery/concurrency/prefork.py", line 109, in on_start
    P = self._pool = Pool(processes=self.limit,
[2024-04-14T02:37:50.706+0000] {logging_mixin.py:188} WARNING -   File "/home/***/.local/lib/python3.8/site-packages/celery/concurrency/asynpool.py", line 464, in __init__
    super().__init__(processes, *args, **kwargs)
[2024-04-14T02:37:50.706+0000] {logging_mixin.py:188} WARNING -   File "/home/***/.local/lib/python3.8/site-packages/billiard/pool.py", line 1045, in __init__
    self._create_worker_process(i)
[2024-04-14T02:37:50.707+0000] {logging_mixin.py:188} WARNING -   File "/home/***/.local/lib/python3.8/site-packages/celery/concurrency/asynpool.py", line 482, in _create_worker_process
    return super()._create_worker_process(i)
[2024-04-14T02:37:50.707+0000] {logging_mixin.py:188} WARNING -   File "/home/***/.local/lib/python3.8/site-packages/billiard/pool.py", line 1157, in _create_worker_process
    w.start()
[2024-04-14T02:37:50.707+0000] {logging_mixin.py:188} WARNING -   File "/home/***/.local/lib/python3.8/site-packages/billiard/process.py", line 120, in start
    self._popen = self._Popen(self)
[2024-04-14T02:37:50.707+0000] {logging_mixin.py:188} WARNING -   File "/home/***/.local/lib/python3.8/site-packages/billiard/context.py", line 331, in _Popen
    return Popen(process_obj)
[2024-04-14T02:37:50.707+0000] {logging_mixin.py:188} WARNING -   File "/home/***/.local/lib/python3.8/site-packages/billiard/popen_fork.py", line 22, in __init__
    self._launch(process_obj)
[2024-04-14T02:37:50.707+0000] {logging_mixin.py:188} WARNING -   File "/home/***/.local/lib/python3.8/site-packages/billiard/popen_fork.py", line 77, in _launch
    code = process_obj._bootstrap()
[2024-04-14T02:37:50.707+0000] {logging_mixin.py:188} WARNING -   File "/home/***/.local/lib/python3.8/site-packages/billiard/process.py", line 323, in _bootstrap
    self.run()
[2024-04-14T02:37:50.707+0000] {logging_mixin.py:188} WARNING -   File "/home/***/.local/lib/python3.8/site-packages/billiard/process.py", line 110, in run
    self._target(*self._args, **self._kwargs)
[2024-04-14T02:37:50.708+0000] {logging_mixin.py:188} WARNING -   File "/home/***/.local/lib/python3.8/site-packages/billiard/pool.py", line 291, in __call__
    sys.exit(self.workloop(pid=pid))
[2024-04-14T02:37:50.708+0000] {logging_mixin.py:188} WARNING -   File "/home/***/.local/lib/python3.8/site-packages/billiard/pool.py", line 361, in workloop
    result = (True, prepare_result(fun(*args, **kwargs)))
[2024-04-14T02:37:50.708+0000] {logging_mixin.py:188} WARNING -   File "/home/***/.local/lib/python3.8/site-packages/celery/app/trace.py", line 675, in fast_trace_task
    R, I, T, Rstr = tasks[task].__trace__(
[2024-04-14T02:37:50.708+0000] {logging_mixin.py:188} WARNING -   File "/home/***/.local/lib/python3.8/site-packages/celery/app/trace.py", line 477, in trace_task
    R = retval = fun(*args, **kwargs)
[2024-04-14T02:37:50.708+0000] {logging_mixin.py:188} WARNING -   File "/home/***/.local/lib/python3.8/site-packages/celery/app/trace.py", line 760, in __protected_call__
    return self.run(*args, **kwargs)
[2024-04-14T02:37:50.708+0000] {logging_mixin.py:188} WARNING -   File "/home/***/.local/lib/python3.8/site-packages/***/providers/celery/executors/celery_executor_utils.py", line 135, in execute_command
    _execute_in_fork(command_to_exec, celery_task_id)
[2024-04-14T02:37:50.708+0000] {logging_mixin.py:188} WARNING -   File "/home/***/.local/lib/python3.8/site-packages/***/providers/celery/executors/celery_executor_utils.py", line 169, in _execute_in_fork
    args.func(args)
[2024-04-14T02:37:50.708+0000] {logging_mixin.py:188} WARNING -   File "/home/***/.local/lib/python3.8/site-packages/***/cli/cli_config.py", line 49, in command
    return func(*args, **kwargs)
[2024-04-14T02:37:50.709+0000] {logging_mixin.py:188} WARNING -   File "/home/***/.local/lib/python3.8/site-packages/***/utils/cli.py", line 114, in wrapper
    return f(*args, **kwargs)
[2024-04-14T02:37:50.709+0000] {logging_mixin.py:188} WARNING -   File "/home/***/.local/lib/python3.8/site-packages/***/cli/commands/task_command.py", line 438, in task_run
    task_return_code = _run_task_by_selected_method(args, _dag, ti)
[2024-04-14T02:37:50.709+0000] {logging_mixin.py:188} WARNING -   File "/home/***/.local/lib/python3.8/site-packages/***/cli/commands/task_command.py", line 216, in _run_task_by_selected_method
    return _run_task_by_local_task_job(args, ti)
[2024-04-14T02:37:50.709+0000] {logging_mixin.py:188} WARNING -   File "/home/***/.local/lib/python3.8/site-packages/***/cli/commands/task_command.py", line 278, in _run_task_by_local_task_job
    ret = run_job(job=job_runner.job, execute_callable=job_runner._execute)
[2024-04-14T02:37:50.709+0000] {logging_mixin.py:188} WARNING -   File "/home/***/.local/lib/python3.8/site-packages/***/utils/session.py", line 79, in wrapper
    return func(*args, session=session, **kwargs)
[2024-04-14T02:37:50.709+0000] {logging_mixin.py:188} WARNING -   File "/home/***/.local/lib/python3.8/site-packages/***/jobs/job.py", line 395, in run_job
    return execute_job(job, execute_callable=execute_callable)
[2024-04-14T02:37:50.709+0000] {logging_mixin.py:188} WARNING -   File "/home/***/.local/lib/python3.8/site-packages/***/jobs/job.py", line 424, in execute_job
    ret = execute_callable()
[2024-04-14T02:37:50.709+0000] {logging_mixin.py:188} WARNING -   File "/home/***/.local/lib/python3.8/site-packages/***/jobs/local_task_job_runner.py", line 165, in _execute
    self.task_runner.start()
[2024-04-14T02:37:50.710+0000] {logging_mixin.py:188} WARNING -   File "/home/***/.local/lib/python3.8/site-packages/***/task/task_runner/standard_task_runner.py", line 48, in start
    self.process = self._start_by_fork()
[2024-04-14T02:37:50.710+0000] {logging_mixin.py:188} WARNING -   File "/home/***/.local/lib/python3.8/site-packages/***/task/task_runner/standard_task_runner.py", line 100, in _start_by_fork
    ret = args.func(args, dag=self.dag)
[2024-04-14T02:37:50.710+0000] {logging_mixin.py:188} WARNING -   File "/home/***/.local/lib/python3.8/site-packages/***/cli/cli_config.py", line 49, in command
    return func(*args, **kwargs)
[2024-04-14T02:37:50.710+0000] {logging_mixin.py:188} WARNING -   File "/home/***/.local/lib/python3.8/site-packages/***/utils/cli.py", line 114, in wrapper
    return f(*args, **kwargs)
[2024-04-14T02:37:50.710+0000] {logging_mixin.py:188} WARNING -   File "/home/***/.local/lib/python3.8/site-packages/***/cli/commands/task_command.py", line 438, in task_run
    task_return_code = _run_task_by_selected_method(args, _dag, ti)
[2024-04-14T02:37:50.710+0000] {logging_mixin.py:188} WARNING -   File "/home/***/.local/lib/python3.8/site-packages/***/cli/commands/task_command.py", line 218, in _run_task_by_selected_method
    return _run_raw_task(args, ti)
[2024-04-14T02:37:50.710+0000] {logging_mixin.py:188} WARNING -   File "/home/***/.local/lib/python3.8/site-packages/***/cli/commands/task_command.py", line 297, in _run_raw_task
    return ti._run_raw_task(
[2024-04-14T02:37:50.710+0000] {logging_mixin.py:188} WARNING -   File "/home/***/.local/lib/python3.8/site-packages/***/utils/session.py", line 79, in wrapper
    return func(*args, session=session, **kwargs)
[2024-04-14T02:37:50.711+0000] {logging_mixin.py:188} WARNING -   File "/home/***/.local/lib/python3.8/site-packages/***/models/taskinstance.py", line 2360, in _run_raw_task
    self._execute_task_with_callbacks(context, test_mode, session=session)
[2024-04-14T02:37:50.711+0000] {logging_mixin.py:188} WARNING -   File "/home/***/.local/lib/python3.8/site-packages/***/models/taskinstance.py", line 2532, in _execute_task_with_callbacks
    result = self._execute_task(context, task_orig)
[2024-04-14T02:37:50.711+0000] {logging_mixin.py:188} WARNING -   File "/home/***/.local/lib/python3.8/site-packages/***/models/taskinstance.py", line 2549, in _execute_task
    return _execute_task(self, context, task_orig)
[2024-04-14T02:37:50.711+0000] {logging_mixin.py:188} WARNING -   File "/home/***/.local/lib/python3.8/site-packages/***/models/taskinstance.py", line 444, in _execute_task
    result = _execute_callable(context=context, **execute_callable_kwargs)
[2024-04-14T02:37:50.711+0000] {logging_mixin.py:188} WARNING -   File "/home/***/.local/lib/python3.8/site-packages/***/models/taskinstance.py", line 414, in _execute_callable
    return execute_callable(context=context, **execute_callable_kwargs)
[2024-04-14T02:37:50.711+0000] {logging_mixin.py:188} WARNING -   File "/home/***/.local/lib/python3.8/site-packages/***/operators/python.py", line 200, in execute
    return_value = self.execute_callable()
[2024-04-14T02:37:50.711+0000] {logging_mixin.py:188} WARNING -   File "/home/***/.local/lib/python3.8/site-packages/***/operators/python.py", line 217, in execute_callable
    return self.python_callable(*self.op_args, **self.op_kwargs)
[2024-04-14T02:37:50.712+0000] {logging_mixin.py:188} WARNING -   File "/opt/***/dags/refresh_token.py", line 46, in refresh_token
    logging.info("access_token:", access_token)
[2024-04-14T02:37:50.712+0000] {logging_mixin.py:188} WARNING -   File "/usr/local/lib/python3.8/logging/__init__.py", line 2082, in info
    root.info(msg, *args, **kwargs)
[2024-04-14T02:37:50.712+0000] {logging_mixin.py:188} WARNING -   File "/usr/local/lib/python3.8/logging/__init__.py", line 1446, in info
    self._log(INFO, msg, args, **kwargs)
[2024-04-14T02:37:50.712+0000] {logging_mixin.py:188} WARNING -   File "/usr/local/lib/python3.8/logging/__init__.py", line 1589, in _log
    self.handle(record)
[2024-04-14T02:37:50.712+0000] {logging_mixin.py:188} WARNING -   File "/usr/local/lib/python3.8/logging/__init__.py", line 1599, in handle
    self.callHandlers(record)
[2024-04-14T02:37:50.712+0000] {logging_mixin.py:188} WARNING -   File "/usr/local/lib/python3.8/logging/__init__.py", line 1661, in callHandlers
    hdlr.handle(record)
[2024-04-14T02:37:50.712+0000] {logging_mixin.py:188} WARNING -   File "/usr/local/lib/python3.8/logging/__init__.py", line 954, in handle
    self.emit(record)
[2024-04-14T02:37:50.712+0000] {logging_mixin.py:188} WARNING -   File "/home/***/.local/lib/python3.8/site-packages/***/utils/log/file_task_handler.py", line 247, in emit
    self.handler.emit(record)
[2024-04-14T02:37:50.713+0000] {logging_mixin.py:188} WARNING - Message: 'access_token:'
Arguments: ('BQDabnA7-cGsodpmE_1oioorVRx046xmT33lDyqwKsKAtQ_ncbt1-Re3KeHxEvKbWE-s1i4J5NfJcQnj_HVl4e8V5Zg5jbFJ4HgUXRP8WGNFVMrWXIM',)
[2024-04-14T02:37:50.713+0000] {python.py:202} INFO - Done. Returned value was: None
[2024-04-14T02:37:50.717+0000] {taskinstance.py:1149} INFO - Marking task as SUCCESS. dag_id=token_refresher_50mins, task_id=refresh_token, execution_date=20240413T050000, start_date=20240414T023750, end_date=20240414T023750
[2024-04-14T02:37:50.743+0000] {local_task_job_runner.py:234} INFO - Task exited with return code 0
[2024-04-14T02:37:50.750+0000] {taskinstance.py:3312} INFO - 0 downstream tasks scheduled from follow-on schedule check
[2024-04-14T02:45:05.975+0000] {taskinstance.py:1979} INFO - Dependencies all met for dep_context=non-requeueable deps ti=<TaskInstance: token_refresher_50mins.refresh_token scheduled__2024-04-13T05:00:00+00:00 [queued]>
[2024-04-14T02:45:05.986+0000] {taskinstance.py:1979} INFO - Dependencies all met for dep_context=requeueable deps ti=<TaskInstance: token_refresher_50mins.refresh_token scheduled__2024-04-13T05:00:00+00:00 [queued]>
[2024-04-14T02:45:05.987+0000] {taskinstance.py:2193} INFO - Starting attempt 1 of 2
[2024-04-14T02:45:05.998+0000] {taskinstance.py:2217} INFO - Executing <Task(PythonOperator): refresh_token> on 2024-04-13 05:00:00+00:00
[2024-04-14T02:45:06.003+0000] {standard_task_runner.py:60} INFO - Started process 1192 to run task
[2024-04-14T02:45:06.006+0000] {standard_task_runner.py:87} INFO - Running: ['***', 'tasks', 'run', 'token_refresher_50mins', 'refresh_token', 'scheduled__2024-04-13T05:00:00+00:00', '--job-id', '194', '--raw', '--subdir', 'DAGS_FOLDER/refresh_token.py', '--cfg-path', '/tmp/tmpg5lye5qp']
[2024-04-14T02:45:06.007+0000] {standard_task_runner.py:88} INFO - Job 194: Subtask refresh_token
[2024-04-14T02:45:06.058+0000] {task_command.py:423} INFO - Running <TaskInstance: token_refresher_50mins.refresh_token scheduled__2024-04-13T05:00:00+00:00 [running]> on host 209a9ac884b0
[2024-04-14T02:45:06.167+0000] {taskinstance.py:2513} INFO - Exporting env vars: AIRFLOW_CTX_DAG_OWNER='***' AIRFLOW_CTX_DAG_ID='token_refresher_50mins' AIRFLOW_CTX_TASK_ID='refresh_token' AIRFLOW_CTX_EXECUTION_DATE='2024-04-13T05:00:00+00:00' AIRFLOW_CTX_TRY_NUMBER='1' AIRFLOW_CTX_DAG_RUN_ID='scheduled__2024-04-13T05:00:00+00:00'
[2024-04-14T02:45:06.282+0000] {logging_mixin.py:188} WARNING - --- Logging error ---
[2024-04-14T02:45:06.283+0000] {logging_mixin.py:188} WARNING - Traceback (most recent call last):
[2024-04-14T02:45:06.286+0000] {logging_mixin.py:188} WARNING -   File "/usr/local/lib/python3.8/logging/__init__.py", line 1085, in emit
    msg = self.format(record)
[2024-04-14T02:45:06.289+0000] {logging_mixin.py:188} WARNING -   File "/usr/local/lib/python3.8/logging/__init__.py", line 929, in format
    return fmt.format(record)
[2024-04-14T02:45:06.290+0000] {logging_mixin.py:188} WARNING -   File "/usr/local/lib/python3.8/logging/__init__.py", line 668, in format
    record.message = record.getMessage()
[2024-04-14T02:45:06.290+0000] {logging_mixin.py:188} WARNING -   File "/usr/local/lib/python3.8/logging/__init__.py", line 373, in getMessage
    msg = msg % self.args
[2024-04-14T02:45:06.291+0000] {logging_mixin.py:188} WARNING - TypeError: not all arguments converted during string formatting
[2024-04-14T02:45:06.295+0000] {logging_mixin.py:188} WARNING - Call stack:
[2024-04-14T02:45:06.316+0000] {logging_mixin.py:188} WARNING -   File "/home/***/.local/bin/***", line 8, in <module>
    sys.exit(main())
[2024-04-14T02:45:06.321+0000] {logging_mixin.py:188} WARNING -   File "/home/***/.local/lib/python3.8/site-packages/***/__main__.py", line 57, in main
    args.func(args)
[2024-04-14T02:45:06.322+0000] {logging_mixin.py:188} WARNING -   File "/home/***/.local/lib/python3.8/site-packages/***/cli/cli_config.py", line 49, in command
    return func(*args, **kwargs)
[2024-04-14T02:45:06.322+0000] {logging_mixin.py:188} WARNING -   File "/home/***/.local/lib/python3.8/site-packages/***/utils/cli.py", line 114, in wrapper
    return f(*args, **kwargs)
[2024-04-14T02:45:06.323+0000] {logging_mixin.py:188} WARNING -   File "/home/***/.local/lib/python3.8/site-packages/***/providers/celery/cli/celery_command.py", line 60, in wrapper
    providers_configuration_loaded(func)(*args, **kwargs)
[2024-04-14T02:45:06.323+0000] {logging_mixin.py:188} WARNING -   File "/home/***/.local/lib/python3.8/site-packages/***/utils/providers_configuration_loader.py", line 55, in wrapped_function
    return func(*args, **kwargs)
[2024-04-14T02:45:06.324+0000] {logging_mixin.py:188} WARNING -   File "/home/***/.local/lib/python3.8/site-packages/***/providers/celery/cli/celery_command.py", line 231, in worker
    _run_command_with_daemon_option(
[2024-04-14T02:45:06.327+0000] {logging_mixin.py:188} WARNING -   File "/home/***/.local/lib/python3.8/site-packages/***/providers/celery/cli/celery_command.py", line 46, in _run_command_with_daemon_option
    run_command_with_daemon_option(*args, **kwargs)
[2024-04-14T02:45:06.331+0000] {logging_mixin.py:188} WARNING -   File "/home/***/.local/lib/python3.8/site-packages/***/cli/commands/daemon_utils.py", line 86, in run_command_with_daemon_option
    callback()
[2024-04-14T02:45:06.333+0000] {logging_mixin.py:188} WARNING -   File "/home/***/.local/lib/python3.8/site-packages/***/providers/celery/cli/celery_command.py", line 224, in run_celery_worker
    celery_app.worker_main(options)
[2024-04-14T02:45:06.335+0000] {logging_mixin.py:188} WARNING -   File "/home/***/.local/lib/python3.8/site-packages/celery/app/base.py", line 389, in worker_main
    self.start(argv=argv)
[2024-04-14T02:45:06.336+0000] {logging_mixin.py:188} WARNING -   File "/home/***/.local/lib/python3.8/site-packages/celery/app/base.py", line 369, in start
    celery.main(args=argv, standalone_mode=False)
[2024-04-14T02:45:06.337+0000] {logging_mixin.py:188} WARNING -   File "/home/***/.local/lib/python3.8/site-packages/click/core.py", line 1078, in main
    rv = self.invoke(ctx)
[2024-04-14T02:45:06.339+0000] {logging_mixin.py:188} WARNING -   File "/home/***/.local/lib/python3.8/site-packages/click/core.py", line 1688, in invoke
    return _process_result(sub_ctx.command.invoke(sub_ctx))
[2024-04-14T02:45:06.342+0000] {logging_mixin.py:188} WARNING -   File "/home/***/.local/lib/python3.8/site-packages/click/core.py", line 1434, in invoke
    return ctx.invoke(self.callback, **ctx.params)
[2024-04-14T02:45:06.343+0000] {logging_mixin.py:188} WARNING -   File "/home/***/.local/lib/python3.8/site-packages/click/core.py", line 783, in invoke
    return __callback(*args, **kwargs)
[2024-04-14T02:45:06.343+0000] {logging_mixin.py:188} WARNING -   File "/home/***/.local/lib/python3.8/site-packages/click/decorators.py", line 33, in new_func
    return f(get_current_context(), *args, **kwargs)
[2024-04-14T02:45:06.344+0000] {logging_mixin.py:188} WARNING -   File "/home/***/.local/lib/python3.8/site-packages/celery/bin/base.py", line 134, in caller
    return f(ctx, *args, **kwargs)
[2024-04-14T02:45:06.345+0000] {logging_mixin.py:188} WARNING -   File "/home/***/.local/lib/python3.8/site-packages/celery/bin/worker.py", line 356, in worker
    worker.start()
[2024-04-14T02:45:06.346+0000] {logging_mixin.py:188} WARNING -   File "/home/***/.local/lib/python3.8/site-packages/celery/worker/worker.py", line 202, in start
    self.blueprint.start(self)
[2024-04-14T02:45:06.347+0000] {logging_mixin.py:188} WARNING -   File "/home/***/.local/lib/python3.8/site-packages/celery/bootsteps.py", line 116, in start
    step.start(parent)
[2024-04-14T02:45:06.350+0000] {logging_mixin.py:188} WARNING -   File "/home/***/.local/lib/python3.8/site-packages/celery/bootsteps.py", line 365, in start
    return self.obj.start()
[2024-04-14T02:45:06.350+0000] {logging_mixin.py:188} WARNING -   File "/home/***/.local/lib/python3.8/site-packages/celery/concurrency/base.py", line 130, in start
    self.on_start()
[2024-04-14T02:45:06.354+0000] {logging_mixin.py:188} WARNING -   File "/home/***/.local/lib/python3.8/site-packages/celery/concurrency/prefork.py", line 109, in on_start
    P = self._pool = Pool(processes=self.limit,
[2024-04-14T02:45:06.355+0000] {logging_mixin.py:188} WARNING -   File "/home/***/.local/lib/python3.8/site-packages/celery/concurrency/asynpool.py", line 464, in __init__
    super().__init__(processes, *args, **kwargs)
[2024-04-14T02:45:06.356+0000] {logging_mixin.py:188} WARNING -   File "/home/***/.local/lib/python3.8/site-packages/billiard/pool.py", line 1045, in __init__
    self._create_worker_process(i)
[2024-04-14T02:45:06.358+0000] {logging_mixin.py:188} WARNING -   File "/home/***/.local/lib/python3.8/site-packages/celery/concurrency/asynpool.py", line 482, in _create_worker_process
    return super()._create_worker_process(i)
[2024-04-14T02:45:06.360+0000] {logging_mixin.py:188} WARNING -   File "/home/***/.local/lib/python3.8/site-packages/billiard/pool.py", line 1157, in _create_worker_process
    w.start()
[2024-04-14T02:45:06.361+0000] {logging_mixin.py:188} WARNING -   File "/home/***/.local/lib/python3.8/site-packages/billiard/process.py", line 120, in start
    self._popen = self._Popen(self)
[2024-04-14T02:45:06.362+0000] {logging_mixin.py:188} WARNING -   File "/home/***/.local/lib/python3.8/site-packages/billiard/context.py", line 331, in _Popen
    return Popen(process_obj)
[2024-04-14T02:45:06.365+0000] {logging_mixin.py:188} WARNING -   File "/home/***/.local/lib/python3.8/site-packages/billiard/popen_fork.py", line 22, in __init__
    self._launch(process_obj)
[2024-04-14T02:45:06.367+0000] {logging_mixin.py:188} WARNING -   File "/home/***/.local/lib/python3.8/site-packages/billiard/popen_fork.py", line 77, in _launch
    code = process_obj._bootstrap()
[2024-04-14T02:45:06.367+0000] {logging_mixin.py:188} WARNING -   File "/home/***/.local/lib/python3.8/site-packages/billiard/process.py", line 323, in _bootstrap
    self.run()
[2024-04-14T02:45:06.368+0000] {logging_mixin.py:188} WARNING -   File "/home/***/.local/lib/python3.8/site-packages/billiard/process.py", line 110, in run
    self._target(*self._args, **self._kwargs)
[2024-04-14T02:45:06.368+0000] {logging_mixin.py:188} WARNING -   File "/home/***/.local/lib/python3.8/site-packages/billiard/pool.py", line 291, in __call__
    sys.exit(self.workloop(pid=pid))
[2024-04-14T02:45:06.371+0000] {logging_mixin.py:188} WARNING -   File "/home/***/.local/lib/python3.8/site-packages/billiard/pool.py", line 361, in workloop
    result = (True, prepare_result(fun(*args, **kwargs)))
[2024-04-14T02:45:06.372+0000] {logging_mixin.py:188} WARNING -   File "/home/***/.local/lib/python3.8/site-packages/celery/app/trace.py", line 675, in fast_trace_task
    R, I, T, Rstr = tasks[task].__trace__(
[2024-04-14T02:45:06.374+0000] {logging_mixin.py:188} WARNING -   File "/home/***/.local/lib/python3.8/site-packages/celery/app/trace.py", line 477, in trace_task
    R = retval = fun(*args, **kwargs)
[2024-04-14T02:45:06.376+0000] {logging_mixin.py:188} WARNING -   File "/home/***/.local/lib/python3.8/site-packages/celery/app/trace.py", line 760, in __protected_call__
    return self.run(*args, **kwargs)
[2024-04-14T02:45:06.377+0000] {logging_mixin.py:188} WARNING -   File "/home/***/.local/lib/python3.8/site-packages/***/providers/celery/executors/celery_executor_utils.py", line 135, in execute_command
    _execute_in_fork(command_to_exec, celery_task_id)
[2024-04-14T02:45:06.378+0000] {logging_mixin.py:188} WARNING -   File "/home/***/.local/lib/python3.8/site-packages/***/providers/celery/executors/celery_executor_utils.py", line 169, in _execute_in_fork
    args.func(args)
[2024-04-14T02:45:06.378+0000] {logging_mixin.py:188} WARNING -   File "/home/***/.local/lib/python3.8/site-packages/***/cli/cli_config.py", line 49, in command
    return func(*args, **kwargs)
[2024-04-14T02:45:06.379+0000] {logging_mixin.py:188} WARNING -   File "/home/***/.local/lib/python3.8/site-packages/***/utils/cli.py", line 114, in wrapper
    return f(*args, **kwargs)
[2024-04-14T02:45:06.380+0000] {logging_mixin.py:188} WARNING -   File "/home/***/.local/lib/python3.8/site-packages/***/cli/commands/task_command.py", line 438, in task_run
    task_return_code = _run_task_by_selected_method(args, _dag, ti)
[2024-04-14T02:45:06.381+0000] {logging_mixin.py:188} WARNING -   File "/home/***/.local/lib/python3.8/site-packages/***/cli/commands/task_command.py", line 216, in _run_task_by_selected_method
    return _run_task_by_local_task_job(args, ti)
[2024-04-14T02:45:06.382+0000] {logging_mixin.py:188} WARNING -   File "/home/***/.local/lib/python3.8/site-packages/***/cli/commands/task_command.py", line 278, in _run_task_by_local_task_job
    ret = run_job(job=job_runner.job, execute_callable=job_runner._execute)
[2024-04-14T02:45:06.386+0000] {logging_mixin.py:188} WARNING -   File "/home/***/.local/lib/python3.8/site-packages/***/utils/session.py", line 79, in wrapper
    return func(*args, session=session, **kwargs)
[2024-04-14T02:45:06.388+0000] {logging_mixin.py:188} WARNING -   File "/home/***/.local/lib/python3.8/site-packages/***/jobs/job.py", line 395, in run_job
    return execute_job(job, execute_callable=execute_callable)
[2024-04-14T02:45:06.389+0000] {logging_mixin.py:188} WARNING -   File "/home/***/.local/lib/python3.8/site-packages/***/jobs/job.py", line 424, in execute_job
    ret = execute_callable()
[2024-04-14T02:45:06.390+0000] {logging_mixin.py:188} WARNING -   File "/home/***/.local/lib/python3.8/site-packages/***/jobs/local_task_job_runner.py", line 165, in _execute
    self.task_runner.start()
[2024-04-14T02:45:06.391+0000] {logging_mixin.py:188} WARNING -   File "/home/***/.local/lib/python3.8/site-packages/***/task/task_runner/standard_task_runner.py", line 48, in start
    self.process = self._start_by_fork()
[2024-04-14T02:45:06.393+0000] {logging_mixin.py:188} WARNING -   File "/home/***/.local/lib/python3.8/site-packages/***/task/task_runner/standard_task_runner.py", line 100, in _start_by_fork
    ret = args.func(args, dag=self.dag)
[2024-04-14T02:45:06.395+0000] {logging_mixin.py:188} WARNING -   File "/home/***/.local/lib/python3.8/site-packages/***/cli/cli_config.py", line 49, in command
    return func(*args, **kwargs)
[2024-04-14T02:45:06.395+0000] {logging_mixin.py:188} WARNING -   File "/home/***/.local/lib/python3.8/site-packages/***/utils/cli.py", line 114, in wrapper
    return f(*args, **kwargs)
[2024-04-14T02:45:06.395+0000] {logging_mixin.py:188} WARNING -   File "/home/***/.local/lib/python3.8/site-packages/***/cli/commands/task_command.py", line 438, in task_run
    task_return_code = _run_task_by_selected_method(args, _dag, ti)
[2024-04-14T02:45:06.396+0000] {logging_mixin.py:188} WARNING -   File "/home/***/.local/lib/python3.8/site-packages/***/cli/commands/task_command.py", line 218, in _run_task_by_selected_method
    return _run_raw_task(args, ti)
[2024-04-14T02:45:06.396+0000] {logging_mixin.py:188} WARNING -   File "/home/***/.local/lib/python3.8/site-packages/***/cli/commands/task_command.py", line 297, in _run_raw_task
    return ti._run_raw_task(
[2024-04-14T02:45:06.396+0000] {logging_mixin.py:188} WARNING -   File "/home/***/.local/lib/python3.8/site-packages/***/utils/session.py", line 79, in wrapper
    return func(*args, session=session, **kwargs)
[2024-04-14T02:45:06.396+0000] {logging_mixin.py:188} WARNING -   File "/home/***/.local/lib/python3.8/site-packages/***/models/taskinstance.py", line 2360, in _run_raw_task
    self._execute_task_with_callbacks(context, test_mode, session=session)
[2024-04-14T02:45:06.396+0000] {logging_mixin.py:188} WARNING -   File "/home/***/.local/lib/python3.8/site-packages/***/models/taskinstance.py", line 2532, in _execute_task_with_callbacks
    result = self._execute_task(context, task_orig)
[2024-04-14T02:45:06.397+0000] {logging_mixin.py:188} WARNING -   File "/home/***/.local/lib/python3.8/site-packages/***/models/taskinstance.py", line 2549, in _execute_task
    return _execute_task(self, context, task_orig)
[2024-04-14T02:45:06.397+0000] {logging_mixin.py:188} WARNING -   File "/home/***/.local/lib/python3.8/site-packages/***/models/taskinstance.py", line 444, in _execute_task
    result = _execute_callable(context=context, **execute_callable_kwargs)
[2024-04-14T02:45:06.397+0000] {logging_mixin.py:188} WARNING -   File "/home/***/.local/lib/python3.8/site-packages/***/models/taskinstance.py", line 414, in _execute_callable
    return execute_callable(context=context, **execute_callable_kwargs)
[2024-04-14T02:45:06.397+0000] {logging_mixin.py:188} WARNING -   File "/home/***/.local/lib/python3.8/site-packages/***/operators/python.py", line 200, in execute
    return_value = self.execute_callable()
[2024-04-14T02:45:06.398+0000] {logging_mixin.py:188} WARNING -   File "/home/***/.local/lib/python3.8/site-packages/***/operators/python.py", line 217, in execute_callable
    return self.python_callable(*self.op_args, **self.op_kwargs)
[2024-04-14T02:45:06.399+0000] {logging_mixin.py:188} WARNING -   File "/opt/***/dags/refresh_token.py", line 42, in refresh_token
    logging.info("access_token:", access_token)
[2024-04-14T02:45:06.400+0000] {logging_mixin.py:188} WARNING -   File "/usr/local/lib/python3.8/logging/__init__.py", line 2082, in info
    root.info(msg, *args, **kwargs)
[2024-04-14T02:45:06.402+0000] {logging_mixin.py:188} WARNING -   File "/usr/local/lib/python3.8/logging/__init__.py", line 1446, in info
    self._log(INFO, msg, args, **kwargs)
[2024-04-14T02:45:06.402+0000] {logging_mixin.py:188} WARNING -   File "/usr/local/lib/python3.8/logging/__init__.py", line 1589, in _log
    self.handle(record)
[2024-04-14T02:45:06.403+0000] {logging_mixin.py:188} WARNING -   File "/usr/local/lib/python3.8/logging/__init__.py", line 1599, in handle
    self.callHandlers(record)
[2024-04-14T02:45:06.403+0000] {logging_mixin.py:188} WARNING -   File "/usr/local/lib/python3.8/logging/__init__.py", line 1661, in callHandlers
    hdlr.handle(record)
[2024-04-14T02:45:06.404+0000] {logging_mixin.py:188} WARNING -   File "/usr/local/lib/python3.8/logging/__init__.py", line 954, in handle
    self.emit(record)
[2024-04-14T02:45:06.405+0000] {logging_mixin.py:188} WARNING -   File "/home/***/.local/lib/python3.8/site-packages/***/utils/log/file_task_handler.py", line 247, in emit
    self.handler.emit(record)
[2024-04-14T02:45:06.406+0000] {logging_mixin.py:188} WARNING - Message: 'access_token:'
Arguments: ('BQBDdNwN5UjhHzk_9jF0mRa-FEWso4TbenXYbSuMBHp7jZKrtCU-qVzuzvdmsFRV5S7Uu-V77Z1cq9YHQymdA2Bvp10nSZiQjKVkTSZzPUhhYtVTv4Y',)
[2024-04-14T02:45:06.407+0000] {python.py:202} INFO - Done. Returned value was: None
[2024-04-14T02:45:06.421+0000] {taskinstance.py:1149} INFO - Marking task as SUCCESS. dag_id=token_refresher_50mins, task_id=refresh_token, execution_date=20240413T050000, start_date=20240414T024505, end_date=20240414T024506
[2024-04-14T02:45:06.732+0000] {local_task_job_runner.py:234} INFO - Task exited with return code 0
[2024-04-14T02:45:06.759+0000] {taskinstance.py:3312} INFO - 1 downstream tasks scheduled from follow-on schedule check
[2024-04-14T02:46:20.971+0000] {taskinstance.py:1979} INFO - Dependencies all met for dep_context=non-requeueable deps ti=<TaskInstance: token_refresher_50mins.refresh_token scheduled__2024-04-13T05:00:00+00:00 [queued]>
[2024-04-14T02:46:20.978+0000] {taskinstance.py:1979} INFO - Dependencies all met for dep_context=requeueable deps ti=<TaskInstance: token_refresher_50mins.refresh_token scheduled__2024-04-13T05:00:00+00:00 [queued]>
[2024-04-14T02:46:20.979+0000] {taskinstance.py:2193} INFO - Starting attempt 1 of 2
[2024-04-14T02:46:20.993+0000] {taskinstance.py:2217} INFO - Executing <Task(PythonOperator): refresh_token> on 2024-04-13 05:00:00+00:00
[2024-04-14T02:46:20.996+0000] {standard_task_runner.py:60} INFO - Started process 1282 to run task
[2024-04-14T02:46:21.001+0000] {standard_task_runner.py:87} INFO - Running: ['***', 'tasks', 'run', 'token_refresher_50mins', 'refresh_token', 'scheduled__2024-04-13T05:00:00+00:00', '--job-id', '228', '--raw', '--subdir', 'DAGS_FOLDER/refresh_token.py', '--cfg-path', '/tmp/tmp67a1upin']
[2024-04-14T02:46:21.007+0000] {standard_task_runner.py:88} INFO - Job 228: Subtask refresh_token
[2024-04-14T02:46:21.131+0000] {task_command.py:423} INFO - Running <TaskInstance: token_refresher_50mins.refresh_token scheduled__2024-04-13T05:00:00+00:00 [running]> on host 209a9ac884b0
[2024-04-14T02:46:21.277+0000] {taskinstance.py:2513} INFO - Exporting env vars: AIRFLOW_CTX_DAG_OWNER='***' AIRFLOW_CTX_DAG_ID='token_refresher_50mins' AIRFLOW_CTX_TASK_ID='refresh_token' AIRFLOW_CTX_EXECUTION_DATE='2024-04-13T05:00:00+00:00' AIRFLOW_CTX_TRY_NUMBER='1' AIRFLOW_CTX_DAG_RUN_ID='scheduled__2024-04-13T05:00:00+00:00'
[2024-04-14T02:46:21.416+0000] {logging_mixin.py:188} WARNING - --- Logging error ---
[2024-04-14T02:46:21.418+0000] {logging_mixin.py:188} WARNING - Traceback (most recent call last):
[2024-04-14T02:46:21.419+0000] {logging_mixin.py:188} WARNING -   File "/usr/local/lib/python3.8/logging/__init__.py", line 1085, in emit
    msg = self.format(record)
[2024-04-14T02:46:21.422+0000] {logging_mixin.py:188} WARNING -   File "/usr/local/lib/python3.8/logging/__init__.py", line 929, in format
    return fmt.format(record)
[2024-04-14T02:46:21.423+0000] {logging_mixin.py:188} WARNING -   File "/usr/local/lib/python3.8/logging/__init__.py", line 668, in format
    record.message = record.getMessage()
[2024-04-14T02:46:21.424+0000] {logging_mixin.py:188} WARNING -   File "/usr/local/lib/python3.8/logging/__init__.py", line 373, in getMessage
    msg = msg % self.args
[2024-04-14T02:46:21.425+0000] {logging_mixin.py:188} WARNING - TypeError: not all arguments converted during string formatting
[2024-04-14T02:46:21.426+0000] {logging_mixin.py:188} WARNING - Call stack:
[2024-04-14T02:46:21.432+0000] {logging_mixin.py:188} WARNING -   File "/home/***/.local/bin/***", line 8, in <module>
    sys.exit(main())
[2024-04-14T02:46:21.434+0000] {logging_mixin.py:188} WARNING -   File "/home/***/.local/lib/python3.8/site-packages/***/__main__.py", line 57, in main
    args.func(args)
[2024-04-14T02:46:21.435+0000] {logging_mixin.py:188} WARNING -   File "/home/***/.local/lib/python3.8/site-packages/***/cli/cli_config.py", line 49, in command
    return func(*args, **kwargs)
[2024-04-14T02:46:21.439+0000] {logging_mixin.py:188} WARNING -   File "/home/***/.local/lib/python3.8/site-packages/***/utils/cli.py", line 114, in wrapper
    return f(*args, **kwargs)
[2024-04-14T02:46:21.440+0000] {logging_mixin.py:188} WARNING -   File "/home/***/.local/lib/python3.8/site-packages/***/providers/celery/cli/celery_command.py", line 60, in wrapper
    providers_configuration_loaded(func)(*args, **kwargs)
[2024-04-14T02:46:21.440+0000] {logging_mixin.py:188} WARNING -   File "/home/***/.local/lib/python3.8/site-packages/***/utils/providers_configuration_loader.py", line 55, in wrapped_function
    return func(*args, **kwargs)
[2024-04-14T02:46:21.441+0000] {logging_mixin.py:188} WARNING -   File "/home/***/.local/lib/python3.8/site-packages/***/providers/celery/cli/celery_command.py", line 231, in worker
    _run_command_with_daemon_option(
[2024-04-14T02:46:21.441+0000] {logging_mixin.py:188} WARNING -   File "/home/***/.local/lib/python3.8/site-packages/***/providers/celery/cli/celery_command.py", line 46, in _run_command_with_daemon_option
    run_command_with_daemon_option(*args, **kwargs)
[2024-04-14T02:46:21.441+0000] {logging_mixin.py:188} WARNING -   File "/home/***/.local/lib/python3.8/site-packages/***/cli/commands/daemon_utils.py", line 86, in run_command_with_daemon_option
    callback()
[2024-04-14T02:46:21.442+0000] {logging_mixin.py:188} WARNING -   File "/home/***/.local/lib/python3.8/site-packages/***/providers/celery/cli/celery_command.py", line 224, in run_celery_worker
    celery_app.worker_main(options)
[2024-04-14T02:46:21.442+0000] {logging_mixin.py:188} WARNING -   File "/home/***/.local/lib/python3.8/site-packages/celery/app/base.py", line 389, in worker_main
    self.start(argv=argv)
[2024-04-14T02:46:21.445+0000] {logging_mixin.py:188} WARNING -   File "/home/***/.local/lib/python3.8/site-packages/celery/app/base.py", line 369, in start
    celery.main(args=argv, standalone_mode=False)
[2024-04-14T02:46:21.445+0000] {logging_mixin.py:188} WARNING -   File "/home/***/.local/lib/python3.8/site-packages/click/core.py", line 1078, in main
    rv = self.invoke(ctx)
[2024-04-14T02:46:21.447+0000] {logging_mixin.py:188} WARNING -   File "/home/***/.local/lib/python3.8/site-packages/click/core.py", line 1688, in invoke
    return _process_result(sub_ctx.command.invoke(sub_ctx))
[2024-04-14T02:46:21.447+0000] {logging_mixin.py:188} WARNING -   File "/home/***/.local/lib/python3.8/site-packages/click/core.py", line 1434, in invoke
    return ctx.invoke(self.callback, **ctx.params)
[2024-04-14T02:46:21.447+0000] {logging_mixin.py:188} WARNING -   File "/home/***/.local/lib/python3.8/site-packages/click/core.py", line 783, in invoke
    return __callback(*args, **kwargs)
[2024-04-14T02:46:21.447+0000] {logging_mixin.py:188} WARNING -   File "/home/***/.local/lib/python3.8/site-packages/click/decorators.py", line 33, in new_func
    return f(get_current_context(), *args, **kwargs)
[2024-04-14T02:46:21.449+0000] {logging_mixin.py:188} WARNING -   File "/home/***/.local/lib/python3.8/site-packages/celery/bin/base.py", line 134, in caller
    return f(ctx, *args, **kwargs)
[2024-04-14T02:46:21.452+0000] {logging_mixin.py:188} WARNING -   File "/home/***/.local/lib/python3.8/site-packages/celery/bin/worker.py", line 356, in worker
    worker.start()
[2024-04-14T02:46:21.454+0000] {logging_mixin.py:188} WARNING -   File "/home/***/.local/lib/python3.8/site-packages/celery/worker/worker.py", line 202, in start
    self.blueprint.start(self)
[2024-04-14T02:46:21.458+0000] {logging_mixin.py:188} WARNING -   File "/home/***/.local/lib/python3.8/site-packages/celery/bootsteps.py", line 116, in start
    step.start(parent)
[2024-04-14T02:46:21.459+0000] {logging_mixin.py:188} WARNING -   File "/home/***/.local/lib/python3.8/site-packages/celery/bootsteps.py", line 365, in start
    return self.obj.start()
[2024-04-14T02:46:21.460+0000] {logging_mixin.py:188} WARNING -   File "/home/***/.local/lib/python3.8/site-packages/celery/concurrency/base.py", line 130, in start
    self.on_start()
[2024-04-14T02:46:21.460+0000] {logging_mixin.py:188} WARNING -   File "/home/***/.local/lib/python3.8/site-packages/celery/concurrency/prefork.py", line 109, in on_start
    P = self._pool = Pool(processes=self.limit,
[2024-04-14T02:46:21.460+0000] {logging_mixin.py:188} WARNING -   File "/home/***/.local/lib/python3.8/site-packages/celery/concurrency/asynpool.py", line 464, in __init__
    super().__init__(processes, *args, **kwargs)
[2024-04-14T02:46:21.461+0000] {logging_mixin.py:188} WARNING -   File "/home/***/.local/lib/python3.8/site-packages/billiard/pool.py", line 1045, in __init__
    self._create_worker_process(i)
[2024-04-14T02:46:21.462+0000] {logging_mixin.py:188} WARNING -   File "/home/***/.local/lib/python3.8/site-packages/celery/concurrency/asynpool.py", line 482, in _create_worker_process
    return super()._create_worker_process(i)
[2024-04-14T02:46:21.466+0000] {logging_mixin.py:188} WARNING -   File "/home/***/.local/lib/python3.8/site-packages/billiard/pool.py", line 1157, in _create_worker_process
    w.start()
[2024-04-14T02:46:21.467+0000] {logging_mixin.py:188} WARNING -   File "/home/***/.local/lib/python3.8/site-packages/billiard/process.py", line 120, in start
    self._popen = self._Popen(self)
[2024-04-14T02:46:21.467+0000] {logging_mixin.py:188} WARNING -   File "/home/***/.local/lib/python3.8/site-packages/billiard/context.py", line 331, in _Popen
    return Popen(process_obj)
[2024-04-14T02:46:21.467+0000] {logging_mixin.py:188} WARNING -   File "/home/***/.local/lib/python3.8/site-packages/billiard/popen_fork.py", line 22, in __init__
    self._launch(process_obj)
[2024-04-14T02:46:21.467+0000] {logging_mixin.py:188} WARNING -   File "/home/***/.local/lib/python3.8/site-packages/billiard/popen_fork.py", line 77, in _launch
    code = process_obj._bootstrap()
[2024-04-14T02:46:21.468+0000] {logging_mixin.py:188} WARNING -   File "/home/***/.local/lib/python3.8/site-packages/billiard/process.py", line 323, in _bootstrap
    self.run()
[2024-04-14T02:46:21.468+0000] {logging_mixin.py:188} WARNING -   File "/home/***/.local/lib/python3.8/site-packages/billiard/process.py", line 110, in run
    self._target(*self._args, **self._kwargs)
[2024-04-14T02:46:21.468+0000] {logging_mixin.py:188} WARNING -   File "/home/***/.local/lib/python3.8/site-packages/billiard/pool.py", line 291, in __call__
    sys.exit(self.workloop(pid=pid))
[2024-04-14T02:46:21.468+0000] {logging_mixin.py:188} WARNING -   File "/home/***/.local/lib/python3.8/site-packages/billiard/pool.py", line 361, in workloop
    result = (True, prepare_result(fun(*args, **kwargs)))
[2024-04-14T02:46:21.469+0000] {logging_mixin.py:188} WARNING -   File "/home/***/.local/lib/python3.8/site-packages/celery/app/trace.py", line 675, in fast_trace_task
    R, I, T, Rstr = tasks[task].__trace__(
[2024-04-14T02:46:21.470+0000] {logging_mixin.py:188} WARNING -   File "/home/***/.local/lib/python3.8/site-packages/celery/app/trace.py", line 477, in trace_task
    R = retval = fun(*args, **kwargs)
[2024-04-14T02:46:21.472+0000] {logging_mixin.py:188} WARNING -   File "/home/***/.local/lib/python3.8/site-packages/celery/app/trace.py", line 760, in __protected_call__
    return self.run(*args, **kwargs)
[2024-04-14T02:46:21.474+0000] {logging_mixin.py:188} WARNING -   File "/home/***/.local/lib/python3.8/site-packages/***/providers/celery/executors/celery_executor_utils.py", line 135, in execute_command
    _execute_in_fork(command_to_exec, celery_task_id)
[2024-04-14T02:46:21.477+0000] {logging_mixin.py:188} WARNING -   File "/home/***/.local/lib/python3.8/site-packages/***/providers/celery/executors/celery_executor_utils.py", line 169, in _execute_in_fork
    args.func(args)
[2024-04-14T02:46:21.479+0000] {logging_mixin.py:188} WARNING -   File "/home/***/.local/lib/python3.8/site-packages/***/cli/cli_config.py", line 49, in command
    return func(*args, **kwargs)
[2024-04-14T02:46:21.480+0000] {logging_mixin.py:188} WARNING -   File "/home/***/.local/lib/python3.8/site-packages/***/utils/cli.py", line 114, in wrapper
    return f(*args, **kwargs)
[2024-04-14T02:46:21.482+0000] {logging_mixin.py:188} WARNING -   File "/home/***/.local/lib/python3.8/site-packages/***/cli/commands/task_command.py", line 438, in task_run
    task_return_code = _run_task_by_selected_method(args, _dag, ti)
[2024-04-14T02:46:21.483+0000] {logging_mixin.py:188} WARNING -   File "/home/***/.local/lib/python3.8/site-packages/***/cli/commands/task_command.py", line 216, in _run_task_by_selected_method
    return _run_task_by_local_task_job(args, ti)
[2024-04-14T02:46:21.483+0000] {logging_mixin.py:188} WARNING -   File "/home/***/.local/lib/python3.8/site-packages/***/cli/commands/task_command.py", line 278, in _run_task_by_local_task_job
    ret = run_job(job=job_runner.job, execute_callable=job_runner._execute)
[2024-04-14T02:46:21.484+0000] {logging_mixin.py:188} WARNING -   File "/home/***/.local/lib/python3.8/site-packages/***/utils/session.py", line 79, in wrapper
    return func(*args, session=session, **kwargs)
[2024-04-14T02:46:21.485+0000] {logging_mixin.py:188} WARNING -   File "/home/***/.local/lib/python3.8/site-packages/***/jobs/job.py", line 395, in run_job
    return execute_job(job, execute_callable=execute_callable)
[2024-04-14T02:46:21.485+0000] {logging_mixin.py:188} WARNING -   File "/home/***/.local/lib/python3.8/site-packages/***/jobs/job.py", line 424, in execute_job
    ret = execute_callable()
[2024-04-14T02:46:21.487+0000] {logging_mixin.py:188} WARNING -   File "/home/***/.local/lib/python3.8/site-packages/***/jobs/local_task_job_runner.py", line 165, in _execute
    self.task_runner.start()
[2024-04-14T02:46:21.491+0000] {logging_mixin.py:188} WARNING -   File "/home/***/.local/lib/python3.8/site-packages/***/task/task_runner/standard_task_runner.py", line 48, in start
    self.process = self._start_by_fork()
[2024-04-14T02:46:21.491+0000] {logging_mixin.py:188} WARNING -   File "/home/***/.local/lib/python3.8/site-packages/***/task/task_runner/standard_task_runner.py", line 100, in _start_by_fork
    ret = args.func(args, dag=self.dag)
[2024-04-14T02:46:21.492+0000] {logging_mixin.py:188} WARNING -   File "/home/***/.local/lib/python3.8/site-packages/***/cli/cli_config.py", line 49, in command
    return func(*args, **kwargs)
[2024-04-14T02:46:21.492+0000] {logging_mixin.py:188} WARNING -   File "/home/***/.local/lib/python3.8/site-packages/***/utils/cli.py", line 114, in wrapper
    return f(*args, **kwargs)
[2024-04-14T02:46:21.493+0000] {logging_mixin.py:188} WARNING -   File "/home/***/.local/lib/python3.8/site-packages/***/cli/commands/task_command.py", line 438, in task_run
    task_return_code = _run_task_by_selected_method(args, _dag, ti)
[2024-04-14T02:46:21.493+0000] {logging_mixin.py:188} WARNING -   File "/home/***/.local/lib/python3.8/site-packages/***/cli/commands/task_command.py", line 218, in _run_task_by_selected_method
    return _run_raw_task(args, ti)
[2024-04-14T02:46:21.493+0000] {logging_mixin.py:188} WARNING -   File "/home/***/.local/lib/python3.8/site-packages/***/cli/commands/task_command.py", line 297, in _run_raw_task
    return ti._run_raw_task(
[2024-04-14T02:46:21.494+0000] {logging_mixin.py:188} WARNING -   File "/home/***/.local/lib/python3.8/site-packages/***/utils/session.py", line 79, in wrapper
    return func(*args, session=session, **kwargs)
[2024-04-14T02:46:21.495+0000] {logging_mixin.py:188} WARNING -   File "/home/***/.local/lib/python3.8/site-packages/***/models/taskinstance.py", line 2360, in _run_raw_task
    self._execute_task_with_callbacks(context, test_mode, session=session)
[2024-04-14T02:46:21.496+0000] {logging_mixin.py:188} WARNING -   File "/home/***/.local/lib/python3.8/site-packages/***/models/taskinstance.py", line 2532, in _execute_task_with_callbacks
    result = self._execute_task(context, task_orig)
[2024-04-14T02:46:21.497+0000] {logging_mixin.py:188} WARNING -   File "/home/***/.local/lib/python3.8/site-packages/***/models/taskinstance.py", line 2549, in _execute_task
    return _execute_task(self, context, task_orig)
[2024-04-14T02:46:21.498+0000] {logging_mixin.py:188} WARNING -   File "/home/***/.local/lib/python3.8/site-packages/***/models/taskinstance.py", line 444, in _execute_task
    result = _execute_callable(context=context, **execute_callable_kwargs)
[2024-04-14T02:46:21.499+0000] {logging_mixin.py:188} WARNING -   File "/home/***/.local/lib/python3.8/site-packages/***/models/taskinstance.py", line 414, in _execute_callable
    return execute_callable(context=context, **execute_callable_kwargs)
[2024-04-14T02:46:21.502+0000] {logging_mixin.py:188} WARNING -   File "/home/***/.local/lib/python3.8/site-packages/***/operators/python.py", line 200, in execute
    return_value = self.execute_callable()
[2024-04-14T02:46:21.503+0000] {logging_mixin.py:188} WARNING -   File "/home/***/.local/lib/python3.8/site-packages/***/operators/python.py", line 217, in execute_callable
    return self.python_callable(*self.op_args, **self.op_kwargs)
[2024-04-14T02:46:21.503+0000] {logging_mixin.py:188} WARNING -   File "/opt/***/dags/refresh_token.py", line 42, in refresh_token
    logging.info("access_token:", access_token)
[2024-04-14T02:46:21.504+0000] {logging_mixin.py:188} WARNING -   File "/usr/local/lib/python3.8/logging/__init__.py", line 2082, in info
    root.info(msg, *args, **kwargs)
[2024-04-14T02:46:21.505+0000] {logging_mixin.py:188} WARNING -   File "/usr/local/lib/python3.8/logging/__init__.py", line 1446, in info
    self._log(INFO, msg, args, **kwargs)
[2024-04-14T02:46:21.505+0000] {logging_mixin.py:188} WARNING -   File "/usr/local/lib/python3.8/logging/__init__.py", line 1589, in _log
    self.handle(record)
[2024-04-14T02:46:21.506+0000] {logging_mixin.py:188} WARNING -   File "/usr/local/lib/python3.8/logging/__init__.py", line 1599, in handle
    self.callHandlers(record)
[2024-04-14T02:46:21.506+0000] {logging_mixin.py:188} WARNING -   File "/usr/local/lib/python3.8/logging/__init__.py", line 1661, in callHandlers
    hdlr.handle(record)
[2024-04-14T02:46:21.506+0000] {logging_mixin.py:188} WARNING -   File "/usr/local/lib/python3.8/logging/__init__.py", line 954, in handle
    self.emit(record)
[2024-04-14T02:46:21.511+0000] {logging_mixin.py:188} WARNING -   File "/home/***/.local/lib/python3.8/site-packages/***/utils/log/file_task_handler.py", line 247, in emit
    self.handler.emit(record)
[2024-04-14T02:46:21.518+0000] {logging_mixin.py:188} WARNING - Message: 'access_token:'
Arguments: ('BQA-wmYzr7HOnJndEo6yfh_hF4C-UiBdS4GwkZZueGphEGxGO1ifzJz-4ub7a9nk5uwFNO8zjG2sJxyuiBQgVHwqfRaB-VQls2LteIPLABs2X3yC7CY',)
[2024-04-14T02:46:21.523+0000] {python.py:202} INFO - Done. Returned value was: None
[2024-04-14T02:46:21.546+0000] {taskinstance.py:1149} INFO - Marking task as SUCCESS. dag_id=token_refresher_50mins, task_id=refresh_token, execution_date=20240413T050000, start_date=20240414T024620, end_date=20240414T024621
[2024-04-14T02:46:21.582+0000] {local_task_job_runner.py:234} INFO - Task exited with return code 0
[2024-04-14T02:46:21.624+0000] {taskinstance.py:3312} INFO - 1 downstream tasks scheduled from follow-on schedule check
