[2024-04-13T18:37:58.583+0000] {taskinstance.py:1979} INFO - Dependencies all met for dep_context=non-requeueable deps ti=<TaskInstance: token_refresher_50mins.refresh_token scheduled__2024-04-13T01:40:00+00:00 [queued]>
[2024-04-13T18:37:58.591+0000] {taskinstance.py:1979} INFO - Dependencies all met for dep_context=requeueable deps ti=<TaskInstance: token_refresher_50mins.refresh_token scheduled__2024-04-13T01:40:00+00:00 [queued]>
[2024-04-13T18:37:58.592+0000] {taskinstance.py:2193} INFO - Starting attempt 1 of 2
[2024-04-13T18:37:58.612+0000] {taskinstance.py:2217} INFO - Executing <Task(PythonOperator): refresh_token> on 2024-04-13 01:40:00+00:00
[2024-04-13T18:37:58.616+0000] {standard_task_runner.py:60} INFO - Started process 441 to run task
[2024-04-13T18:37:58.636+0000] {standard_task_runner.py:87} INFO - Running: ['***', 'tasks', 'run', 'token_refresher_50mins', 'refresh_token', 'scheduled__2024-04-13T01:40:00+00:00', '--job-id', '8', '--raw', '--subdir', 'DAGS_FOLDER/refresh_token.py', '--cfg-path', '/tmp/tmpef1y0aw7']
[2024-04-13T18:37:58.640+0000] {standard_task_runner.py:88} INFO - Job 8: Subtask refresh_token
[2024-04-13T18:37:58.722+0000] {task_command.py:423} INFO - Running <TaskInstance: token_refresher_50mins.refresh_token scheduled__2024-04-13T01:40:00+00:00 [running]> on host 209a9ac884b0
[2024-04-13T18:37:58.808+0000] {taskinstance.py:2513} INFO - Exporting env vars: AIRFLOW_CTX_DAG_OWNER='***' AIRFLOW_CTX_DAG_ID='token_refresher_50mins' AIRFLOW_CTX_TASK_ID='refresh_token' AIRFLOW_CTX_EXECUTION_DATE='2024-04-13T01:40:00+00:00' AIRFLOW_CTX_TRY_NUMBER='1' AIRFLOW_CTX_DAG_RUN_ID='scheduled__2024-04-13T01:40:00+00:00'
[2024-04-13T18:37:58.814+0000] {oauth2.py:471} INFO - User authentication requires interaction with your web browser. Once you enter your credentials and give authorization, you will be redirected to a url.  Paste that url you were directed to to complete the authorization.
[2024-04-13T18:37:58.816+0000] {taskinstance.py:2731} ERROR - Task failed with exception
Traceback (most recent call last):
  File "/home/airflow/.local/lib/python3.8/site-packages/airflow/models/taskinstance.py", line 444, in _execute_task
    result = _execute_callable(context=context, **execute_callable_kwargs)
  File "/home/airflow/.local/lib/python3.8/site-packages/airflow/models/taskinstance.py", line 414, in _execute_callable
    return execute_callable(context=context, **execute_callable_kwargs)
  File "/home/airflow/.local/lib/python3.8/site-packages/airflow/operators/python.py", line 200, in execute
    return_value = self.execute_callable()
  File "/home/airflow/.local/lib/python3.8/site-packages/airflow/operators/python.py", line 217, in execute_callable
    return self.python_callable(*self.op_args, **self.op_kwargs)
  File "/opt/airflow/dags/refresh_token.py", line 34, in refresh_token
    current_user = sp.current_user()
  File "/home/airflow/.local/lib/python3.8/site-packages/spotipy/client.py", line 1227, in current_user
    return self.me()
  File "/home/airflow/.local/lib/python3.8/site-packages/spotipy/client.py", line 1221, in me
    return self._get("me/")
  File "/home/airflow/.local/lib/python3.8/site-packages/spotipy/client.py", line 323, in _get
    return self._internal_call("GET", url, payload, kwargs)
  File "/home/airflow/.local/lib/python3.8/site-packages/spotipy/client.py", line 247, in _internal_call
    headers = self._auth_headers()
  File "/home/airflow/.local/lib/python3.8/site-packages/spotipy/client.py", line 238, in _auth_headers
    token = self.auth_manager.get_access_token(as_dict=False)
  File "/home/airflow/.local/lib/python3.8/site-packages/spotipy/oauth2.py", line 535, in get_access_token
    "code": code or self.get_auth_response(),
  File "/home/airflow/.local/lib/python3.8/site-packages/spotipy/oauth2.py", line 490, in get_auth_response
    return self._get_auth_response_local_server(redirect_port)
  File "/home/airflow/.local/lib/python3.8/site-packages/spotipy/oauth2.py", line 457, in _get_auth_response_local_server
    server = start_local_http_server(redirect_port)
  File "/home/airflow/.local/lib/python3.8/site-packages/spotipy/oauth2.py", line 1303, in start_local_http_server
    server = HTTPServer(("127.0.0.1", port), handler)
  File "/usr/local/lib/python3.8/socketserver.py", line 452, in __init__
    self.server_bind()
  File "/usr/local/lib/python3.8/http/server.py", line 139, in server_bind
    socketserver.TCPServer.server_bind(self)
  File "/usr/local/lib/python3.8/socketserver.py", line 466, in server_bind
    self.socket.bind(self.server_address)
OSError: [Errno 98] Address already in use
[2024-04-13T18:37:58.831+0000] {taskinstance.py:1149} INFO - Marking task as UP_FOR_RETRY. dag_id=token_refresher_50mins, task_id=refresh_token, execution_date=20240413T014000, start_date=20240413T183758, end_date=20240413T183758
[2024-04-13T18:37:58.853+0000] {standard_task_runner.py:107} ERROR - Failed to execute job 8 for task refresh_token ([Errno 98] Address already in use; 441)
[2024-04-13T18:37:58.895+0000] {local_task_job_runner.py:234} INFO - Task exited with return code 1
[2024-04-13T18:37:58.948+0000] {taskinstance.py:3312} INFO - 0 downstream tasks scheduled from follow-on schedule check
[2024-04-13T18:39:59.601+0000] {taskinstance.py:1979} INFO - Dependencies all met for dep_context=non-requeueable deps ti=<TaskInstance: token_refresher_50mins.refresh_token scheduled__2024-04-13T01:40:00+00:00 [queued]>
[2024-04-13T18:39:59.607+0000] {taskinstance.py:1979} INFO - Dependencies all met for dep_context=requeueable deps ti=<TaskInstance: token_refresher_50mins.refresh_token scheduled__2024-04-13T01:40:00+00:00 [queued]>
[2024-04-13T18:39:59.609+0000] {taskinstance.py:2193} INFO - Starting attempt 1 of 2
[2024-04-13T18:39:59.621+0000] {taskinstance.py:2217} INFO - Executing <Task(PythonOperator): refresh_token> on 2024-04-13 01:40:00+00:00
[2024-04-13T18:39:59.625+0000] {standard_task_runner.py:60} INFO - Started process 507 to run task
[2024-04-13T18:39:59.630+0000] {standard_task_runner.py:87} INFO - Running: ['***', 'tasks', 'run', 'token_refresher_50mins', 'refresh_token', 'scheduled__2024-04-13T01:40:00+00:00', '--job-id', '26', '--raw', '--subdir', 'DAGS_FOLDER/refresh_token.py', '--cfg-path', '/tmp/tmpuwm0n0bp']
[2024-04-13T18:39:59.631+0000] {standard_task_runner.py:88} INFO - Job 26: Subtask refresh_token
[2024-04-13T18:39:59.663+0000] {task_command.py:423} INFO - Running <TaskInstance: token_refresher_50mins.refresh_token scheduled__2024-04-13T01:40:00+00:00 [running]> on host 209a9ac884b0
[2024-04-13T18:39:59.712+0000] {taskinstance.py:2513} INFO - Exporting env vars: AIRFLOW_CTX_DAG_OWNER='***' AIRFLOW_CTX_DAG_ID='token_refresher_50mins' AIRFLOW_CTX_TASK_ID='refresh_token' AIRFLOW_CTX_EXECUTION_DATE='2024-04-13T01:40:00+00:00' AIRFLOW_CTX_TRY_NUMBER='1' AIRFLOW_CTX_DAG_RUN_ID='scheduled__2024-04-13T01:40:00+00:00'
[2024-04-13T18:39:59.713+0000] {oauth2.py:471} INFO - User authentication requires interaction with your web browser. Once you enter your credentials and give authorization, you will be redirected to a url.  Paste that url you were directed to to complete the authorization.
[2024-04-13T18:39:59.714+0000] {taskinstance.py:2731} ERROR - Task failed with exception
Traceback (most recent call last):
  File "/home/airflow/.local/lib/python3.8/site-packages/airflow/models/taskinstance.py", line 444, in _execute_task
    result = _execute_callable(context=context, **execute_callable_kwargs)
  File "/home/airflow/.local/lib/python3.8/site-packages/airflow/models/taskinstance.py", line 414, in _execute_callable
    return execute_callable(context=context, **execute_callable_kwargs)
  File "/home/airflow/.local/lib/python3.8/site-packages/airflow/operators/python.py", line 200, in execute
    return_value = self.execute_callable()
  File "/home/airflow/.local/lib/python3.8/site-packages/airflow/operators/python.py", line 217, in execute_callable
    return self.python_callable(*self.op_args, **self.op_kwargs)
  File "/opt/airflow/dags/refresh_token.py", line 34, in refresh_token
    current_user = sp.current_user()
  File "/home/airflow/.local/lib/python3.8/site-packages/spotipy/client.py", line 1227, in current_user
    return self.me()
  File "/home/airflow/.local/lib/python3.8/site-packages/spotipy/client.py", line 1221, in me
    return self._get("me/")
  File "/home/airflow/.local/lib/python3.8/site-packages/spotipy/client.py", line 323, in _get
    return self._internal_call("GET", url, payload, kwargs)
  File "/home/airflow/.local/lib/python3.8/site-packages/spotipy/client.py", line 247, in _internal_call
    headers = self._auth_headers()
  File "/home/airflow/.local/lib/python3.8/site-packages/spotipy/client.py", line 238, in _auth_headers
    token = self.auth_manager.get_access_token(as_dict=False)
  File "/home/airflow/.local/lib/python3.8/site-packages/spotipy/oauth2.py", line 535, in get_access_token
    "code": code or self.get_auth_response(),
  File "/home/airflow/.local/lib/python3.8/site-packages/spotipy/oauth2.py", line 490, in get_auth_response
    return self._get_auth_response_local_server(redirect_port)
  File "/home/airflow/.local/lib/python3.8/site-packages/spotipy/oauth2.py", line 457, in _get_auth_response_local_server
    server = start_local_http_server(redirect_port)
  File "/home/airflow/.local/lib/python3.8/site-packages/spotipy/oauth2.py", line 1303, in start_local_http_server
    server = HTTPServer(("127.0.0.1", port), handler)
  File "/usr/local/lib/python3.8/socketserver.py", line 452, in __init__
    self.server_bind()
  File "/usr/local/lib/python3.8/http/server.py", line 139, in server_bind
    socketserver.TCPServer.server_bind(self)
  File "/usr/local/lib/python3.8/socketserver.py", line 466, in server_bind
    self.socket.bind(self.server_address)
OSError: [Errno 98] Address already in use
[2024-04-13T18:39:59.725+0000] {taskinstance.py:1149} INFO - Marking task as UP_FOR_RETRY. dag_id=token_refresher_50mins, task_id=refresh_token, execution_date=20240413T014000, start_date=20240413T183959, end_date=20240413T183959
[2024-04-13T18:39:59.737+0000] {standard_task_runner.py:107} ERROR - Failed to execute job 26 for task refresh_token ([Errno 98] Address already in use; 507)
[2024-04-13T18:39:59.765+0000] {local_task_job_runner.py:234} INFO - Task exited with return code 1
[2024-04-13T18:39:59.790+0000] {taskinstance.py:3312} INFO - 0 downstream tasks scheduled from follow-on schedule check
[2024-04-13T18:41:29.985+0000] {taskinstance.py:1979} INFO - Dependencies all met for dep_context=non-requeueable deps ti=<TaskInstance: token_refresher_50mins.refresh_token scheduled__2024-04-13T01:40:00+00:00 [queued]>
[2024-04-13T18:41:29.991+0000] {taskinstance.py:1979} INFO - Dependencies all met for dep_context=requeueable deps ti=<TaskInstance: token_refresher_50mins.refresh_token scheduled__2024-04-13T01:40:00+00:00 [queued]>
[2024-04-13T18:41:29.992+0000] {taskinstance.py:2193} INFO - Starting attempt 1 of 2
[2024-04-13T18:41:30.000+0000] {taskinstance.py:2217} INFO - Executing <Task(PythonOperator): refresh_token> on 2024-04-13 01:40:00+00:00
[2024-04-13T18:41:30.003+0000] {standard_task_runner.py:60} INFO - Started process 561 to run task
[2024-04-13T18:41:30.005+0000] {standard_task_runner.py:87} INFO - Running: ['***', 'tasks', 'run', 'token_refresher_50mins', 'refresh_token', 'scheduled__2024-04-13T01:40:00+00:00', '--job-id', '41', '--raw', '--subdir', 'DAGS_FOLDER/refresh_token.py', '--cfg-path', '/tmp/tmpx9tyxdbz']
[2024-04-13T18:41:30.009+0000] {standard_task_runner.py:88} INFO - Job 41: Subtask refresh_token
[2024-04-13T18:41:30.040+0000] {task_command.py:423} INFO - Running <TaskInstance: token_refresher_50mins.refresh_token scheduled__2024-04-13T01:40:00+00:00 [running]> on host 209a9ac884b0
[2024-04-13T18:41:30.097+0000] {taskinstance.py:2513} INFO - Exporting env vars: AIRFLOW_CTX_DAG_OWNER='***' AIRFLOW_CTX_DAG_ID='token_refresher_50mins' AIRFLOW_CTX_TASK_ID='refresh_token' AIRFLOW_CTX_EXECUTION_DATE='2024-04-13T01:40:00+00:00' AIRFLOW_CTX_TRY_NUMBER='1' AIRFLOW_CTX_DAG_RUN_ID='scheduled__2024-04-13T01:40:00+00:00'
[2024-04-13T18:41:30.099+0000] {oauth2.py:471} INFO - User authentication requires interaction with your web browser. Once you enter your credentials and give authorization, you will be redirected to a url.  Paste that url you were directed to to complete the authorization.
[2024-04-13T18:41:30.102+0000] {taskinstance.py:2731} ERROR - Task failed with exception
Traceback (most recent call last):
  File "/home/airflow/.local/lib/python3.8/site-packages/airflow/models/taskinstance.py", line 444, in _execute_task
    result = _execute_callable(context=context, **execute_callable_kwargs)
  File "/home/airflow/.local/lib/python3.8/site-packages/airflow/models/taskinstance.py", line 414, in _execute_callable
    return execute_callable(context=context, **execute_callable_kwargs)
  File "/home/airflow/.local/lib/python3.8/site-packages/airflow/operators/python.py", line 200, in execute
    return_value = self.execute_callable()
  File "/home/airflow/.local/lib/python3.8/site-packages/airflow/operators/python.py", line 217, in execute_callable
    return self.python_callable(*self.op_args, **self.op_kwargs)
  File "/opt/airflow/dags/refresh_token.py", line 34, in refresh_token
    current_user = sp.current_user()
  File "/home/airflow/.local/lib/python3.8/site-packages/spotipy/client.py", line 1227, in current_user
    return self.me()
  File "/home/airflow/.local/lib/python3.8/site-packages/spotipy/client.py", line 1221, in me
    return self._get("me/")
  File "/home/airflow/.local/lib/python3.8/site-packages/spotipy/client.py", line 323, in _get
    return self._internal_call("GET", url, payload, kwargs)
  File "/home/airflow/.local/lib/python3.8/site-packages/spotipy/client.py", line 247, in _internal_call
    headers = self._auth_headers()
  File "/home/airflow/.local/lib/python3.8/site-packages/spotipy/client.py", line 238, in _auth_headers
    token = self.auth_manager.get_access_token(as_dict=False)
  File "/home/airflow/.local/lib/python3.8/site-packages/spotipy/oauth2.py", line 535, in get_access_token
    "code": code or self.get_auth_response(),
  File "/home/airflow/.local/lib/python3.8/site-packages/spotipy/oauth2.py", line 490, in get_auth_response
    return self._get_auth_response_local_server(redirect_port)
  File "/home/airflow/.local/lib/python3.8/site-packages/spotipy/oauth2.py", line 457, in _get_auth_response_local_server
    server = start_local_http_server(redirect_port)
  File "/home/airflow/.local/lib/python3.8/site-packages/spotipy/oauth2.py", line 1303, in start_local_http_server
    server = HTTPServer(("127.0.0.1", port), handler)
  File "/usr/local/lib/python3.8/socketserver.py", line 452, in __init__
    self.server_bind()
  File "/usr/local/lib/python3.8/http/server.py", line 139, in server_bind
    socketserver.TCPServer.server_bind(self)
  File "/usr/local/lib/python3.8/socketserver.py", line 466, in server_bind
    self.socket.bind(self.server_address)
OSError: [Errno 98] Address already in use
[2024-04-13T18:41:30.111+0000] {taskinstance.py:1149} INFO - Marking task as UP_FOR_RETRY. dag_id=token_refresher_50mins, task_id=refresh_token, execution_date=20240413T014000, start_date=20240413T184129, end_date=20240413T184130
[2024-04-13T18:41:30.121+0000] {standard_task_runner.py:107} ERROR - Failed to execute job 41 for task refresh_token ([Errno 98] Address already in use; 561)
[2024-04-13T18:41:30.145+0000] {local_task_job_runner.py:234} INFO - Task exited with return code 1
[2024-04-13T18:41:30.187+0000] {taskinstance.py:3312} INFO - 0 downstream tasks scheduled from follow-on schedule check
[2024-04-14T02:34:45.432+0000] {taskinstance.py:1979} INFO - Dependencies all met for dep_context=non-requeueable deps ti=<TaskInstance: token_refresher_50mins.refresh_token scheduled__2024-04-13T01:40:00+00:00 [queued]>
[2024-04-14T02:34:45.440+0000] {taskinstance.py:1979} INFO - Dependencies all met for dep_context=requeueable deps ti=<TaskInstance: token_refresher_50mins.refresh_token scheduled__2024-04-13T01:40:00+00:00 [queued]>
[2024-04-14T02:34:45.441+0000] {taskinstance.py:2193} INFO - Starting attempt 1 of 2
[2024-04-14T02:34:45.451+0000] {taskinstance.py:2217} INFO - Executing <Task(PythonOperator): refresh_token> on 2024-04-13 01:40:00+00:00
[2024-04-14T02:34:45.454+0000] {standard_task_runner.py:60} INFO - Started process 890 to run task
[2024-04-14T02:34:45.456+0000] {standard_task_runner.py:87} INFO - Running: ['***', 'tasks', 'run', 'token_refresher_50mins', 'refresh_token', 'scheduled__2024-04-13T01:40:00+00:00', '--job-id', '122', '--raw', '--subdir', 'DAGS_FOLDER/refresh_token.py', '--cfg-path', '/tmp/tmptd3gyjyq']
[2024-04-14T02:34:45.457+0000] {standard_task_runner.py:88} INFO - Job 122: Subtask refresh_token
[2024-04-14T02:34:45.493+0000] {task_command.py:423} INFO - Running <TaskInstance: token_refresher_50mins.refresh_token scheduled__2024-04-13T01:40:00+00:00 [running]> on host 209a9ac884b0
[2024-04-14T02:34:45.558+0000] {taskinstance.py:2513} INFO - Exporting env vars: AIRFLOW_CTX_DAG_OWNER='***' AIRFLOW_CTX_DAG_ID='token_refresher_50mins' AIRFLOW_CTX_TASK_ID='refresh_token' AIRFLOW_CTX_EXECUTION_DATE='2024-04-13T01:40:00+00:00' AIRFLOW_CTX_TRY_NUMBER='1' AIRFLOW_CTX_DAG_RUN_ID='scheduled__2024-04-13T01:40:00+00:00'
[2024-04-14T02:34:45.629+0000] {logging_mixin.py:188} INFO - BQB3nBo3hk23G3Jp4v2lMiEvBI9c84XnwYYC_7gHoaA5scKiJtL8LAdQUB5j-hN_tUO4pyckb2kitsV6XuwoMMm_03-TI6BT8AOrLRTvYPKYCBux-vE
[2024-04-14T02:34:45.632+0000] {python.py:202} INFO - Done. Returned value was: None
[2024-04-14T02:34:45.641+0000] {taskinstance.py:1149} INFO - Marking task as SUCCESS. dag_id=token_refresher_50mins, task_id=refresh_token, execution_date=20240413T014000, start_date=20240414T023445, end_date=20240414T023445
[2024-04-14T02:34:45.678+0000] {local_task_job_runner.py:234} INFO - Task exited with return code 0
[2024-04-14T02:34:45.691+0000] {taskinstance.py:3312} INFO - 0 downstream tasks scheduled from follow-on schedule check
[2024-04-14T02:37:50.128+0000] {taskinstance.py:1979} INFO - Dependencies all met for dep_context=non-requeueable deps ti=<TaskInstance: token_refresher_50mins.refresh_token scheduled__2024-04-13T01:40:00+00:00 [queued]>
[2024-04-14T02:37:50.139+0000] {taskinstance.py:1979} INFO - Dependencies all met for dep_context=requeueable deps ti=<TaskInstance: token_refresher_50mins.refresh_token scheduled__2024-04-13T01:40:00+00:00 [queued]>
[2024-04-14T02:37:50.140+0000] {taskinstance.py:2193} INFO - Starting attempt 1 of 2
[2024-04-14T02:37:50.156+0000] {taskinstance.py:2217} INFO - Executing <Task(PythonOperator): refresh_token> on 2024-04-13 01:40:00+00:00
[2024-04-14T02:37:50.159+0000] {standard_task_runner.py:60} INFO - Started process 1004 to run task
[2024-04-14T02:37:50.162+0000] {standard_task_runner.py:87} INFO - Running: ['***', 'tasks', 'run', 'token_refresher_50mins', 'refresh_token', 'scheduled__2024-04-13T01:40:00+00:00', '--job-id', '155', '--raw', '--subdir', 'DAGS_FOLDER/refresh_token.py', '--cfg-path', '/tmp/tmp2idxki5d']
[2024-04-14T02:37:50.164+0000] {standard_task_runner.py:88} INFO - Job 155: Subtask refresh_token
[2024-04-14T02:37:50.219+0000] {task_command.py:423} INFO - Running <TaskInstance: token_refresher_50mins.refresh_token scheduled__2024-04-13T01:40:00+00:00 [running]> on host 209a9ac884b0
[2024-04-14T02:37:50.286+0000] {taskinstance.py:2513} INFO - Exporting env vars: AIRFLOW_CTX_DAG_OWNER='***' AIRFLOW_CTX_DAG_ID='token_refresher_50mins' AIRFLOW_CTX_TASK_ID='refresh_token' AIRFLOW_CTX_EXECUTION_DATE='2024-04-13T01:40:00+00:00' AIRFLOW_CTX_TRY_NUMBER='1' AIRFLOW_CTX_DAG_RUN_ID='scheduled__2024-04-13T01:40:00+00:00'
[2024-04-14T02:37:50.381+0000] {logging_mixin.py:188} WARNING - --- Logging error ---
[2024-04-14T02:37:50.383+0000] {logging_mixin.py:188} WARNING - Traceback (most recent call last):
[2024-04-14T02:37:50.383+0000] {logging_mixin.py:188} WARNING -   File "/usr/local/lib/python3.8/logging/__init__.py", line 1085, in emit
    msg = self.format(record)
[2024-04-14T02:37:50.384+0000] {logging_mixin.py:188} WARNING -   File "/usr/local/lib/python3.8/logging/__init__.py", line 929, in format
    return fmt.format(record)
[2024-04-14T02:37:50.384+0000] {logging_mixin.py:188} WARNING -   File "/usr/local/lib/python3.8/logging/__init__.py", line 668, in format
    record.message = record.getMessage()
[2024-04-14T02:37:50.385+0000] {logging_mixin.py:188} WARNING -   File "/usr/local/lib/python3.8/logging/__init__.py", line 373, in getMessage
    msg = msg % self.args
[2024-04-14T02:37:50.385+0000] {logging_mixin.py:188} WARNING - TypeError: not all arguments converted during string formatting
[2024-04-14T02:37:50.386+0000] {logging_mixin.py:188} WARNING - Call stack:
[2024-04-14T02:37:50.390+0000] {logging_mixin.py:188} WARNING -   File "/home/***/.local/bin/***", line 8, in <module>
    sys.exit(main())
[2024-04-14T02:37:50.391+0000] {logging_mixin.py:188} WARNING -   File "/home/***/.local/lib/python3.8/site-packages/***/__main__.py", line 57, in main
    args.func(args)
[2024-04-14T02:37:50.392+0000] {logging_mixin.py:188} WARNING -   File "/home/***/.local/lib/python3.8/site-packages/***/cli/cli_config.py", line 49, in command
    return func(*args, **kwargs)
[2024-04-14T02:37:50.392+0000] {logging_mixin.py:188} WARNING -   File "/home/***/.local/lib/python3.8/site-packages/***/utils/cli.py", line 114, in wrapper
    return f(*args, **kwargs)
[2024-04-14T02:37:50.393+0000] {logging_mixin.py:188} WARNING -   File "/home/***/.local/lib/python3.8/site-packages/***/providers/celery/cli/celery_command.py", line 60, in wrapper
    providers_configuration_loaded(func)(*args, **kwargs)
[2024-04-14T02:37:50.393+0000] {logging_mixin.py:188} WARNING -   File "/home/***/.local/lib/python3.8/site-packages/***/utils/providers_configuration_loader.py", line 55, in wrapped_function
    return func(*args, **kwargs)
[2024-04-14T02:37:50.394+0000] {logging_mixin.py:188} WARNING -   File "/home/***/.local/lib/python3.8/site-packages/***/providers/celery/cli/celery_command.py", line 231, in worker
    _run_command_with_daemon_option(
[2024-04-14T02:37:50.394+0000] {logging_mixin.py:188} WARNING -   File "/home/***/.local/lib/python3.8/site-packages/***/providers/celery/cli/celery_command.py", line 46, in _run_command_with_daemon_option
    run_command_with_daemon_option(*args, **kwargs)
[2024-04-14T02:37:50.395+0000] {logging_mixin.py:188} WARNING -   File "/home/***/.local/lib/python3.8/site-packages/***/cli/commands/daemon_utils.py", line 86, in run_command_with_daemon_option
    callback()
[2024-04-14T02:37:50.395+0000] {logging_mixin.py:188} WARNING -   File "/home/***/.local/lib/python3.8/site-packages/***/providers/celery/cli/celery_command.py", line 224, in run_celery_worker
    celery_app.worker_main(options)
[2024-04-14T02:37:50.396+0000] {logging_mixin.py:188} WARNING -   File "/home/***/.local/lib/python3.8/site-packages/celery/app/base.py", line 389, in worker_main
    self.start(argv=argv)
[2024-04-14T02:37:50.396+0000] {logging_mixin.py:188} WARNING -   File "/home/***/.local/lib/python3.8/site-packages/celery/app/base.py", line 369, in start
    celery.main(args=argv, standalone_mode=False)
[2024-04-14T02:37:50.397+0000] {logging_mixin.py:188} WARNING -   File "/home/***/.local/lib/python3.8/site-packages/click/core.py", line 1078, in main
    rv = self.invoke(ctx)
[2024-04-14T02:37:50.397+0000] {logging_mixin.py:188} WARNING -   File "/home/***/.local/lib/python3.8/site-packages/click/core.py", line 1688, in invoke
    return _process_result(sub_ctx.command.invoke(sub_ctx))
[2024-04-14T02:37:50.398+0000] {logging_mixin.py:188} WARNING -   File "/home/***/.local/lib/python3.8/site-packages/click/core.py", line 1434, in invoke
    return ctx.invoke(self.callback, **ctx.params)
[2024-04-14T02:37:50.398+0000] {logging_mixin.py:188} WARNING -   File "/home/***/.local/lib/python3.8/site-packages/click/core.py", line 783, in invoke
    return __callback(*args, **kwargs)
[2024-04-14T02:37:50.399+0000] {logging_mixin.py:188} WARNING -   File "/home/***/.local/lib/python3.8/site-packages/click/decorators.py", line 33, in new_func
    return f(get_current_context(), *args, **kwargs)
[2024-04-14T02:37:50.399+0000] {logging_mixin.py:188} WARNING -   File "/home/***/.local/lib/python3.8/site-packages/celery/bin/base.py", line 134, in caller
    return f(ctx, *args, **kwargs)
[2024-04-14T02:37:50.400+0000] {logging_mixin.py:188} WARNING -   File "/home/***/.local/lib/python3.8/site-packages/celery/bin/worker.py", line 356, in worker
    worker.start()
[2024-04-14T02:37:50.401+0000] {logging_mixin.py:188} WARNING -   File "/home/***/.local/lib/python3.8/site-packages/celery/worker/worker.py", line 202, in start
    self.blueprint.start(self)
[2024-04-14T02:37:50.402+0000] {logging_mixin.py:188} WARNING -   File "/home/***/.local/lib/python3.8/site-packages/celery/bootsteps.py", line 116, in start
    step.start(parent)
[2024-04-14T02:37:50.402+0000] {logging_mixin.py:188} WARNING -   File "/home/***/.local/lib/python3.8/site-packages/celery/bootsteps.py", line 365, in start
    return self.obj.start()
[2024-04-14T02:37:50.403+0000] {logging_mixin.py:188} WARNING -   File "/home/***/.local/lib/python3.8/site-packages/celery/concurrency/base.py", line 130, in start
    self.on_start()
[2024-04-14T02:37:50.403+0000] {logging_mixin.py:188} WARNING -   File "/home/***/.local/lib/python3.8/site-packages/celery/concurrency/prefork.py", line 109, in on_start
    P = self._pool = Pool(processes=self.limit,
[2024-04-14T02:37:50.404+0000] {logging_mixin.py:188} WARNING -   File "/home/***/.local/lib/python3.8/site-packages/celery/concurrency/asynpool.py", line 464, in __init__
    super().__init__(processes, *args, **kwargs)
[2024-04-14T02:37:50.404+0000] {logging_mixin.py:188} WARNING -   File "/home/***/.local/lib/python3.8/site-packages/billiard/pool.py", line 1045, in __init__
    self._create_worker_process(i)
[2024-04-14T02:37:50.404+0000] {logging_mixin.py:188} WARNING -   File "/home/***/.local/lib/python3.8/site-packages/celery/concurrency/asynpool.py", line 482, in _create_worker_process
    return super()._create_worker_process(i)
[2024-04-14T02:37:50.405+0000] {logging_mixin.py:188} WARNING -   File "/home/***/.local/lib/python3.8/site-packages/billiard/pool.py", line 1157, in _create_worker_process
    w.start()
[2024-04-14T02:37:50.405+0000] {logging_mixin.py:188} WARNING -   File "/home/***/.local/lib/python3.8/site-packages/billiard/process.py", line 120, in start
    self._popen = self._Popen(self)
[2024-04-14T02:37:50.406+0000] {logging_mixin.py:188} WARNING -   File "/home/***/.local/lib/python3.8/site-packages/billiard/context.py", line 331, in _Popen
    return Popen(process_obj)
[2024-04-14T02:37:50.407+0000] {logging_mixin.py:188} WARNING -   File "/home/***/.local/lib/python3.8/site-packages/billiard/popen_fork.py", line 22, in __init__
    self._launch(process_obj)
[2024-04-14T02:37:50.413+0000] {logging_mixin.py:188} WARNING -   File "/home/***/.local/lib/python3.8/site-packages/billiard/popen_fork.py", line 77, in _launch
    code = process_obj._bootstrap()
[2024-04-14T02:37:50.419+0000] {logging_mixin.py:188} WARNING -   File "/home/***/.local/lib/python3.8/site-packages/billiard/process.py", line 323, in _bootstrap
    self.run()
[2024-04-14T02:37:50.421+0000] {logging_mixin.py:188} WARNING -   File "/home/***/.local/lib/python3.8/site-packages/billiard/process.py", line 110, in run
    self._target(*self._args, **self._kwargs)
[2024-04-14T02:37:50.423+0000] {logging_mixin.py:188} WARNING -   File "/home/***/.local/lib/python3.8/site-packages/billiard/pool.py", line 291, in __call__
    sys.exit(self.workloop(pid=pid))
[2024-04-14T02:37:50.425+0000] {logging_mixin.py:188} WARNING -   File "/home/***/.local/lib/python3.8/site-packages/billiard/pool.py", line 361, in workloop
    result = (True, prepare_result(fun(*args, **kwargs)))
[2024-04-14T02:37:50.426+0000] {logging_mixin.py:188} WARNING -   File "/home/***/.local/lib/python3.8/site-packages/celery/app/trace.py", line 675, in fast_trace_task
    R, I, T, Rstr = tasks[task].__trace__(
[2024-04-14T02:37:50.427+0000] {logging_mixin.py:188} WARNING -   File "/home/***/.local/lib/python3.8/site-packages/celery/app/trace.py", line 477, in trace_task
    R = retval = fun(*args, **kwargs)
[2024-04-14T02:37:50.427+0000] {logging_mixin.py:188} WARNING -   File "/home/***/.local/lib/python3.8/site-packages/celery/app/trace.py", line 760, in __protected_call__
    return self.run(*args, **kwargs)
[2024-04-14T02:37:50.428+0000] {logging_mixin.py:188} WARNING -   File "/home/***/.local/lib/python3.8/site-packages/***/providers/celery/executors/celery_executor_utils.py", line 135, in execute_command
    _execute_in_fork(command_to_exec, celery_task_id)
[2024-04-14T02:37:50.429+0000] {logging_mixin.py:188} WARNING -   File "/home/***/.local/lib/python3.8/site-packages/***/providers/celery/executors/celery_executor_utils.py", line 169, in _execute_in_fork
    args.func(args)
[2024-04-14T02:37:50.429+0000] {logging_mixin.py:188} WARNING -   File "/home/***/.local/lib/python3.8/site-packages/***/cli/cli_config.py", line 49, in command
    return func(*args, **kwargs)
[2024-04-14T02:37:50.430+0000] {logging_mixin.py:188} WARNING -   File "/home/***/.local/lib/python3.8/site-packages/***/utils/cli.py", line 114, in wrapper
    return f(*args, **kwargs)
[2024-04-14T02:37:50.430+0000] {logging_mixin.py:188} WARNING -   File "/home/***/.local/lib/python3.8/site-packages/***/cli/commands/task_command.py", line 438, in task_run
    task_return_code = _run_task_by_selected_method(args, _dag, ti)
[2024-04-14T02:37:50.431+0000] {logging_mixin.py:188} WARNING -   File "/home/***/.local/lib/python3.8/site-packages/***/cli/commands/task_command.py", line 216, in _run_task_by_selected_method
    return _run_task_by_local_task_job(args, ti)
[2024-04-14T02:37:50.432+0000] {logging_mixin.py:188} WARNING -   File "/home/***/.local/lib/python3.8/site-packages/***/cli/commands/task_command.py", line 278, in _run_task_by_local_task_job
    ret = run_job(job=job_runner.job, execute_callable=job_runner._execute)
[2024-04-14T02:37:50.432+0000] {logging_mixin.py:188} WARNING -   File "/home/***/.local/lib/python3.8/site-packages/***/utils/session.py", line 79, in wrapper
    return func(*args, session=session, **kwargs)
[2024-04-14T02:37:50.434+0000] {logging_mixin.py:188} WARNING -   File "/home/***/.local/lib/python3.8/site-packages/***/jobs/job.py", line 395, in run_job
    return execute_job(job, execute_callable=execute_callable)
[2024-04-14T02:37:50.435+0000] {logging_mixin.py:188} WARNING -   File "/home/***/.local/lib/python3.8/site-packages/***/jobs/job.py", line 424, in execute_job
    ret = execute_callable()
[2024-04-14T02:37:50.436+0000] {logging_mixin.py:188} WARNING -   File "/home/***/.local/lib/python3.8/site-packages/***/jobs/local_task_job_runner.py", line 165, in _execute
    self.task_runner.start()
[2024-04-14T02:37:50.437+0000] {logging_mixin.py:188} WARNING -   File "/home/***/.local/lib/python3.8/site-packages/***/task/task_runner/standard_task_runner.py", line 48, in start
    self.process = self._start_by_fork()
[2024-04-14T02:37:50.438+0000] {logging_mixin.py:188} WARNING -   File "/home/***/.local/lib/python3.8/site-packages/***/task/task_runner/standard_task_runner.py", line 100, in _start_by_fork
    ret = args.func(args, dag=self.dag)
[2024-04-14T02:37:50.439+0000] {logging_mixin.py:188} WARNING -   File "/home/***/.local/lib/python3.8/site-packages/***/cli/cli_config.py", line 49, in command
    return func(*args, **kwargs)
[2024-04-14T02:37:50.442+0000] {logging_mixin.py:188} WARNING -   File "/home/***/.local/lib/python3.8/site-packages/***/utils/cli.py", line 114, in wrapper
    return f(*args, **kwargs)
[2024-04-14T02:37:50.443+0000] {logging_mixin.py:188} WARNING -   File "/home/***/.local/lib/python3.8/site-packages/***/cli/commands/task_command.py", line 438, in task_run
    task_return_code = _run_task_by_selected_method(args, _dag, ti)
[2024-04-14T02:37:50.444+0000] {logging_mixin.py:188} WARNING -   File "/home/***/.local/lib/python3.8/site-packages/***/cli/commands/task_command.py", line 218, in _run_task_by_selected_method
    return _run_raw_task(args, ti)
[2024-04-14T02:37:50.445+0000] {logging_mixin.py:188} WARNING -   File "/home/***/.local/lib/python3.8/site-packages/***/cli/commands/task_command.py", line 297, in _run_raw_task
    return ti._run_raw_task(
[2024-04-14T02:37:50.445+0000] {logging_mixin.py:188} WARNING -   File "/home/***/.local/lib/python3.8/site-packages/***/utils/session.py", line 79, in wrapper
    return func(*args, session=session, **kwargs)
[2024-04-14T02:37:50.446+0000] {logging_mixin.py:188} WARNING -   File "/home/***/.local/lib/python3.8/site-packages/***/models/taskinstance.py", line 2360, in _run_raw_task
    self._execute_task_with_callbacks(context, test_mode, session=session)
[2024-04-14T02:37:50.446+0000] {logging_mixin.py:188} WARNING -   File "/home/***/.local/lib/python3.8/site-packages/***/models/taskinstance.py", line 2532, in _execute_task_with_callbacks
    result = self._execute_task(context, task_orig)
[2024-04-14T02:37:50.447+0000] {logging_mixin.py:188} WARNING -   File "/home/***/.local/lib/python3.8/site-packages/***/models/taskinstance.py", line 2549, in _execute_task
    return _execute_task(self, context, task_orig)
[2024-04-14T02:37:50.447+0000] {logging_mixin.py:188} WARNING -   File "/home/***/.local/lib/python3.8/site-packages/***/models/taskinstance.py", line 444, in _execute_task
    result = _execute_callable(context=context, **execute_callable_kwargs)
[2024-04-14T02:37:50.448+0000] {logging_mixin.py:188} WARNING -   File "/home/***/.local/lib/python3.8/site-packages/***/models/taskinstance.py", line 414, in _execute_callable
    return execute_callable(context=context, **execute_callable_kwargs)
[2024-04-14T02:37:50.448+0000] {logging_mixin.py:188} WARNING -   File "/home/***/.local/lib/python3.8/site-packages/***/operators/python.py", line 200, in execute
    return_value = self.execute_callable()
[2024-04-14T02:37:50.449+0000] {logging_mixin.py:188} WARNING -   File "/home/***/.local/lib/python3.8/site-packages/***/operators/python.py", line 217, in execute_callable
    return self.python_callable(*self.op_args, **self.op_kwargs)
[2024-04-14T02:37:50.449+0000] {logging_mixin.py:188} WARNING -   File "/opt/***/dags/refresh_token.py", line 46, in refresh_token
    logging.info("access_token:", access_token)
[2024-04-14T02:37:50.450+0000] {logging_mixin.py:188} WARNING -   File "/usr/local/lib/python3.8/logging/__init__.py", line 2082, in info
    root.info(msg, *args, **kwargs)
[2024-04-14T02:37:50.450+0000] {logging_mixin.py:188} WARNING -   File "/usr/local/lib/python3.8/logging/__init__.py", line 1446, in info
    self._log(INFO, msg, args, **kwargs)
[2024-04-14T02:37:50.450+0000] {logging_mixin.py:188} WARNING -   File "/usr/local/lib/python3.8/logging/__init__.py", line 1589, in _log
    self.handle(record)
[2024-04-14T02:37:50.451+0000] {logging_mixin.py:188} WARNING -   File "/usr/local/lib/python3.8/logging/__init__.py", line 1599, in handle
    self.callHandlers(record)
[2024-04-14T02:37:50.451+0000] {logging_mixin.py:188} WARNING -   File "/usr/local/lib/python3.8/logging/__init__.py", line 1661, in callHandlers
    hdlr.handle(record)
[2024-04-14T02:37:50.451+0000] {logging_mixin.py:188} WARNING -   File "/usr/local/lib/python3.8/logging/__init__.py", line 954, in handle
    self.emit(record)
[2024-04-14T02:37:50.452+0000] {logging_mixin.py:188} WARNING -   File "/home/***/.local/lib/python3.8/site-packages/***/utils/log/file_task_handler.py", line 247, in emit
    self.handler.emit(record)
[2024-04-14T02:37:50.452+0000] {logging_mixin.py:188} WARNING - Message: 'access_token:'
Arguments: ('BQCf2g1fR26RVim2sYMuxlJAeSuH9TeUz5HMb8wojs8D4C5PESiNyTVye0-AwLbYxN1zosUzFvaf2R07WxyDQ-IRPjN2xYmIfCqqZr55giBX841T5Io',)
[2024-04-14T02:37:50.454+0000] {python.py:202} INFO - Done. Returned value was: None
[2024-04-14T02:37:50.464+0000] {taskinstance.py:1149} INFO - Marking task as SUCCESS. dag_id=token_refresher_50mins, task_id=refresh_token, execution_date=20240413T014000, start_date=20240414T023750, end_date=20240414T023750
[2024-04-14T02:37:50.508+0000] {local_task_job_runner.py:234} INFO - Task exited with return code 0
[2024-04-14T02:37:50.518+0000] {taskinstance.py:3312} INFO - 0 downstream tasks scheduled from follow-on schedule check
[2024-04-14T02:45:05.525+0000] {taskinstance.py:1979} INFO - Dependencies all met for dep_context=non-requeueable deps ti=<TaskInstance: token_refresher_50mins.refresh_token scheduled__2024-04-13T01:40:00+00:00 [queued]>
[2024-04-14T02:45:05.536+0000] {taskinstance.py:1979} INFO - Dependencies all met for dep_context=requeueable deps ti=<TaskInstance: token_refresher_50mins.refresh_token scheduled__2024-04-13T01:40:00+00:00 [queued]>
[2024-04-14T02:45:05.537+0000] {taskinstance.py:2193} INFO - Starting attempt 1 of 2
[2024-04-14T02:45:05.578+0000] {taskinstance.py:2217} INFO - Executing <Task(PythonOperator): refresh_token> on 2024-04-13 01:40:00+00:00
[2024-04-14T02:45:05.582+0000] {standard_task_runner.py:60} INFO - Started process 1183 to run task
[2024-04-14T02:45:05.586+0000] {standard_task_runner.py:87} INFO - Running: ['***', 'tasks', 'run', 'token_refresher_50mins', 'refresh_token', 'scheduled__2024-04-13T01:40:00+00:00', '--job-id', '190', '--raw', '--subdir', 'DAGS_FOLDER/refresh_token.py', '--cfg-path', '/tmp/tmp_tju575x']
[2024-04-14T02:45:05.587+0000] {standard_task_runner.py:88} INFO - Job 190: Subtask refresh_token
[2024-04-14T02:45:05.647+0000] {task_command.py:423} INFO - Running <TaskInstance: token_refresher_50mins.refresh_token scheduled__2024-04-13T01:40:00+00:00 [running]> on host 209a9ac884b0
[2024-04-14T02:45:05.710+0000] {taskinstance.py:2513} INFO - Exporting env vars: AIRFLOW_CTX_DAG_OWNER='***' AIRFLOW_CTX_DAG_ID='token_refresher_50mins' AIRFLOW_CTX_TASK_ID='refresh_token' AIRFLOW_CTX_EXECUTION_DATE='2024-04-13T01:40:00+00:00' AIRFLOW_CTX_TRY_NUMBER='1' AIRFLOW_CTX_DAG_RUN_ID='scheduled__2024-04-13T01:40:00+00:00'
[2024-04-14T02:45:05.794+0000] {logging_mixin.py:188} WARNING - --- Logging error ---
[2024-04-14T02:45:05.795+0000] {logging_mixin.py:188} WARNING - Traceback (most recent call last):
[2024-04-14T02:45:05.796+0000] {logging_mixin.py:188} WARNING -   File "/usr/local/lib/python3.8/logging/__init__.py", line 1085, in emit
    msg = self.format(record)
[2024-04-14T02:45:05.796+0000] {logging_mixin.py:188} WARNING -   File "/usr/local/lib/python3.8/logging/__init__.py", line 929, in format
    return fmt.format(record)
[2024-04-14T02:45:05.797+0000] {logging_mixin.py:188} WARNING -   File "/usr/local/lib/python3.8/logging/__init__.py", line 668, in format
    record.message = record.getMessage()
[2024-04-14T02:45:05.797+0000] {logging_mixin.py:188} WARNING -   File "/usr/local/lib/python3.8/logging/__init__.py", line 373, in getMessage
    msg = msg % self.args
[2024-04-14T02:45:05.798+0000] {logging_mixin.py:188} WARNING - TypeError: not all arguments converted during string formatting
[2024-04-14T02:45:05.798+0000] {logging_mixin.py:188} WARNING - Call stack:
[2024-04-14T02:45:05.804+0000] {logging_mixin.py:188} WARNING -   File "/home/***/.local/bin/***", line 8, in <module>
    sys.exit(main())
[2024-04-14T02:45:05.805+0000] {logging_mixin.py:188} WARNING -   File "/home/***/.local/lib/python3.8/site-packages/***/__main__.py", line 57, in main
    args.func(args)
[2024-04-14T02:45:05.807+0000] {logging_mixin.py:188} WARNING -   File "/home/***/.local/lib/python3.8/site-packages/***/cli/cli_config.py", line 49, in command
    return func(*args, **kwargs)
[2024-04-14T02:45:05.808+0000] {logging_mixin.py:188} WARNING -   File "/home/***/.local/lib/python3.8/site-packages/***/utils/cli.py", line 114, in wrapper
    return f(*args, **kwargs)
[2024-04-14T02:45:05.809+0000] {logging_mixin.py:188} WARNING -   File "/home/***/.local/lib/python3.8/site-packages/***/providers/celery/cli/celery_command.py", line 60, in wrapper
    providers_configuration_loaded(func)(*args, **kwargs)
[2024-04-14T02:45:05.813+0000] {logging_mixin.py:188} WARNING -   File "/home/***/.local/lib/python3.8/site-packages/***/utils/providers_configuration_loader.py", line 55, in wrapped_function
    return func(*args, **kwargs)
[2024-04-14T02:45:05.813+0000] {logging_mixin.py:188} WARNING -   File "/home/***/.local/lib/python3.8/site-packages/***/providers/celery/cli/celery_command.py", line 231, in worker
    _run_command_with_daemon_option(
[2024-04-14T02:45:05.814+0000] {logging_mixin.py:188} WARNING -   File "/home/***/.local/lib/python3.8/site-packages/***/providers/celery/cli/celery_command.py", line 46, in _run_command_with_daemon_option
    run_command_with_daemon_option(*args, **kwargs)
[2024-04-14T02:45:05.818+0000] {logging_mixin.py:188} WARNING -   File "/home/***/.local/lib/python3.8/site-packages/***/cli/commands/daemon_utils.py", line 86, in run_command_with_daemon_option
    callback()
[2024-04-14T02:45:05.818+0000] {logging_mixin.py:188} WARNING -   File "/home/***/.local/lib/python3.8/site-packages/***/providers/celery/cli/celery_command.py", line 224, in run_celery_worker
    celery_app.worker_main(options)
[2024-04-14T02:45:05.819+0000] {logging_mixin.py:188} WARNING -   File "/home/***/.local/lib/python3.8/site-packages/celery/app/base.py", line 389, in worker_main
    self.start(argv=argv)
[2024-04-14T02:45:05.819+0000] {logging_mixin.py:188} WARNING -   File "/home/***/.local/lib/python3.8/site-packages/celery/app/base.py", line 369, in start
    celery.main(args=argv, standalone_mode=False)
[2024-04-14T02:45:05.819+0000] {logging_mixin.py:188} WARNING -   File "/home/***/.local/lib/python3.8/site-packages/click/core.py", line 1078, in main
    rv = self.invoke(ctx)
[2024-04-14T02:45:05.820+0000] {logging_mixin.py:188} WARNING -   File "/home/***/.local/lib/python3.8/site-packages/click/core.py", line 1688, in invoke
    return _process_result(sub_ctx.command.invoke(sub_ctx))
[2024-04-14T02:45:05.820+0000] {logging_mixin.py:188} WARNING -   File "/home/***/.local/lib/python3.8/site-packages/click/core.py", line 1434, in invoke
    return ctx.invoke(self.callback, **ctx.params)
[2024-04-14T02:45:05.821+0000] {logging_mixin.py:188} WARNING -   File "/home/***/.local/lib/python3.8/site-packages/click/core.py", line 783, in invoke
    return __callback(*args, **kwargs)
[2024-04-14T02:45:05.821+0000] {logging_mixin.py:188} WARNING -   File "/home/***/.local/lib/python3.8/site-packages/click/decorators.py", line 33, in new_func
    return f(get_current_context(), *args, **kwargs)
[2024-04-14T02:45:05.822+0000] {logging_mixin.py:188} WARNING -   File "/home/***/.local/lib/python3.8/site-packages/celery/bin/base.py", line 134, in caller
    return f(ctx, *args, **kwargs)
[2024-04-14T02:45:05.823+0000] {logging_mixin.py:188} WARNING -   File "/home/***/.local/lib/python3.8/site-packages/celery/bin/worker.py", line 356, in worker
    worker.start()
[2024-04-14T02:45:05.823+0000] {logging_mixin.py:188} WARNING -   File "/home/***/.local/lib/python3.8/site-packages/celery/worker/worker.py", line 202, in start
    self.blueprint.start(self)
[2024-04-14T02:45:05.824+0000] {logging_mixin.py:188} WARNING -   File "/home/***/.local/lib/python3.8/site-packages/celery/bootsteps.py", line 116, in start
    step.start(parent)
[2024-04-14T02:45:05.824+0000] {logging_mixin.py:188} WARNING -   File "/home/***/.local/lib/python3.8/site-packages/celery/bootsteps.py", line 365, in start
    return self.obj.start()
[2024-04-14T02:45:05.825+0000] {logging_mixin.py:188} WARNING -   File "/home/***/.local/lib/python3.8/site-packages/celery/concurrency/base.py", line 130, in start
    self.on_start()
[2024-04-14T02:45:05.825+0000] {logging_mixin.py:188} WARNING -   File "/home/***/.local/lib/python3.8/site-packages/celery/concurrency/prefork.py", line 109, in on_start
    P = self._pool = Pool(processes=self.limit,
[2024-04-14T02:45:05.826+0000] {logging_mixin.py:188} WARNING -   File "/home/***/.local/lib/python3.8/site-packages/celery/concurrency/asynpool.py", line 464, in __init__
    super().__init__(processes, *args, **kwargs)
[2024-04-14T02:45:05.827+0000] {logging_mixin.py:188} WARNING -   File "/home/***/.local/lib/python3.8/site-packages/billiard/pool.py", line 1045, in __init__
    self._create_worker_process(i)
[2024-04-14T02:45:05.828+0000] {logging_mixin.py:188} WARNING -   File "/home/***/.local/lib/python3.8/site-packages/celery/concurrency/asynpool.py", line 482, in _create_worker_process
    return super()._create_worker_process(i)
[2024-04-14T02:45:05.829+0000] {logging_mixin.py:188} WARNING -   File "/home/***/.local/lib/python3.8/site-packages/billiard/pool.py", line 1157, in _create_worker_process
    w.start()
[2024-04-14T02:45:05.829+0000] {logging_mixin.py:188} WARNING -   File "/home/***/.local/lib/python3.8/site-packages/billiard/process.py", line 120, in start
    self._popen = self._Popen(self)
[2024-04-14T02:45:05.830+0000] {logging_mixin.py:188} WARNING -   File "/home/***/.local/lib/python3.8/site-packages/billiard/context.py", line 331, in _Popen
    return Popen(process_obj)
[2024-04-14T02:45:05.830+0000] {logging_mixin.py:188} WARNING -   File "/home/***/.local/lib/python3.8/site-packages/billiard/popen_fork.py", line 22, in __init__
    self._launch(process_obj)
[2024-04-14T02:45:05.831+0000] {logging_mixin.py:188} WARNING -   File "/home/***/.local/lib/python3.8/site-packages/billiard/popen_fork.py", line 77, in _launch
    code = process_obj._bootstrap()
[2024-04-14T02:45:05.832+0000] {logging_mixin.py:188} WARNING -   File "/home/***/.local/lib/python3.8/site-packages/billiard/process.py", line 323, in _bootstrap
    self.run()
[2024-04-14T02:45:05.833+0000] {logging_mixin.py:188} WARNING -   File "/home/***/.local/lib/python3.8/site-packages/billiard/process.py", line 110, in run
    self._target(*self._args, **self._kwargs)
[2024-04-14T02:45:05.835+0000] {logging_mixin.py:188} WARNING -   File "/home/***/.local/lib/python3.8/site-packages/billiard/pool.py", line 291, in __call__
    sys.exit(self.workloop(pid=pid))
[2024-04-14T02:45:05.836+0000] {logging_mixin.py:188} WARNING -   File "/home/***/.local/lib/python3.8/site-packages/billiard/pool.py", line 361, in workloop
    result = (True, prepare_result(fun(*args, **kwargs)))
[2024-04-14T02:45:05.836+0000] {logging_mixin.py:188} WARNING -   File "/home/***/.local/lib/python3.8/site-packages/celery/app/trace.py", line 675, in fast_trace_task
    R, I, T, Rstr = tasks[task].__trace__(
[2024-04-14T02:45:05.837+0000] {logging_mixin.py:188} WARNING -   File "/home/***/.local/lib/python3.8/site-packages/celery/app/trace.py", line 477, in trace_task
    R = retval = fun(*args, **kwargs)
[2024-04-14T02:45:05.837+0000] {logging_mixin.py:188} WARNING -   File "/home/***/.local/lib/python3.8/site-packages/celery/app/trace.py", line 760, in __protected_call__
    return self.run(*args, **kwargs)
[2024-04-14T02:45:05.838+0000] {logging_mixin.py:188} WARNING -   File "/home/***/.local/lib/python3.8/site-packages/***/providers/celery/executors/celery_executor_utils.py", line 135, in execute_command
    _execute_in_fork(command_to_exec, celery_task_id)
[2024-04-14T02:45:05.838+0000] {logging_mixin.py:188} WARNING -   File "/home/***/.local/lib/python3.8/site-packages/***/providers/celery/executors/celery_executor_utils.py", line 169, in _execute_in_fork
    args.func(args)
[2024-04-14T02:45:05.838+0000] {logging_mixin.py:188} WARNING -   File "/home/***/.local/lib/python3.8/site-packages/***/cli/cli_config.py", line 49, in command
    return func(*args, **kwargs)
[2024-04-14T02:45:05.839+0000] {logging_mixin.py:188} WARNING -   File "/home/***/.local/lib/python3.8/site-packages/***/utils/cli.py", line 114, in wrapper
    return f(*args, **kwargs)
[2024-04-14T02:45:05.839+0000] {logging_mixin.py:188} WARNING -   File "/home/***/.local/lib/python3.8/site-packages/***/cli/commands/task_command.py", line 438, in task_run
    task_return_code = _run_task_by_selected_method(args, _dag, ti)
[2024-04-14T02:45:05.840+0000] {logging_mixin.py:188} WARNING -   File "/home/***/.local/lib/python3.8/site-packages/***/cli/commands/task_command.py", line 216, in _run_task_by_selected_method
    return _run_task_by_local_task_job(args, ti)
[2024-04-14T02:45:05.840+0000] {logging_mixin.py:188} WARNING -   File "/home/***/.local/lib/python3.8/site-packages/***/cli/commands/task_command.py", line 278, in _run_task_by_local_task_job
    ret = run_job(job=job_runner.job, execute_callable=job_runner._execute)
[2024-04-14T02:45:05.840+0000] {logging_mixin.py:188} WARNING -   File "/home/***/.local/lib/python3.8/site-packages/***/utils/session.py", line 79, in wrapper
    return func(*args, session=session, **kwargs)
[2024-04-14T02:45:05.841+0000] {logging_mixin.py:188} WARNING -   File "/home/***/.local/lib/python3.8/site-packages/***/jobs/job.py", line 395, in run_job
    return execute_job(job, execute_callable=execute_callable)
[2024-04-14T02:45:05.841+0000] {logging_mixin.py:188} WARNING -   File "/home/***/.local/lib/python3.8/site-packages/***/jobs/job.py", line 424, in execute_job
    ret = execute_callable()
[2024-04-14T02:45:05.842+0000] {logging_mixin.py:188} WARNING -   File "/home/***/.local/lib/python3.8/site-packages/***/jobs/local_task_job_runner.py", line 165, in _execute
    self.task_runner.start()
[2024-04-14T02:45:05.842+0000] {logging_mixin.py:188} WARNING -   File "/home/***/.local/lib/python3.8/site-packages/***/task/task_runner/standard_task_runner.py", line 48, in start
    self.process = self._start_by_fork()
[2024-04-14T02:45:05.842+0000] {logging_mixin.py:188} WARNING -   File "/home/***/.local/lib/python3.8/site-packages/***/task/task_runner/standard_task_runner.py", line 100, in _start_by_fork
    ret = args.func(args, dag=self.dag)
[2024-04-14T02:45:05.843+0000] {logging_mixin.py:188} WARNING -   File "/home/***/.local/lib/python3.8/site-packages/***/cli/cli_config.py", line 49, in command
    return func(*args, **kwargs)
[2024-04-14T02:45:05.844+0000] {logging_mixin.py:188} WARNING -   File "/home/***/.local/lib/python3.8/site-packages/***/utils/cli.py", line 114, in wrapper
    return f(*args, **kwargs)
[2024-04-14T02:45:05.844+0000] {logging_mixin.py:188} WARNING -   File "/home/***/.local/lib/python3.8/site-packages/***/cli/commands/task_command.py", line 438, in task_run
    task_return_code = _run_task_by_selected_method(args, _dag, ti)
[2024-04-14T02:45:05.844+0000] {logging_mixin.py:188} WARNING -   File "/home/***/.local/lib/python3.8/site-packages/***/cli/commands/task_command.py", line 218, in _run_task_by_selected_method
    return _run_raw_task(args, ti)
[2024-04-14T02:45:05.845+0000] {logging_mixin.py:188} WARNING -   File "/home/***/.local/lib/python3.8/site-packages/***/cli/commands/task_command.py", line 297, in _run_raw_task
    return ti._run_raw_task(
[2024-04-14T02:45:05.845+0000] {logging_mixin.py:188} WARNING -   File "/home/***/.local/lib/python3.8/site-packages/***/utils/session.py", line 79, in wrapper
    return func(*args, session=session, **kwargs)
[2024-04-14T02:45:05.846+0000] {logging_mixin.py:188} WARNING -   File "/home/***/.local/lib/python3.8/site-packages/***/models/taskinstance.py", line 2360, in _run_raw_task
    self._execute_task_with_callbacks(context, test_mode, session=session)
[2024-04-14T02:45:05.847+0000] {logging_mixin.py:188} WARNING -   File "/home/***/.local/lib/python3.8/site-packages/***/models/taskinstance.py", line 2532, in _execute_task_with_callbacks
    result = self._execute_task(context, task_orig)
[2024-04-14T02:45:05.847+0000] {logging_mixin.py:188} WARNING -   File "/home/***/.local/lib/python3.8/site-packages/***/models/taskinstance.py", line 2549, in _execute_task
    return _execute_task(self, context, task_orig)
[2024-04-14T02:45:05.848+0000] {logging_mixin.py:188} WARNING -   File "/home/***/.local/lib/python3.8/site-packages/***/models/taskinstance.py", line 444, in _execute_task
    result = _execute_callable(context=context, **execute_callable_kwargs)
[2024-04-14T02:45:05.849+0000] {logging_mixin.py:188} WARNING -   File "/home/***/.local/lib/python3.8/site-packages/***/models/taskinstance.py", line 414, in _execute_callable
    return execute_callable(context=context, **execute_callable_kwargs)
[2024-04-14T02:45:05.850+0000] {logging_mixin.py:188} WARNING -   File "/home/***/.local/lib/python3.8/site-packages/***/operators/python.py", line 200, in execute
    return_value = self.execute_callable()
[2024-04-14T02:45:05.851+0000] {logging_mixin.py:188} WARNING -   File "/home/***/.local/lib/python3.8/site-packages/***/operators/python.py", line 217, in execute_callable
    return self.python_callable(*self.op_args, **self.op_kwargs)
[2024-04-14T02:45:05.851+0000] {logging_mixin.py:188} WARNING -   File "/opt/***/dags/refresh_token.py", line 42, in refresh_token
    logging.info("access_token:", access_token)
[2024-04-14T02:45:05.852+0000] {logging_mixin.py:188} WARNING -   File "/usr/local/lib/python3.8/logging/__init__.py", line 2082, in info
    root.info(msg, *args, **kwargs)
[2024-04-14T02:45:05.855+0000] {logging_mixin.py:188} WARNING -   File "/usr/local/lib/python3.8/logging/__init__.py", line 1446, in info
    self._log(INFO, msg, args, **kwargs)
[2024-04-14T02:45:05.856+0000] {logging_mixin.py:188} WARNING -   File "/usr/local/lib/python3.8/logging/__init__.py", line 1589, in _log
    self.handle(record)
[2024-04-14T02:45:05.857+0000] {logging_mixin.py:188} WARNING -   File "/usr/local/lib/python3.8/logging/__init__.py", line 1599, in handle
    self.callHandlers(record)
[2024-04-14T02:45:05.858+0000] {logging_mixin.py:188} WARNING -   File "/usr/local/lib/python3.8/logging/__init__.py", line 1661, in callHandlers
    hdlr.handle(record)
[2024-04-14T02:45:05.858+0000] {logging_mixin.py:188} WARNING -   File "/usr/local/lib/python3.8/logging/__init__.py", line 954, in handle
    self.emit(record)
[2024-04-14T02:45:05.859+0000] {logging_mixin.py:188} WARNING -   File "/home/***/.local/lib/python3.8/site-packages/***/utils/log/file_task_handler.py", line 247, in emit
    self.handler.emit(record)
[2024-04-14T02:45:05.860+0000] {logging_mixin.py:188} WARNING - Message: 'access_token:'
Arguments: ('BQD8GA-xakMqCFzVuFC6Y-rAadZoCYCBQEV63MV6SSK7W6Rh8OoJgpyza7mvzD8Ihck1U0Sg8QuAmdyhwaRseRzZFnhYs8iPi80U2xyOKHRbxnF5io8',)
[2024-04-14T02:45:05.862+0000] {python.py:202} INFO - Done. Returned value was: None
[2024-04-14T02:45:05.870+0000] {taskinstance.py:1149} INFO - Marking task as SUCCESS. dag_id=token_refresher_50mins, task_id=refresh_token, execution_date=20240413T014000, start_date=20240414T024505, end_date=20240414T024505
[2024-04-14T02:45:05.895+0000] {local_task_job_runner.py:234} INFO - Task exited with return code 0
[2024-04-14T02:45:05.916+0000] {taskinstance.py:3312} INFO - 1 downstream tasks scheduled from follow-on schedule check
[2024-04-14T02:46:20.399+0000] {taskinstance.py:1979} INFO - Dependencies all met for dep_context=non-requeueable deps ti=<TaskInstance: token_refresher_50mins.refresh_token scheduled__2024-04-13T01:40:00+00:00 [queued]>
[2024-04-14T02:46:20.407+0000] {taskinstance.py:1979} INFO - Dependencies all met for dep_context=requeueable deps ti=<TaskInstance: token_refresher_50mins.refresh_token scheduled__2024-04-13T01:40:00+00:00 [queued]>
[2024-04-14T02:46:20.408+0000] {taskinstance.py:2193} INFO - Starting attempt 1 of 2
[2024-04-14T02:46:20.449+0000] {taskinstance.py:2217} INFO - Executing <Task(PythonOperator): refresh_token> on 2024-04-13 01:40:00+00:00
[2024-04-14T02:46:20.456+0000] {standard_task_runner.py:60} INFO - Started process 1273 to run task
[2024-04-14T02:46:20.462+0000] {standard_task_runner.py:87} INFO - Running: ['***', 'tasks', 'run', 'token_refresher_50mins', 'refresh_token', 'scheduled__2024-04-13T01:40:00+00:00', '--job-id', '224', '--raw', '--subdir', 'DAGS_FOLDER/refresh_token.py', '--cfg-path', '/tmp/tmpxh6sdqtf']
[2024-04-14T02:46:20.464+0000] {standard_task_runner.py:88} INFO - Job 224: Subtask refresh_token
[2024-04-14T02:46:20.527+0000] {task_command.py:423} INFO - Running <TaskInstance: token_refresher_50mins.refresh_token scheduled__2024-04-13T01:40:00+00:00 [running]> on host 209a9ac884b0
[2024-04-14T02:46:20.621+0000] {taskinstance.py:2513} INFO - Exporting env vars: AIRFLOW_CTX_DAG_OWNER='***' AIRFLOW_CTX_DAG_ID='token_refresher_50mins' AIRFLOW_CTX_TASK_ID='refresh_token' AIRFLOW_CTX_EXECUTION_DATE='2024-04-13T01:40:00+00:00' AIRFLOW_CTX_TRY_NUMBER='1' AIRFLOW_CTX_DAG_RUN_ID='scheduled__2024-04-13T01:40:00+00:00'
[2024-04-14T02:46:20.724+0000] {logging_mixin.py:188} WARNING - --- Logging error ---
[2024-04-14T02:46:20.726+0000] {logging_mixin.py:188} WARNING - Traceback (most recent call last):
[2024-04-14T02:46:20.728+0000] {logging_mixin.py:188} WARNING -   File "/usr/local/lib/python3.8/logging/__init__.py", line 1085, in emit
    msg = self.format(record)
[2024-04-14T02:46:20.729+0000] {logging_mixin.py:188} WARNING -   File "/usr/local/lib/python3.8/logging/__init__.py", line 929, in format
    return fmt.format(record)
[2024-04-14T02:46:20.729+0000] {logging_mixin.py:188} WARNING -   File "/usr/local/lib/python3.8/logging/__init__.py", line 668, in format
    record.message = record.getMessage()
[2024-04-14T02:46:20.730+0000] {logging_mixin.py:188} WARNING -   File "/usr/local/lib/python3.8/logging/__init__.py", line 373, in getMessage
    msg = msg % self.args
[2024-04-14T02:46:20.731+0000] {logging_mixin.py:188} WARNING - TypeError: not all arguments converted during string formatting
[2024-04-14T02:46:20.733+0000] {logging_mixin.py:188} WARNING - Call stack:
[2024-04-14T02:46:20.745+0000] {logging_mixin.py:188} WARNING -   File "/home/***/.local/bin/***", line 8, in <module>
    sys.exit(main())
[2024-04-14T02:46:20.750+0000] {logging_mixin.py:188} WARNING -   File "/home/***/.local/lib/python3.8/site-packages/***/__main__.py", line 57, in main
    args.func(args)
[2024-04-14T02:46:20.753+0000] {logging_mixin.py:188} WARNING -   File "/home/***/.local/lib/python3.8/site-packages/***/cli/cli_config.py", line 49, in command
    return func(*args, **kwargs)
[2024-04-14T02:46:20.757+0000] {logging_mixin.py:188} WARNING -   File "/home/***/.local/lib/python3.8/site-packages/***/utils/cli.py", line 114, in wrapper
    return f(*args, **kwargs)
[2024-04-14T02:46:20.758+0000] {logging_mixin.py:188} WARNING -   File "/home/***/.local/lib/python3.8/site-packages/***/providers/celery/cli/celery_command.py", line 60, in wrapper
    providers_configuration_loaded(func)(*args, **kwargs)
[2024-04-14T02:46:20.759+0000] {logging_mixin.py:188} WARNING -   File "/home/***/.local/lib/python3.8/site-packages/***/utils/providers_configuration_loader.py", line 55, in wrapped_function
    return func(*args, **kwargs)
[2024-04-14T02:46:20.760+0000] {logging_mixin.py:188} WARNING -   File "/home/***/.local/lib/python3.8/site-packages/***/providers/celery/cli/celery_command.py", line 231, in worker
    _run_command_with_daemon_option(
[2024-04-14T02:46:20.760+0000] {logging_mixin.py:188} WARNING -   File "/home/***/.local/lib/python3.8/site-packages/***/providers/celery/cli/celery_command.py", line 46, in _run_command_with_daemon_option
    run_command_with_daemon_option(*args, **kwargs)
[2024-04-14T02:46:20.762+0000] {logging_mixin.py:188} WARNING -   File "/home/***/.local/lib/python3.8/site-packages/***/cli/commands/daemon_utils.py", line 86, in run_command_with_daemon_option
    callback()
[2024-04-14T02:46:20.762+0000] {logging_mixin.py:188} WARNING -   File "/home/***/.local/lib/python3.8/site-packages/***/providers/celery/cli/celery_command.py", line 224, in run_celery_worker
    celery_app.worker_main(options)
[2024-04-14T02:46:20.763+0000] {logging_mixin.py:188} WARNING -   File "/home/***/.local/lib/python3.8/site-packages/celery/app/base.py", line 389, in worker_main
    self.start(argv=argv)
[2024-04-14T02:46:20.766+0000] {logging_mixin.py:188} WARNING -   File "/home/***/.local/lib/python3.8/site-packages/celery/app/base.py", line 369, in start
    celery.main(args=argv, standalone_mode=False)
[2024-04-14T02:46:20.769+0000] {logging_mixin.py:188} WARNING -   File "/home/***/.local/lib/python3.8/site-packages/click/core.py", line 1078, in main
    rv = self.invoke(ctx)
[2024-04-14T02:46:20.771+0000] {logging_mixin.py:188} WARNING -   File "/home/***/.local/lib/python3.8/site-packages/click/core.py", line 1688, in invoke
    return _process_result(sub_ctx.command.invoke(sub_ctx))
[2024-04-14T02:46:20.776+0000] {logging_mixin.py:188} WARNING -   File "/home/***/.local/lib/python3.8/site-packages/click/core.py", line 1434, in invoke
    return ctx.invoke(self.callback, **ctx.params)
[2024-04-14T02:46:20.777+0000] {logging_mixin.py:188} WARNING -   File "/home/***/.local/lib/python3.8/site-packages/click/core.py", line 783, in invoke
    return __callback(*args, **kwargs)
[2024-04-14T02:46:20.777+0000] {logging_mixin.py:188} WARNING -   File "/home/***/.local/lib/python3.8/site-packages/click/decorators.py", line 33, in new_func
    return f(get_current_context(), *args, **kwargs)
[2024-04-14T02:46:20.780+0000] {logging_mixin.py:188} WARNING -   File "/home/***/.local/lib/python3.8/site-packages/celery/bin/base.py", line 134, in caller
    return f(ctx, *args, **kwargs)
[2024-04-14T02:46:20.782+0000] {logging_mixin.py:188} WARNING -   File "/home/***/.local/lib/python3.8/site-packages/celery/bin/worker.py", line 356, in worker
    worker.start()
[2024-04-14T02:46:20.784+0000] {logging_mixin.py:188} WARNING -   File "/home/***/.local/lib/python3.8/site-packages/celery/worker/worker.py", line 202, in start
    self.blueprint.start(self)
[2024-04-14T02:46:20.784+0000] {logging_mixin.py:188} WARNING -   File "/home/***/.local/lib/python3.8/site-packages/celery/bootsteps.py", line 116, in start
    step.start(parent)
[2024-04-14T02:46:20.786+0000] {logging_mixin.py:188} WARNING -   File "/home/***/.local/lib/python3.8/site-packages/celery/bootsteps.py", line 365, in start
    return self.obj.start()
[2024-04-14T02:46:20.787+0000] {logging_mixin.py:188} WARNING -   File "/home/***/.local/lib/python3.8/site-packages/celery/concurrency/base.py", line 130, in start
    self.on_start()
[2024-04-14T02:46:20.789+0000] {logging_mixin.py:188} WARNING -   File "/home/***/.local/lib/python3.8/site-packages/celery/concurrency/prefork.py", line 109, in on_start
    P = self._pool = Pool(processes=self.limit,
[2024-04-14T02:46:20.790+0000] {logging_mixin.py:188} WARNING -   File "/home/***/.local/lib/python3.8/site-packages/celery/concurrency/asynpool.py", line 464, in __init__
    super().__init__(processes, *args, **kwargs)
[2024-04-14T02:46:20.791+0000] {logging_mixin.py:188} WARNING -   File "/home/***/.local/lib/python3.8/site-packages/billiard/pool.py", line 1045, in __init__
    self._create_worker_process(i)
[2024-04-14T02:46:20.791+0000] {logging_mixin.py:188} WARNING -   File "/home/***/.local/lib/python3.8/site-packages/celery/concurrency/asynpool.py", line 482, in _create_worker_process
    return super()._create_worker_process(i)
[2024-04-14T02:46:20.792+0000] {logging_mixin.py:188} WARNING -   File "/home/***/.local/lib/python3.8/site-packages/billiard/pool.py", line 1157, in _create_worker_process
    w.start()
[2024-04-14T02:46:20.792+0000] {logging_mixin.py:188} WARNING -   File "/home/***/.local/lib/python3.8/site-packages/billiard/process.py", line 120, in start
    self._popen = self._Popen(self)
[2024-04-14T02:46:20.792+0000] {logging_mixin.py:188} WARNING -   File "/home/***/.local/lib/python3.8/site-packages/billiard/context.py", line 331, in _Popen
    return Popen(process_obj)
[2024-04-14T02:46:20.793+0000] {logging_mixin.py:188} WARNING -   File "/home/***/.local/lib/python3.8/site-packages/billiard/popen_fork.py", line 22, in __init__
    self._launch(process_obj)
[2024-04-14T02:46:20.793+0000] {logging_mixin.py:188} WARNING -   File "/home/***/.local/lib/python3.8/site-packages/billiard/popen_fork.py", line 77, in _launch
    code = process_obj._bootstrap()
[2024-04-14T02:46:20.793+0000] {logging_mixin.py:188} WARNING -   File "/home/***/.local/lib/python3.8/site-packages/billiard/process.py", line 323, in _bootstrap
    self.run()
[2024-04-14T02:46:20.794+0000] {logging_mixin.py:188} WARNING -   File "/home/***/.local/lib/python3.8/site-packages/billiard/process.py", line 110, in run
    self._target(*self._args, **self._kwargs)
[2024-04-14T02:46:20.794+0000] {logging_mixin.py:188} WARNING -   File "/home/***/.local/lib/python3.8/site-packages/billiard/pool.py", line 291, in __call__
    sys.exit(self.workloop(pid=pid))
[2024-04-14T02:46:20.794+0000] {logging_mixin.py:188} WARNING -   File "/home/***/.local/lib/python3.8/site-packages/billiard/pool.py", line 361, in workloop
    result = (True, prepare_result(fun(*args, **kwargs)))
[2024-04-14T02:46:20.796+0000] {logging_mixin.py:188} WARNING -   File "/home/***/.local/lib/python3.8/site-packages/celery/app/trace.py", line 675, in fast_trace_task
    R, I, T, Rstr = tasks[task].__trace__(
[2024-04-14T02:46:20.796+0000] {logging_mixin.py:188} WARNING -   File "/home/***/.local/lib/python3.8/site-packages/celery/app/trace.py", line 477, in trace_task
    R = retval = fun(*args, **kwargs)
[2024-04-14T02:46:20.797+0000] {logging_mixin.py:188} WARNING -   File "/home/***/.local/lib/python3.8/site-packages/celery/app/trace.py", line 760, in __protected_call__
    return self.run(*args, **kwargs)
[2024-04-14T02:46:20.797+0000] {logging_mixin.py:188} WARNING -   File "/home/***/.local/lib/python3.8/site-packages/***/providers/celery/executors/celery_executor_utils.py", line 135, in execute_command
    _execute_in_fork(command_to_exec, celery_task_id)
[2024-04-14T02:46:20.799+0000] {logging_mixin.py:188} WARNING -   File "/home/***/.local/lib/python3.8/site-packages/***/providers/celery/executors/celery_executor_utils.py", line 169, in _execute_in_fork
    args.func(args)
[2024-04-14T02:46:20.800+0000] {logging_mixin.py:188} WARNING -   File "/home/***/.local/lib/python3.8/site-packages/***/cli/cli_config.py", line 49, in command
    return func(*args, **kwargs)
[2024-04-14T02:46:20.801+0000] {logging_mixin.py:188} WARNING -   File "/home/***/.local/lib/python3.8/site-packages/***/utils/cli.py", line 114, in wrapper
    return f(*args, **kwargs)
[2024-04-14T02:46:20.804+0000] {logging_mixin.py:188} WARNING -   File "/home/***/.local/lib/python3.8/site-packages/***/cli/commands/task_command.py", line 438, in task_run
    task_return_code = _run_task_by_selected_method(args, _dag, ti)
[2024-04-14T02:46:20.805+0000] {logging_mixin.py:188} WARNING -   File "/home/***/.local/lib/python3.8/site-packages/***/cli/commands/task_command.py", line 216, in _run_task_by_selected_method
    return _run_task_by_local_task_job(args, ti)
[2024-04-14T02:46:20.809+0000] {logging_mixin.py:188} WARNING -   File "/home/***/.local/lib/python3.8/site-packages/***/cli/commands/task_command.py", line 278, in _run_task_by_local_task_job
    ret = run_job(job=job_runner.job, execute_callable=job_runner._execute)
[2024-04-14T02:46:20.811+0000] {logging_mixin.py:188} WARNING -   File "/home/***/.local/lib/python3.8/site-packages/***/utils/session.py", line 79, in wrapper
    return func(*args, session=session, **kwargs)
[2024-04-14T02:46:20.812+0000] {logging_mixin.py:188} WARNING -   File "/home/***/.local/lib/python3.8/site-packages/***/jobs/job.py", line 395, in run_job
    return execute_job(job, execute_callable=execute_callable)
[2024-04-14T02:46:20.814+0000] {logging_mixin.py:188} WARNING -   File "/home/***/.local/lib/python3.8/site-packages/***/jobs/job.py", line 424, in execute_job
    ret = execute_callable()
[2024-04-14T02:46:20.823+0000] {logging_mixin.py:188} WARNING -   File "/home/***/.local/lib/python3.8/site-packages/***/jobs/local_task_job_runner.py", line 165, in _execute
    self.task_runner.start()
[2024-04-14T02:46:20.826+0000] {logging_mixin.py:188} WARNING -   File "/home/***/.local/lib/python3.8/site-packages/***/task/task_runner/standard_task_runner.py", line 48, in start
    self.process = self._start_by_fork()
[2024-04-14T02:46:20.829+0000] {logging_mixin.py:188} WARNING -   File "/home/***/.local/lib/python3.8/site-packages/***/task/task_runner/standard_task_runner.py", line 100, in _start_by_fork
    ret = args.func(args, dag=self.dag)
[2024-04-14T02:46:20.830+0000] {logging_mixin.py:188} WARNING -   File "/home/***/.local/lib/python3.8/site-packages/***/cli/cli_config.py", line 49, in command
    return func(*args, **kwargs)
[2024-04-14T02:46:20.833+0000] {logging_mixin.py:188} WARNING -   File "/home/***/.local/lib/python3.8/site-packages/***/utils/cli.py", line 114, in wrapper
    return f(*args, **kwargs)
[2024-04-14T02:46:20.833+0000] {logging_mixin.py:188} WARNING -   File "/home/***/.local/lib/python3.8/site-packages/***/cli/commands/task_command.py", line 438, in task_run
    task_return_code = _run_task_by_selected_method(args, _dag, ti)
[2024-04-14T02:46:20.837+0000] {logging_mixin.py:188} WARNING -   File "/home/***/.local/lib/python3.8/site-packages/***/cli/commands/task_command.py", line 218, in _run_task_by_selected_method
    return _run_raw_task(args, ti)
[2024-04-14T02:46:20.839+0000] {logging_mixin.py:188} WARNING -   File "/home/***/.local/lib/python3.8/site-packages/***/cli/commands/task_command.py", line 297, in _run_raw_task
    return ti._run_raw_task(
[2024-04-14T02:46:20.844+0000] {logging_mixin.py:188} WARNING -   File "/home/***/.local/lib/python3.8/site-packages/***/utils/session.py", line 79, in wrapper
    return func(*args, session=session, **kwargs)
[2024-04-14T02:46:20.850+0000] {logging_mixin.py:188} WARNING -   File "/home/***/.local/lib/python3.8/site-packages/***/models/taskinstance.py", line 2360, in _run_raw_task
    self._execute_task_with_callbacks(context, test_mode, session=session)
[2024-04-14T02:46:20.855+0000] {logging_mixin.py:188} WARNING -   File "/home/***/.local/lib/python3.8/site-packages/***/models/taskinstance.py", line 2532, in _execute_task_with_callbacks
    result = self._execute_task(context, task_orig)
[2024-04-14T02:46:20.859+0000] {logging_mixin.py:188} WARNING -   File "/home/***/.local/lib/python3.8/site-packages/***/models/taskinstance.py", line 2549, in _execute_task
    return _execute_task(self, context, task_orig)
[2024-04-14T02:46:20.862+0000] {logging_mixin.py:188} WARNING -   File "/home/***/.local/lib/python3.8/site-packages/***/models/taskinstance.py", line 444, in _execute_task
    result = _execute_callable(context=context, **execute_callable_kwargs)
[2024-04-14T02:46:20.862+0000] {logging_mixin.py:188} WARNING -   File "/home/***/.local/lib/python3.8/site-packages/***/models/taskinstance.py", line 414, in _execute_callable
    return execute_callable(context=context, **execute_callable_kwargs)
[2024-04-14T02:46:20.863+0000] {logging_mixin.py:188} WARNING -   File "/home/***/.local/lib/python3.8/site-packages/***/operators/python.py", line 200, in execute
    return_value = self.execute_callable()
[2024-04-14T02:46:20.863+0000] {logging_mixin.py:188} WARNING -   File "/home/***/.local/lib/python3.8/site-packages/***/operators/python.py", line 217, in execute_callable
    return self.python_callable(*self.op_args, **self.op_kwargs)
[2024-04-14T02:46:20.872+0000] {logging_mixin.py:188} WARNING -   File "/opt/***/dags/refresh_token.py", line 42, in refresh_token
    logging.info("access_token:", access_token)
[2024-04-14T02:46:20.876+0000] {logging_mixin.py:188} WARNING -   File "/usr/local/lib/python3.8/logging/__init__.py", line 2082, in info
    root.info(msg, *args, **kwargs)
[2024-04-14T02:46:20.876+0000] {logging_mixin.py:188} WARNING -   File "/usr/local/lib/python3.8/logging/__init__.py", line 1446, in info
    self._log(INFO, msg, args, **kwargs)
[2024-04-14T02:46:20.879+0000] {logging_mixin.py:188} WARNING -   File "/usr/local/lib/python3.8/logging/__init__.py", line 1589, in _log
    self.handle(record)
[2024-04-14T02:46:20.880+0000] {logging_mixin.py:188} WARNING -   File "/usr/local/lib/python3.8/logging/__init__.py", line 1599, in handle
    self.callHandlers(record)
[2024-04-14T02:46:20.885+0000] {logging_mixin.py:188} WARNING -   File "/usr/local/lib/python3.8/logging/__init__.py", line 1661, in callHandlers
    hdlr.handle(record)
[2024-04-14T02:46:20.887+0000] {logging_mixin.py:188} WARNING -   File "/usr/local/lib/python3.8/logging/__init__.py", line 954, in handle
    self.emit(record)
[2024-04-14T02:46:20.889+0000] {logging_mixin.py:188} WARNING -   File "/home/***/.local/lib/python3.8/site-packages/***/utils/log/file_task_handler.py", line 247, in emit
    self.handler.emit(record)
[2024-04-14T02:46:20.890+0000] {logging_mixin.py:188} WARNING - Message: 'access_token:'
Arguments: ('BQCwFeDN8zk-Ysen0VEqoGVEgbW843kHVq4_KQjNjDVV7H8TJTsAIzlSaT9u-4W77JKixVMpbesmTZ27SJadlepjKCt6AEtGpzlR6z8Vp3I9ET25uBg',)
[2024-04-14T02:46:20.893+0000] {python.py:202} INFO - Done. Returned value was: None
[2024-04-14T02:46:20.918+0000] {taskinstance.py:1149} INFO - Marking task as SUCCESS. dag_id=token_refresher_50mins, task_id=refresh_token, execution_date=20240413T014000, start_date=20240414T024620, end_date=20240414T024620
[2024-04-14T02:46:20.982+0000] {local_task_job_runner.py:234} INFO - Task exited with return code 0
[2024-04-14T02:46:21.012+0000] {taskinstance.py:3312} INFO - 1 downstream tasks scheduled from follow-on schedule check
