[2024-04-17T00:30:09.876+0000] {taskinstance.py:1979} INFO - Dependencies all met for dep_context=non-requeueable deps ti=<TaskInstance: spotify_atomation.py.get_data scheduled__2024-04-16T00:00:00+00:00 [queued]>
[2024-04-17T00:30:09.883+0000] {taskinstance.py:1979} INFO - Dependencies all met for dep_context=requeueable deps ti=<TaskInstance: spotify_atomation.py.get_data scheduled__2024-04-16T00:00:00+00:00 [queued]>
[2024-04-17T00:30:09.883+0000] {taskinstance.py:2193} INFO - Starting attempt 1 of 1
[2024-04-17T00:30:09.893+0000] {taskinstance.py:2217} INFO - Executing <Task(PythonOperator): get_data> on 2024-04-16 00:00:00+00:00
[2024-04-17T00:30:09.896+0000] {standard_task_runner.py:60} INFO - Started process 24949 to run task
[2024-04-17T00:30:09.900+0000] {standard_task_runner.py:87} INFO - Running: ['***', 'tasks', 'run', 'spotify_atomation.py', 'get_data', 'scheduled__2024-04-16T00:00:00+00:00', '--job-id', '401', '--raw', '--subdir', 'DAGS_FOLDER/spotify_atomation.py', '--cfg-path', '/tmp/tmplos2iumd']
[2024-04-17T00:30:09.901+0000] {standard_task_runner.py:88} INFO - Job 401: Subtask get_data
[2024-04-17T00:30:09.948+0000] {task_command.py:423} INFO - Running <TaskInstance: spotify_atomation.py.get_data scheduled__2024-04-16T00:00:00+00:00 [running]> on host 209a9ac884b0
[2024-04-17T00:30:09.998+0000] {taskinstance.py:2513} INFO - Exporting env vars: AIRFLOW_CTX_DAG_OWNER='***' AIRFLOW_CTX_DAG_ID='spotify_atomation.py' AIRFLOW_CTX_TASK_ID='get_data' AIRFLOW_CTX_EXECUTION_DATE='2024-04-16T00:00:00+00:00' AIRFLOW_CTX_TRY_NUMBER='1' AIRFLOW_CTX_DAG_RUN_ID='scheduled__2024-04-16T00:00:00+00:00'
[2024-04-17T00:30:10.021+0000] {conn.py:380} INFO - <BrokerConnection node_id=bootstrap-0 host=broker:29092 <connecting> [IPv4 ('172.19.0.9', 29092)]>: connecting to broker:29092 [('172.19.0.9', 29092) IPv4]
[2024-04-17T00:30:10.022+0000] {conn.py:1206} INFO - Probing node bootstrap-0 broker version
[2024-04-17T00:30:10.024+0000] {conn.py:410} INFO - <BrokerConnection node_id=bootstrap-0 host=broker:29092 <connecting> [IPv4 ('172.19.0.9', 29092)]>: Connection complete.
[2024-04-17T00:30:10.130+0000] {conn.py:1268} INFO - Broker version identified as 2.6.0
[2024-04-17T00:30:10.130+0000] {conn.py:1269} INFO - Set configuration api_version=(2, 6, 0) to skip auto check_version requests on startup
[2024-04-17T00:30:10.133+0000] {spotify_atomation.py:88} INFO - Using access_token:BQBB8cd30Bplp78v3TlGFV0HS09HcRDoHSCdPbBs_j37wLvy_cHfhO58LkIxSaKmgqqxDtD-6N7Zg-ZtWWhkPXonYX3i61PlNik_3zo46VuwLEIbWpogckXj5vJgpbMcHOWi-47HjF3Q3eGOEms2hAintJm5O9RTO-h9u6Esv3nGIDNjdZCI5veCR6rclQ_vFhSp-8PjvRFajHkZdglo4NqX57uk1niY-4TCabcBDFiTWDv-
[2024-04-17T00:30:10.133+0000] {spotify_atomation.py:90} INFO - Using url: https://charts-spotify-com-service.spotify.com/auth/v0/charts/regional-global-daily/2024-01-01
[2024-04-17T00:30:10.929+0000] {taskinstance.py:2731} ERROR - Task failed with exception
Traceback (most recent call last):
  File "/home/airflow/.local/lib/python3.8/site-packages/urllib3/connection.py", line 174, in _new_conn
    conn = connection.create_connection(
  File "/home/airflow/.local/lib/python3.8/site-packages/urllib3/util/connection.py", line 72, in create_connection
    for res in socket.getaddrinfo(host, port, family, socket.SOCK_STREAM):
  File "/usr/local/lib/python3.8/socket.py", line 918, in getaddrinfo
    for res in _socket.getaddrinfo(host, port, family, type, proto, flags):
socket.gaierror: [Errno -2] Name or service not known

During handling of the above exception, another exception occurred:

Traceback (most recent call last):
  File "/home/airflow/.local/lib/python3.8/site-packages/urllib3/connectionpool.py", line 715, in urlopen
    httplib_response = self._make_request(
  File "/home/airflow/.local/lib/python3.8/site-packages/urllib3/connectionpool.py", line 404, in _make_request
    self._validate_conn(conn)
  File "/home/airflow/.local/lib/python3.8/site-packages/urllib3/connectionpool.py", line 1058, in _validate_conn
    conn.connect()
  File "/home/airflow/.local/lib/python3.8/site-packages/urllib3/connection.py", line 363, in connect
    self.sock = conn = self._new_conn()
  File "/home/airflow/.local/lib/python3.8/site-packages/urllib3/connection.py", line 186, in _new_conn
    raise NewConnectionError(
urllib3.exceptions.NewConnectionError: <urllib3.connection.HTTPSConnection object at 0xffff7589c640>: Failed to establish a new connection: [Errno -2] Name or service not known

During handling of the above exception, another exception occurred:

Traceback (most recent call last):
  File "/home/airflow/.local/lib/python3.8/site-packages/requests/adapters.py", line 486, in send
    resp = conn.urlopen(
  File "/home/airflow/.local/lib/python3.8/site-packages/urllib3/connectionpool.py", line 799, in urlopen
    retries = retries.increment(
  File "/home/airflow/.local/lib/python3.8/site-packages/urllib3/util/retry.py", line 592, in increment
    raise MaxRetryError(_pool, url, error or ResponseError(cause))
urllib3.exceptions.MaxRetryError: HTTPSConnectionPool(host='charts-spotify-com-service.spotify.com', port=443): Max retries exceeded with url: /auth/v0/charts/regional-global-daily/2024-01-01 (Caused by NewConnectionError('<urllib3.connection.HTTPSConnection object at 0xffff7589c640>: Failed to establish a new connection: [Errno -2] Name or service not known'))

During handling of the above exception, another exception occurred:

Traceback (most recent call last):
  File "/home/airflow/.local/lib/python3.8/site-packages/airflow/models/taskinstance.py", line 444, in _execute_task
    result = _execute_callable(context=context, **execute_callable_kwargs)
  File "/home/airflow/.local/lib/python3.8/site-packages/airflow/models/taskinstance.py", line 414, in _execute_callable
    return execute_callable(context=context, **execute_callable_kwargs)
  File "/home/airflow/.local/lib/python3.8/site-packages/airflow/operators/python.py", line 200, in execute
    return_value = self.execute_callable()
  File "/home/airflow/.local/lib/python3.8/site-packages/airflow/operators/python.py", line 217, in execute_callable
    return self.python_callable(*self.op_args, **self.op_kwargs)
  File "/opt/airflow/dags/spotify_atomation.py", line 91, in get_data
    response = requests.get(
  File "/home/airflow/.local/lib/python3.8/site-packages/requests/api.py", line 73, in get
    return request("get", url, params=params, **kwargs)
  File "/home/airflow/.local/lib/python3.8/site-packages/requests/api.py", line 59, in request
    return session.request(method=method, url=url, **kwargs)
  File "/home/airflow/.local/lib/python3.8/site-packages/requests/sessions.py", line 589, in request
    resp = self.send(prep, **send_kwargs)
  File "/home/airflow/.local/lib/python3.8/site-packages/requests/sessions.py", line 703, in send
    r = adapter.send(request, **kwargs)
  File "/home/airflow/.local/lib/python3.8/site-packages/requests/adapters.py", line 519, in send
    raise ConnectionError(e, request=request)
requests.exceptions.ConnectionError: HTTPSConnectionPool(host='charts-spotify-com-service.spotify.com', port=443): Max retries exceeded with url: /auth/v0/charts/regional-global-daily/2024-01-01 (Caused by NewConnectionError('<urllib3.connection.HTTPSConnection object at 0xffff7589c640>: Failed to establish a new connection: [Errno -2] Name or service not known'))
[2024-04-17T00:30:11.220+0000] {taskinstance.py:1149} INFO - Marking task as FAILED. dag_id=spotify_atomation.py, task_id=get_data, execution_date=20240416T000000, start_date=20240417T003009, end_date=20240417T003011
[2024-04-17T00:30:11.337+0000] {basenotifier.py:108} ERROR - Failed to send notification: <urlopen error [Errno -2] Name or service not known>
Traceback (most recent call last):
  File "/home/airflow/.local/lib/python3.8/site-packages/urllib3/connection.py", line 174, in _new_conn
    conn = connection.create_connection(
  File "/home/airflow/.local/lib/python3.8/site-packages/urllib3/util/connection.py", line 72, in create_connection
    for res in socket.getaddrinfo(host, port, family, socket.SOCK_STREAM):
  File "/usr/local/lib/python3.8/socket.py", line 918, in getaddrinfo
    for res in _socket.getaddrinfo(host, port, family, type, proto, flags):
socket.gaierror: [Errno -2] Name or service not known

During handling of the above exception, another exception occurred:

Traceback (most recent call last):
  File "/home/airflow/.local/lib/python3.8/site-packages/urllib3/connectionpool.py", line 715, in urlopen
    httplib_response = self._make_request(
  File "/home/airflow/.local/lib/python3.8/site-packages/urllib3/connectionpool.py", line 404, in _make_request
    self._validate_conn(conn)
  File "/home/airflow/.local/lib/python3.8/site-packages/urllib3/connectionpool.py", line 1058, in _validate_conn
    conn.connect()
  File "/home/airflow/.local/lib/python3.8/site-packages/urllib3/connection.py", line 363, in connect
    self.sock = conn = self._new_conn()
  File "/home/airflow/.local/lib/python3.8/site-packages/urllib3/connection.py", line 186, in _new_conn
    raise NewConnectionError(
urllib3.exceptions.NewConnectionError: <urllib3.connection.HTTPSConnection object at 0xffff7589c640>: Failed to establish a new connection: [Errno -2] Name or service not known

During handling of the above exception, another exception occurred:

Traceback (most recent call last):
  File "/home/airflow/.local/lib/python3.8/site-packages/requests/adapters.py", line 486, in send
    resp = conn.urlopen(
  File "/home/airflow/.local/lib/python3.8/site-packages/urllib3/connectionpool.py", line 799, in urlopen
    retries = retries.increment(
  File "/home/airflow/.local/lib/python3.8/site-packages/urllib3/util/retry.py", line 592, in increment
    raise MaxRetryError(_pool, url, error or ResponseError(cause))
urllib3.exceptions.MaxRetryError: HTTPSConnectionPool(host='charts-spotify-com-service.spotify.com', port=443): Max retries exceeded with url: /auth/v0/charts/regional-global-daily/2024-01-01 (Caused by NewConnectionError('<urllib3.connection.HTTPSConnection object at 0xffff7589c640>: Failed to establish a new connection: [Errno -2] Name or service not known'))

During handling of the above exception, another exception occurred:

Traceback (most recent call last):
  File "/home/airflow/.local/lib/python3.8/site-packages/airflow/models/taskinstance.py", line 2360, in _run_raw_task
    self._execute_task_with_callbacks(context, test_mode, session=session)
  File "/home/airflow/.local/lib/python3.8/site-packages/airflow/models/taskinstance.py", line 2532, in _execute_task_with_callbacks
    result = self._execute_task(context, task_orig)
  File "/home/airflow/.local/lib/python3.8/site-packages/airflow/models/taskinstance.py", line 2549, in _execute_task
    return _execute_task(self, context, task_orig)
  File "/home/airflow/.local/lib/python3.8/site-packages/airflow/models/taskinstance.py", line 444, in _execute_task
    result = _execute_callable(context=context, **execute_callable_kwargs)
  File "/home/airflow/.local/lib/python3.8/site-packages/airflow/models/taskinstance.py", line 414, in _execute_callable
    return execute_callable(context=context, **execute_callable_kwargs)
  File "/home/airflow/.local/lib/python3.8/site-packages/airflow/operators/python.py", line 200, in execute
    return_value = self.execute_callable()
  File "/home/airflow/.local/lib/python3.8/site-packages/airflow/operators/python.py", line 217, in execute_callable
    return self.python_callable(*self.op_args, **self.op_kwargs)
  File "/opt/airflow/dags/spotify_atomation.py", line 91, in get_data
    response = requests.get(
  File "/home/airflow/.local/lib/python3.8/site-packages/requests/api.py", line 73, in get
    return request("get", url, params=params, **kwargs)
  File "/home/airflow/.local/lib/python3.8/site-packages/requests/api.py", line 59, in request
    return session.request(method=method, url=url, **kwargs)
  File "/home/airflow/.local/lib/python3.8/site-packages/requests/sessions.py", line 589, in request
    resp = self.send(prep, **send_kwargs)
  File "/home/airflow/.local/lib/python3.8/site-packages/requests/sessions.py", line 703, in send
    r = adapter.send(request, **kwargs)
  File "/home/airflow/.local/lib/python3.8/site-packages/requests/adapters.py", line 519, in send
    raise ConnectionError(e, request=request)
requests.exceptions.ConnectionError: HTTPSConnectionPool(host='charts-spotify-com-service.spotify.com', port=443): Max retries exceeded with url: /auth/v0/charts/regional-global-daily/2024-01-01 (Caused by NewConnectionError('<urllib3.connection.HTTPSConnection object at 0xffff7589c640>: Failed to establish a new connection: [Errno -2] Name or service not known'))

During handling of the above exception, another exception occurred:

Traceback (most recent call last):
  File "/usr/local/lib/python3.8/urllib/request.py", line 1354, in do_open
    h.request(req.get_method(), req.selector, req.data, headers,
  File "/usr/local/lib/python3.8/http/client.py", line 1256, in request
    self._send_request(method, url, body, headers, encode_chunked)
  File "/usr/local/lib/python3.8/http/client.py", line 1302, in _send_request
    self.endheaders(body, encode_chunked=encode_chunked)
  File "/usr/local/lib/python3.8/http/client.py", line 1251, in endheaders
    self._send_output(message_body, encode_chunked=encode_chunked)
  File "/usr/local/lib/python3.8/http/client.py", line 1011, in _send_output
    self.send(msg)
  File "/usr/local/lib/python3.8/http/client.py", line 951, in send
    self.connect()
  File "/usr/local/lib/python3.8/http/client.py", line 1418, in connect
    super().connect()
  File "/usr/local/lib/python3.8/http/client.py", line 922, in connect
    self.sock = self._create_connection(
  File "/usr/local/lib/python3.8/socket.py", line 787, in create_connection
    for res in getaddrinfo(host, port, 0, SOCK_STREAM):
  File "/usr/local/lib/python3.8/socket.py", line 918, in getaddrinfo
    for res in _socket.getaddrinfo(host, port, family, type, proto, flags):
socket.gaierror: [Errno -2] Name or service not known

During handling of the above exception, another exception occurred:

Traceback (most recent call last):
  File "/home/airflow/.local/lib/python3.8/site-packages/airflow/notifications/basenotifier.py", line 106, in __call__
    self.notify(context)
  File "/opt/airflow/dags/utils/DiscordNotifier.py", line 16, in notify
    self.notifier.send(self.msg + title, True)
  File "/home/airflow/.local/lib/python3.8/site-packages/discord_notify/__init__.py", line 33, in send
    urlopen(request)
  File "/usr/local/lib/python3.8/urllib/request.py", line 222, in urlopen
    return opener.open(url, data, timeout)
  File "/usr/local/lib/python3.8/urllib/request.py", line 525, in open
    response = self._open(req, data)
  File "/usr/local/lib/python3.8/urllib/request.py", line 542, in _open
    result = self._call_chain(self.handle_open, protocol, protocol +
  File "/usr/local/lib/python3.8/urllib/request.py", line 502, in _call_chain
    result = func(*args)
  File "/usr/local/lib/python3.8/urllib/request.py", line 1397, in https_open
    return self.do_open(http.client.HTTPSConnection, req,
  File "/usr/local/lib/python3.8/urllib/request.py", line 1357, in do_open
    raise URLError(err)
urllib.error.URLError: <urlopen error [Errno -2] Name or service not known>
[2024-04-17T00:30:11.376+0000] {standard_task_runner.py:107} ERROR - Failed to execute job 401 for task get_data (HTTPSConnectionPool(host='charts-spotify-com-service.spotify.com', port=443): Max retries exceeded with url: /auth/v0/charts/regional-global-daily/2024-01-01 (Caused by NewConnectionError('<urllib3.connection.HTTPSConnection object at 0xffff7589c640>: Failed to establish a new connection: [Errno -2] Name or service not known')); 24949)
[2024-04-17T00:30:11.403+0000] {local_task_job_runner.py:234} INFO - Task exited with return code 1
[2024-04-17T00:30:11.432+0000] {taskinstance.py:3312} INFO - 0 downstream tasks scheduled from follow-on schedule check
