[2024-04-16T10:32:43.488+0000] {taskinstance.py:1979} INFO - Dependencies all met for dep_context=non-requeueable deps ti=<TaskInstance: spotify_atomation.py.get_data manual__2024-04-16T10:32:42.830977+00:00 [queued]>
[2024-04-16T10:32:43.492+0000] {taskinstance.py:1979} INFO - Dependencies all met for dep_context=requeueable deps ti=<TaskInstance: spotify_atomation.py.get_data manual__2024-04-16T10:32:42.830977+00:00 [queued]>
[2024-04-16T10:32:43.492+0000] {taskinstance.py:2193} INFO - Starting attempt 1 of 1
[2024-04-16T10:32:43.498+0000] {taskinstance.py:2217} INFO - Executing <Task(PythonOperator): get_data> on 2024-04-16 10:32:42.830977+00:00
[2024-04-16T10:32:43.500+0000] {standard_task_runner.py:60} INFO - Started process 19375 to run task
[2024-04-16T10:32:43.503+0000] {standard_task_runner.py:87} INFO - Running: ['***', 'tasks', 'run', 'spotify_atomation.py', 'get_data', 'manual__2024-04-16T10:32:42.830977+00:00', '--job-id', '380', '--raw', '--subdir', 'DAGS_FOLDER/spotify_atomation.py', '--cfg-path', '/tmp/tmp2_k2t_0g']
[2024-04-16T10:32:43.504+0000] {standard_task_runner.py:88} INFO - Job 380: Subtask get_data
[2024-04-16T10:32:43.526+0000] {task_command.py:423} INFO - Running <TaskInstance: spotify_atomation.py.get_data manual__2024-04-16T10:32:42.830977+00:00 [running]> on host 209a9ac884b0
[2024-04-16T10:32:43.563+0000] {taskinstance.py:2513} INFO - Exporting env vars: AIRFLOW_CTX_DAG_OWNER='***' AIRFLOW_CTX_DAG_ID='spotify_atomation.py' AIRFLOW_CTX_TASK_ID='get_data' AIRFLOW_CTX_EXECUTION_DATE='2024-04-16T10:32:42.830977+00:00' AIRFLOW_CTX_TRY_NUMBER='1' AIRFLOW_CTX_DAG_RUN_ID='manual__2024-04-16T10:32:42.830977+00:00'
[2024-04-16T10:32:43.653+0000] {taskinstance.py:2731} ERROR - Task failed with exception
Traceback (most recent call last):
  File "/home/airflow/.local/lib/python3.8/site-packages/requests/models.py", line 971, in json
    return complexjson.loads(self.text, **kwargs)
  File "/usr/local/lib/python3.8/json/__init__.py", line 357, in loads
    return _default_decoder.decode(s)
  File "/usr/local/lib/python3.8/json/decoder.py", line 337, in decode
    obj, end = self.raw_decode(s, idx=_w(s, 0).end())
  File "/usr/local/lib/python3.8/json/decoder.py", line 355, in raw_decode
    raise JSONDecodeError("Expecting value", s, err.value) from None
json.decoder.JSONDecodeError: Expecting value: line 1 column 1 (char 0)

During handling of the above exception, another exception occurred:

Traceback (most recent call last):
  File "/home/airflow/.local/lib/python3.8/site-packages/airflow/models/taskinstance.py", line 444, in _execute_task
    result = _execute_callable(context=context, **execute_callable_kwargs)
  File "/home/airflow/.local/lib/python3.8/site-packages/airflow/models/taskinstance.py", line 414, in _execute_callable
    return execute_callable(context=context, **execute_callable_kwargs)
  File "/home/airflow/.local/lib/python3.8/site-packages/airflow/operators/python.py", line 200, in execute
    return_value = self.execute_callable()
  File "/home/airflow/.local/lib/python3.8/site-packages/airflow/operators/python.py", line 217, in execute_callable
    return self.python_callable(*self.op_args, **self.op_kwargs)
  File "/opt/airflow/dags/spotify_atomation.py", line 84, in get_data
    entries = response.json()["entries"]
  File "/home/airflow/.local/lib/python3.8/site-packages/requests/models.py", line 975, in json
    raise RequestsJSONDecodeError(e.msg, e.doc, e.pos)
requests.exceptions.JSONDecodeError: Expecting value: line 1 column 1 (char 0)
[2024-04-16T10:32:43.657+0000] {taskinstance.py:1149} INFO - Marking task as FAILED. dag_id=spotify_atomation.py, task_id=get_data, execution_date=20240416T103242, start_date=20240416T103243, end_date=20240416T103243
[2024-04-16T10:32:44.029+0000] {logging_mixin.py:188} INFO -  ⚠️️Task Run Failed!⚠️>>Check Task get_data
[2024-04-16T10:32:44.040+0000] {standard_task_runner.py:107} ERROR - Failed to execute job 380 for task get_data (Expecting value: line 1 column 1 (char 0); 19375)
[2024-04-16T10:32:44.075+0000] {local_task_job_runner.py:234} INFO - Task exited with return code 1
[2024-04-16T10:32:44.091+0000] {taskinstance.py:3312} INFO - 0 downstream tasks scheduled from follow-on schedule check
